Workbook

Sheet Summary
A1: GoKesari - Shop-based Product Master & Inventory spec vs. built code (18 Oct 2026)
A2: Spec: "Gokesari Marketplace - Shop-Based Product Master, Inventory, MRP, Barcode & Stock Management" (sections 1-44). Compared against GoKesari main @c96cd04 (live on gokesari.com) by reading the schema, services, API routes, screens and tests. Status: DONE = built and live; PARTIAL = built in part (see "Missing"); NOT BUILT = no code yet. Change a status with the dropdown - counts are formulas.
A4: 1. Features & functions by status
A5: Status | B5: Features / functions | C5: % of total
A6: DONE | B6: =COUNTIF('Features & Functions'!$E$2:$E$53,A6) | C6: =IF($B$9=0,0,B6/$B$9)
A7: PARTIAL | B7: =COUNTIF('Features & Functions'!$E$2:$E$53,A7) | C7: =IF($B$9=0,0,B7/$B$9)
A8: NOT BUILT | B8: =COUNTIF('Features & Functions'!$E$2:$E$53,A8) | C8: =IF($B$9=0,0,B8/$B$9)
A9: Total | B9: =SUM(B6:B8) | C9: =SUM(C6:C8)
A11: 2. By area
A12: Area | B12: DONE | C12: PARTIAL | D12: NOT BUILT | E12: Total | F12: % done
A13: Marketplace model | B13: =COUNTIFS('Features & Functions'!$C$2:$C$53,$A13,'Features & Functions'!$E$2:$E$53,B$12) | C13: =COUNTIFS('Features & Functions'!$C$2:$C$53,$A13,'Features & Functions'!$E$2:$E$53,C$12) | D13: =COUNTIFS('Features & Functions'!$C$2:$C$53,$A13,'Features & Functions'!$E$2:$E$53,D$12) | E13: =SUM(B13:D13) | F13: =IF(E13=0,0,B13/E13)
A14: Product Master | B14: =COUNTIFS('Features & Functions'!$C$2:$C$53,$A14,'Features & Functions'!$E$2:$E$53,B$12) | C14: =COUNTIFS('Features & Functions'!$C$2:$C$53,$A14,'Features & Functions'!$E$2:$E$53,C$12) | D14: =COUNTIFS('Features & Functions'!$C$2:$C$53,$A14,'Features & Functions'!$E$2:$E$53,D$12) | E14: =SUM(B14:D14) | F14: =IF(E14=0,0,B14/E14)
A15: Admin | B15: =COUNTIFS('Features & Functions'!$C$2:$C$53,$A15,'Features & Functions'!$E$2:$E$53,B$12) | C15: =COUNTIFS('Features & Functions'!$C$2:$C$53,$A15,'Features & Functions'!$E$2:$E$53,C$12) | D15: =COUNTIFS('Features & Functions'!$C$2:$C$53,$A15,'Features & Functions'!$E$2:$E$53,D$12) | E15: =SUM(B15:D15) | F15: =IF(E15=0,0,B15/E15)
A16: Data ownership | B16: =COUNTIFS('Features & Functions'!$C$2:$C$53,$A16,'Features & Functions'!$E$2:$E$53,B$12) | C16: =COUNTIFS('Features & Functions'!$C$2:$C$53,$A16,'Features & Functions'!$E$2:$E$53,C$12) | D16: =COUNTIFS('Features & Functions'!$C$2:$C$53,$A16,'Features & Functions'!$E$2:$E$53,D$12) | E16: =SUM(B16:D16) | F16: =IF(E16=0,0,B16/E16)
A17: Migration | B17: =COUNTIFS('Features & Functions'!$C$2:$C$53,$A17,'Features & Functions'!$E$2:$E$53,B$12) | C17: =COUNTIFS('Features & Functions'!$C$2:$C$53,$A17,'Features & Functions'!$E$2:$E$53,C$12) | D17: =COUNTIFS('Features & Functions'!$C$2:$C$53,$A17,'Features & Functions'!$E$2:$E$53,D$12) | E17: =SUM(B17:D17) | F17: =IF(E17=0,0,B17/E17)
A18: Shop Inventory | B18: =COUNTIFS('Features & Functions'!$C$2:$C$53,$A18,'Features & Functions'!$E$2:$E$53,B$12) | C18: =COUNTIFS('Features & Functions'!$C$2:$C$53,$A18,'Features & Functions'!$E$2:$E$53,C$12) | D18: =COUNTIFS('Features & Functions'!$C$2:$C$53,$A18,'Features & Functions'!$E$2:$E$53,D$12) | E18: =SUM(B18:D18) | F18: =IF(E18=0,0,B18/E18)
A19: Barcode | B19: =COUNTIFS('Features & Functions'!$C$2:$C$53,$A19,'Features & Functions'!$E$2:$E$53,B$12) | C19: =COUNTIFS('Features & Functions'!$C$2:$C$53,$A19,'Features & Functions'!$E$2:$E$53,C$12) | D19: =COUNTIFS('Features & Functions'!$C$2:$C$53,$A19,'Features & Functions'!$E$2:$E$53,D$12) | E19: =SUM(B19:D19) | F19: =IF(E19=0,0,B19/E19)
A20: Alerts | B20: =COUNTIFS('Features & Functions'!$C$2:$C$53,$A20,'Features & Functions'!$E$2:$E$53,B$12) | C20: =COUNTIFS('Features & Functions'!$C$2:$C$53,$A20,'Features & Functions'!$E$2:$E$53,C$12) | D20: =COUNTIFS('Features & Functions'!$C$2:$C$53,$A20,'Features & Functions'!$E$2:$E$53,D$12) | E20: =SUM(B20:D20) | F20: =IF(E20=0,0,B20/E20)
A21: Customer | B21: =COUNTIFS('Features & Functions'!$C$2:$C$53,$A21,'Features & Functions'!$E$2:$E$53,B$12) | C21: =COUNTIFS('Features & Functions'!$C$2:$C$53,$A21,'Features & Functions'!$E$2:$E$53,C$12) | D21: =COUNTIFS('Features & Functions'!$C$2:$C$53,$A21,'Features & Functions'!$E$2:$E$53,D$12) | E21: =SUM(B21:D21) | F21: =IF(E21=0,0,B21/E21)
A22: Bulk import | B22: =COUNTIFS('Features & Functions'!$C$2:$C$53,$A22,'Features & Functions'!$E$2:$E$53,B$12) | C22: =COUNTIFS('Features & Functions'!$C$2:$C$53,$A22,'Features & Functions'!$E$2:$E$53,C$12) | D22: =COUNTIFS('Features & Functions'!$C$2:$C$53,$A22,'Features & Functions'!$E$2:$E$53,D$12) | E22: =SUM(B22:D22) | F22: =IF(E22=0,0,B22/E22)
A23: Inventory history | B23: =COUNTIFS('Features & Functions'!$C$2:$C$53,$A23,'Features & Functions'!$E$2:$E$53,B$12) | C23: =COUNTIFS('Features & Functions'!$C$2:$C$53,$A23,'Features & Functions'!$E$2:$E$53,C$12) | D23: =COUNTIFS('Features & Functions'!$C$2:$C$53,$A23,'Features & Functions'!$E$2:$E$53,D$12) | E23: =SUM(B23:D23) | F23: =IF(E23=0,0,B23/E23)
A24: Orders | B24: =COUNTIFS('Features & Functions'!$C$2:$C$53,$A24,'Features & Functions'!$E$2:$E$53,B$12) | C24: =COUNTIFS('Features & Functions'!$C$2:$C$53,$A24,'Features & Functions'!$E$2:$E$53,C$12) | D24: =COUNTIFS('Features & Functions'!$C$2:$C$53,$A24,'Features & Functions'!$E$2:$E$53,D$12) | E24: =SUM(B24:D24) | F24: =IF(E24=0,0,B24/E24)
... A30: AI | B30: =COUNTIFS('Features & Functions'!$C$2:$C$53,$A30,'Features & Functions'!$E$2:$E$53,B$12) | C30: =COUNTIFS('Features & Functions'!$C$2:$C$53,$A30,'Features & Functions'!$E$2:$E$53,C$12) | D30: =COUNTIFS('Features & Functions'!$C$2:$C$53,$A30,'Features & Functions'!$E$2:$E$53,D$12) | E30: =SUM(B30:D30) | F30: =IF(E30=0,0,B30/E30)
A31: Total | B31: =SUM(B13:B30) | C31: =SUM(C13:C30) | D31: =SUM(D13:D30) | E31: =SUM(E13:E30) | F31: =IF(E31=0,0,B31/E31)
A33: 3. Workflow steps by status
A34: Status | B34: Steps
A35: DONE | B35: =COUNTIFS('Workflow Trees'!$B$2:$B$51,2,'Workflow Trees'!$D$2:$D$51,A35)
A36: PARTIAL | B36: =COUNTIFS('Workflow Trees'!$B$2:$B$51,2,'Workflow Trees'!$D$2:$D$51,A36)
A37: NOT BUILT | B37: =COUNTIFS('Workflow Trees'!$B$2:$B$51,2,'Workflow Trees'!$D$2:$D$51,A37)
A39: 4. Mandatory acceptance tests (§43)
A40: Coverage | B40: Tests
A41: COVERED | B41: =COUNTIF('Acceptance Tests'!$C$2:$C$16,A41)
A42: PARTLY | B42: =COUNTIF('Acceptance Tests'!$C$2:$C$16,A42)
A43: NOT COVERED | B43: =COUNTIF('Acceptance Tests'!$C$2:$C$16,A43)
A45: 5. Headlines
A46: The marketplace model is intact: shops stay the seller, every inventory row belongs to one shop, the master is shared, MRP is master-level and shop prices are per shop. Server-side shop isolation is in place on every inventory route.
A47: Built and live: per-shop stock, low-stock / reorder thresholds, de-duplicated stock alerts (dashboard + bell), out-of-stock per shop, inventory dashboard with value, offers, atomic no-oversell checkout, MRP governance with a correction queue, bulk Excel / CSV shop upload (15 Oct).
A48: Not built: barcode scanning (Phase 3), per-GTIN external lookup / live GS1 (Phase 5 - waits on the GS1 agreement), purchase orders, AI product recognition.
A49: Gaps to fix first: controlled Request New Product, restock on customer returns, shop flows writing master MRP, admin edit screens for master fields / brands / subcategories, a Reorder List page, richer Add Product form.
A50: Tests: 6 of the 15 acceptance tests fully covered, 8 partly, 1 not (concurrent last-unit oversell).

Sheet Features & Functions
A1: ID | B1: Spec section | C1: Area | D1: Feature / function | E1: Status | F1: What exists today | G1: Missing / gap | H1: Evidence (code)
A2: MP-01 | B2: §1, §5, §44 | C2: Marketplace model | D2: GoKesari stays a multi-shop marketplace; shop is the seller, GoKesari is not | E2: DONE | F2: Carts split into one order per shop; orders.shop_id; invoice names the shop as supplier ("Sold by"); About page says GoKesari is not the seller of record | G2: - | H2: services/invoices.ts; app/invoices/[id]/page.tsx; tests/integration/checkout.test.ts
A3: MP-02 | B3: §5, §6 | C3: Marketplace model | D3: Every inventory record belongs to one registered shop; shop → shop product → product master | E3: DONE | F3: shop_products(shop_id, product_id) NOT NULL FKs, unique per shop + product; master never owns stock | G3: - | H3: schema.ts:1519-1621
A4: PM-01 | B4: §3, §7 | C4: Product Master | D4: Central Product Master as a shared catalogue that shops reference | E4: DONE | F4: public.products shared by all shops via shop_products.product_id; separate PMD data platform (pmd.*) feeds it through pmd.catalogue_link | G4: - | H4: schema.ts:1314-1443; drizzle/0015
A5: PM-02 | B5: §7 | C5: Product Master | D5: Identity: productId, productName, shortName, internalSKU, GTIN, EAN, UPC, barcode | E5: PARTIAL | F5: id, code (P00001 = internal SKU), name, gtin (EAN/UPC stored in gtin), barcode (non-GTIN) | G5: shortName; separate EAN / UPC columns (pmd.product_master has them) | H5: schema.ts:1317-1356
A6: PM-03 | B6: §8 | C6: Product Master | D6: Brand Master table (brandId, brandName, brandCode, description, logoUrl, status, dates); products reference brand | E6: PARTIAL | F6: brands table (name, slug, description, logo_url, is_active, timestamps); products.brand_id FK; create/update service with audit | G6: brand_code; status is a boolean; NO admin screen or API calls the brand create/update service | H6: schema.ts:1215-1234; services/brands.ts
A7: PM-04 | B7: §9 | C7: Product Master | D7: Category + subcategory tables; product references categoryId and subcategoryId | E7: PARTIAL | F7: product_categories + product_subcategories; products.category_id / subcategory_id; Category Master page /product-categories with CRUD API | G7: No subcategory create / edit service, API or screen; product create still takes the old free-text sub-category | H7: schema.ts:1246-1308; app/product-categories
A8: PM-05 | B8: §7 | C8: Product Master | D8: Packaging: pack size, pack unit, net quantity, quantity unit, variant, flavour, size, colour | E8: PARTIAL | F8: net_quantity, net_quantity_unit, unit, unit_size_milli, variant; extras kept in product_attributes (jsonb) | G8: pack size / pack unit, flavour, size, colour columns | H8: schema.ts:1358, 1390-1396
A9: PM-06 | B9: §7 | C9: Product Master | D9: Manufacturer name, address, country of origin | E9: DONE | F9: manufacturer_name, manufacturer_address, country_of_origin on products | G9: No admin edit screen (see PM-13) | H9: schema.ts:1387-1389
A10: PM-07 | B10: §7 | C10: Product Master | D10: Tax: HSN, GST rate, tax category | E10: PARTIAL | F10: hsn_code, gst_rate_bp (checked); shop-level HSN / GST / cess overrides on shop_products | G10: taxCategory; cess on the master | H10: schema.ts:1376-1377, 1548-1550
A11: PM-08 | B11: §7, §10 | C11: Product Master | D11: MRP at master level: MRP, currency, source, effective date, verification status, last updated; MRP history | E11: PARTIAL | F11: mrp_paise, mrp_source, mrp_effective_from, mrp_verification_status, mrp_updated_at; product_mrp_history table | G11: currency column (INR assumed) | H11: schema.ts:1365-1371, 1450-1468
A12: PM-09 | B12: §11, §36 | C12: Product Master | D12: Migration: unknown MRP = NULL + PENDING; never copy selling price into MRP | E12: PARTIAL | F12: MRP added nullable, no backfill; no migration copies price into MRP | G12: Default verification status is UNVERIFIED, not PENDING | H12: drizzle/0014:70-74
... A53: AI-01 | B53: §42 Ph 7 | C53: AI | D53: Product image recognition, OCR, matching, AI categorisation, AI duplicate detection | E53: PARTIAL | F53: Keyword categoriser (rule-based); deterministic PMD matcher (GTIN / MPN / trigram); AI + OCR reading of SUPPLIER BILLS and KYC documents | G53: No product-image recognition, product-label OCR, AI categorisation or AI duplicate detection | H53: services/product-categorisation.ts; pmd/match/engine.ts; accounts/capture

Sheet Workflow Trees
A1: Flow / step | B1: Level | C1: Workflow tree | D1: Status | E1: Note
A2: WF-A | B2: 1 | C2: Shop owner adds a product by searching the Product Master | D2: =IF(COUNTIF($D$3:$D$8,"DONE")=ROWS($D$3:$D$8),"DONE",IF(COUNTIF($D$3:$D$8,"NOT BUILT")=ROWS($D$3:$D$8),"NOT BUILT","PARTIAL")) | E2: =COUNTIF($D$3:$D$8,"DONE")&" of "&ROWS($D$3:$D$8)&" steps done"
A3: WF-A.1 | B3: 2 | C3: Open My Shop → Inventory → Add Product | D3: DONE | E3: /shop/manage/products → Add New Product → Add Existing Product
A4: WF-A.2 | B4: 2 | C4: Search the Product Master | D4: PARTIAL | E4: Approved products in the shop's categories; name / code / brand only - not GTIN
A5: WF-A.3 | B5: 2 | C5: Show name, brand, category, subcategory, pack, GTIN, MRP, image | D5: PARTIAL | E5: Shows name, category, code, unit only
A6: WF-A.4 | B6: 2 | C6: Enter selling price | D6: DONE | E6: One price used for online and in-shop
A7: WF-A.5 | B7: 2 | C7: Enter stock, threshold, reorder level / qty, discount | D7: NOT BUILT | E7: Set later on other screens; stock starts at 0
A8: WF-A.6 | B8: 2 | C8: Add to My Shop (server checks MRP, category, duplicate) | D8: DONE | E8: POST /api/shops/[id]/products
A9: WF-B | B9: 1 | C9: Shop owner adds a product by barcode scan | D9: =IF(COUNTIF($D$10:$D$14,"DONE")=ROWS($D$10:$D$14),"DONE",IF(COUNTIF($D$10:$D$14,"NOT BUILT")=ROWS($D$10:$D$14),"NOT BUILT","PARTIAL")) | E9: =COUNTIF($D$10:$D$14,"DONE")&" of "&ROWS($D$10:$D$14)&" steps done"
A10: WF-B.1 | B10: 2 | C10: Scan barcode with camera / scanner | D10: NOT BUILT | E10: No scanner in web or app
A11: WF-B.2 | B11: 2 | C11: Look up GTIN in the Product Master | D11: NOT BUILT | E11: GTIN lookup is staff-only (PMD_VIEW)
A12: WF-B.3 | B12: 2 | C12: Found → select → add to own shop inventory | D12: NOT BUILT
A13: WF-B.4 | B13: 2 | C13: Not found → external provider lookup (GS1 DataKart) | D13: NOT BUILT | E13: No live provider; GS1 agreement pending
A14: WF-B.5 | B14: 2 | C14: Still not found → controlled Request New Product | D14: PARTIAL | E14: Creates a pending product that the shop can sell at once; duplicate warning can be skipped
A15: WF-C | B15: 1 | C15: Low stock → alert → reorder | D15: =IF(COUNTIF($D$16:$D$22,"DONE")=ROWS($D$16:$D$22),"DONE",IF(COUNTIF($D$16:$D$22,"NOT BUILT")=ROWS($D$16:$D$22),"NOT BUILT","PARTIAL")) | E15: =COUNTIF($D$16:$D$22,"DONE")&" of "&ROWS($D$16:$D$22)&" steps done"
A16: WF-C.1 | B16: 2 | C16: Every stock change re-checks alerts in the same transaction | D16: DONE | E16: Orders, restock, bills, imports, edits
A17: WF-C.2 | B17: 2 | C17: Compare with the shop's own threshold | D17: DONE | E17: Listing → product default → shop default
A18: WF-C.3 | B18: 2 | C18: Open / resolve the shop's stock alert (no duplicates) | D18: DONE | E18: stock_alerts
A19: WF-C.4 | B19: 2 | C19: Notify: dashboard, bell, inventory page | D19: DONE | E19: In-app
A20: WF-C.5 | B20: 2 | C20: Notify: email / SMS / WhatsApp | D20: PARTIAL | E20: Email opt-in only; SMS / WhatsApp wait on D2 vendor
A21: WF-C.6 | B21: 2 | C21: Reorder recommended flag + suggested quantity | D21: DONE
A22: WF-C.7 | B22: 2 | C22: Shop Reorder List | D22: PARTIAL | E22: Data in the inventory table; no reorder-only page / filter
A23: WF-D | B23: 1 | C23: Customer buys from a shop → that shop's stock goes down | D23: =IF(COUNTIF($D$24:$D$30,"DONE")=ROWS($D$24:$D$30),"DONE",IF(COUNTIF($D$24:$D$30,"NOT BUILT")=ROWS($D$24:$D$30),"NOT BUILT","PARTIAL")) | E23: =COUNTIF($D$24:$D$30,"DONE")&" of "&ROWS($D$24:$D$30)&" steps done"
A24: WF-D.1 | B24: 2 | C24: Customer searches a product | D24: DONE
A25: WF-D.2 | B25: 2 | C25: Sees each shop with price and availability | D25: PARTIAL | E25: No "Low stock" label for customers
A26: WF-D.3 | B26: 2 | C26: Cart split per shop; order belongs to the shop | D26: DONE
A27: WF-D.4 | B27: 2 | C27: Stock taken from that shop only, atomically (no overselling) | D27: DONE | E27: Conditional update + CHECK >= 0
A28: WF-D.5 | B28: 2 | C28: Zero stock → that shop's listing out of stock; others stay available | D28: DONE
A29: WF-D.6 | B29: 2 | C29: Cancellation puts stock back | D29: DONE
A30: WF-D.7 | B30: 2 | C30: Customer return after delivery puts stock back | D30: NOT BUILT | E30: Credit note only; stock not restored
A31: WF-E | B31: 1 | C31: Shop bulk inventory upload (Excel / CSV) | D31: =IF(COUNTIF($D$32:$D$36,"DONE")=ROWS($D$32:$D$36),"DONE",IF(COUNTIF($D$32:$D$36,"NOT BUILT")=ROWS($D$32:$D$36),"NOT BUILT","PARTIAL")) | E31: =COUNTIF($D$32:$D$36,"DONE")&" of "&ROWS($D$32:$D$36)&" steps done"
A32: WF-E.1 | B32: 2 | C32: Upload file for the logged-in shop only (server check) | D32: DONE | E32: 403 / 404 for another shop
A33: WF-E.2 | B33: 2 | C33: Match rows by GTIN / SKU / name to the master | D33: DONE
A34: WF-E.3 | B34: 2 | C34: Set / add stock and selling price; ledger rows written | D34: DONE
A35: WF-E.4 | B35: 2 | C35: Import threshold, reorder level, reorder qty | D35: NOT BUILT
A36: WF-E.5 | B36: 2 | C36: Validation, warnings and downloadable result report | D36: PARTIAL | E36: Warnings only - rows never rejected; missing GTIN not flagged
A37: WF-F | B37: 1 | C37: Product Master import and external data | D37: =IF(COUNTIF($D$38:$D$42,"DONE")=ROWS($D$38:$D$42),"DONE",IF(COUNTIF($D$38:$D$42,"NOT BUILT")=ROWS($D$38:$D$42),"NOT BUILT","PARTIAL")) | E37: =COUNTIF($D$38:$D$42,"DONE")&" of "&ROWS($D$38:$D$42)&" steps done"
A38: WF-F.1 | B38: 2 | C38: Admin uploads Product Master Excel (no shop involved) | D38: PARTIAL | E38: Only via shop picker, or PMD JSON / CLI
A39: WF-F.2 | B39: 2 | C39: Validate and report errors | D39: PARTIAL | E39: PMD has error codes; shop import warns only
A40: WF-F.3 | B40: 2 | C40: Duplicate detection by GTIN | D40: PARTIAL | E40: Unique GTIN; no canonical GTIN-14 form
...

Sheet Acceptance Tests
A1: Test | B1: Spec test (§43) | C1: Coverage | D1: Existing automated test (file :: name) | E1: Gap
A2: T1 | B2: Marketplace preservation - two shops stay independent sellers | C2: COVERED | D2: checkout.test.ts :: splits a cross-shop cart; product-master-inventory.test.ts :: two shops stock the same master product
A3: T2 | B3: Same product → one Product Master | C3: COVERED | D3: product-master-inventory.test.ts (asserts 1 product row); pmd-review-bridge.test.ts
A4: T3 | B4: Independent price (95 / 90) | C4: COVERED | D4: product-master-inventory.test.ts; shop-inventory-fill.test.ts
A5: T4 | B5: Independent stock (A 20→10, B stays 5) | C5: COVERED | D5: product-master-inventory.test.ts (A restocked, B unchanged)
A6: T5 | B6: Low-stock alert only for shop B | C6: PARTLY | D6: product-master-inventory.test.ts :: raises LOW_STOCK alert | E6: Single shop; does not check shop A gets no alert
A7: T6 | B7: Out of stock at B, A still available | C7: PARTLY | D7: product-master-inventory.test.ts :: OUT_OF_STOCK marks line unavailable | E7: Single shop
A8: T7 | B8: Customer search shows shops with price / availability | C8: PARTLY | D8: price-comparison.test.ts | E8: Prices only; "Low stock" not shown to customers
A9: T8 | B9: Barcode scan finds master and adds to shop A | C9: PARTLY | D9: product-master-inventory.test.ts :: finds master by GTIN; product-import.test.ts :: barcode links shop | E9: Scan-and-add not built
A10: T9 | B10: MRP stays 100 with shop prices 95 / 90 | C10: COVERED | D10: product-master-inventory.test.ts
A11: T10 | B11: Shop owner cannot change MRP | C11: COVERED | D11: product-master-inventory.test.ts :: refuses a shop owner writing master MRP | E11: Service level; no /api/mrp route test
A12: T11 | B12: Bulk inventory upload changes only shop A | C12: PARTLY | D12: excel-goods-upload.test.ts; product-import.test.ts :: cannot import into another shop | E12: Cross-shop stock not asserted
A13: T12 | B13: Shop A cannot modify shop B inventory | C13: PARTLY | D13: shop-inventory-fill.test.ts (403 on prices); inventory-accounting.test.ts | E13: No test on stock routes (shop-products, stock-settings, inventory)
A14: T13 | B14: Order from shop A decreases only shop A stock | C14: PARTLY | D14: checkout.test.ts :: decrements stock | E14: Other shop's stock not asserted
A15: T14 | B15: Concurrent orders cannot oversell | C15: NOT COVERED | D15: - | E15: Protected in code (conditional update) but no last-unit race test
A16: T15 | B16: Below reorder level → in that shop's Reorder List | C16: PARTLY | D16: product-master-inventory.test.ts :: reorder level separate signal | E16: No Reorder List feature to test

Sheet Phases
A1: Phase | B1: Name | C1: Spec scope | D1: Status | E1: Comment | F1: Feature IDs
A2: Phase 1 | B2: Product catalogue | C2: Product Master, brands, categories, subcategories, GTIN, pack, manufacturer, origin, HSN, GST, MRP, MRP history, images | D2: PARTIAL | E2: Tables and data built; admin edit screens for master fields, brands and subcategories missing; a few columns missing | F2: PM-01, PM-02, PM-03, PM-04, PM-05, PM-06, PM-07, PM-08, PM-11
A3: Phase 2 | B3: Shop inventory | C3: Shop → master link, independent inventory, price, stock, thresholds, reorder, dashboard, reorder list, status, history | D3: PARTIAL | E3: Engine, alerts and dashboard done; reorder list page, MRP column and add-product form fields missing | F3: SI-01, SI-05, SI-06, SI-07, SI-08, SI-09, SI-10, SI-11, IT-01
A4: Phase 3 | B4: Barcode | C4: Mobile scanning, scanner support, GTIN lookup, master lookup | D4: NOT BUILT | E4: Only a back-end GTIN lookup function exists | F4: SI-03, SI-04
A5: Phase 4 | B5: Bulk import | C5: Master import, shop inventory import, validation, error reports, duplicates | D5: PARTIAL | E5: Shop bulk upload live on gokesari.com (15 Oct); master-only Excel import, thresholds and hard validation missing | F5: IM-01, IM-02, IM-03
A6: Phase 5 | B6: External product data | C6: Provider abstraction, GS1 / DataKart, lookup, sync, MRP verification | D6: PARTIAL | E6: Batch adapters built; per-GTIN lookup, live GS1 and sync missing; GS1 agreement pending | F6: EX-01, EX-02, EX-03
A7: Phase 6 | B7: Advanced inventory | C7: Reservation, order deduction, purchase / restock, supplier, purchase orders | D7: PARTIAL | E7: Order deduction and purchase bills done; reservation holds, purchase orders and GRN missing | F7: OR-01, OR-02, OR-03, OR-04, SU-01
A8: Phase 7 | B8: AI | C8: Image recognition, OCR, matching, AI categorisation, duplicates | D8: PARTIAL | E8: AI used for bills and KYC documents only | F8: AI-01

Sheet Gap List
A1: # | B1: Priority | C1: What to build / fix | D1: Spec IDs
A2: 1 | B2: High | C2: Barcode scanning for shop owners (camera + scanner) with GTIN → master lookup and add-to-shop | D2: SI-03, WF-B, T8
A3: 2 | B3: High | C3: Controlled Request New Product: request record, not sellable until approved, no "Create anyway" bypass | D3: SI-04, PM-12
A4: 3 | B4: High | C4: Customer returns after delivery must restock the shop (shop_products + ledger) | D4: OR-03, WF-D.7
A5: 4 | B5: High | C5: Stop shop flows writing master MRP / identity (purchase bill creates product with MRP, no history) | D5: PM-10, PM-16
A6: 5 | B6: High | C6: Admin edit screens: product master fields, brands, subcategories | D6: PM-03, PM-04, PM-13
A7: 6 | B7: Medium | C7: Add Product form: show brand / pack / GTIN / MRP / image; take stock, threshold, reorder, discount; search by GTIN | D7: SI-02, WF-A
A8: 7 | B8: Medium | C8: Dedicated Reorder List page and filter | D8: SI-10, WF-C.7, T15
A9: 8 | B9: Medium | C9: MRP column in shop inventory table; "Low stock" label for customers | D9: SI-11, CU-01
A10: 9 | B10: Medium | C10: Shop inventory import: thresholds and reorder fields; reject missing GTIN / invalid GST; master-only admin import | D10: IM-01..03
A11: 10 | B11: Medium | C11: Canonical GTIN-14 storage and use of the duplicate-candidate check | D11: PM-12
A12: 11 | B12: Medium | C12: Tests: last-unit oversell race, cross-shop stock / alert assertions, /api/mrp 403 | D12: T5, T6, T11-T14
A13: 12 | B13: Low | C13: Columns: shortName, brandCode, currency, taxCategory, imageType, pack / flavour / size / colour; migrated MRP status PENDING | D13: PM-02..09, PM-11
... A17: 16 | B17: Low | C17: AI: product image recognition, label OCR, AI categorisation / duplicates | D17: AI-01
