Workbook

Sheet Read me
A1: GoKesari - test scenarios and test cases
A2: Prepared 3 Oct 2026 for execution by Claude in a browser against the test site. Nothing here has been run yet - every Expected result is a claim to confirm or refute. Updated 3 Oct with three new requirements (NEW-008 to NEW-010), field-level, log out and sell / purchase / inventory cases - see the Change log sheet. Updated 4 Oct: the 24 open features are treated as completed and have positive and negative cases.
A4: What is in this workbook
A5: Test cases | B5: 826 cases across 30 modules (P0 320, P1 345, P2 161; the QA automation module TC-QA-001 to 007 and the Purchase lists module TC-LIST-001 to 028 added 24 Oct). One row per case with steps, expected result, the feature IDs it covers and the earlier plan it comes from. 213 cases were added on 3 Oct and 106 on 4 Oct.
A6: E2E scenarios | B6: 37 end-to-end journeys built from the ten workflows (WF-001 to WF-010), the MVP vertical flow, the 3-Oct requirements (SC-23 to SC-28) and the open features treated as completed (SC-29 to SC-35); SC-36 and SC-37 (24 Oct) are the QA release check and the Claude QA agent's signed-in run.
A7: Coverage | B7: Every feature ID from the 28-Sep status report plus NEW-001 to NEW-010, with the test cases that cover it.
A8: Not yet testable | B8: Features still with no code behind them and not in the 3-Oct open-features list. Listed so nobody reports them as defects.
A9: Test data | B9: Accounts and seed data to prepare before the run.
A10: Run summary | B10: Live pass/fail counts per module, driven by the Status column.
A11: Change log | B11: What was added or changed on 3 Oct and 4 Oct, and the open questions to confirm with the owner.
A13: Sources used
A14: Feature lists | B14: Gokesari_Complete_Features_and_Workflows.xlsx (Feature Master, Workflow Master, RBAC Matrix, State Machines, Gig Assignment Rules, Navigation, KPIs); GOKESARI_FEATURE_STATUS_REPORT 27-Sep, 28-Sep and the 2-Oct re-audit in the repository; GOKESARI_IMPLEMENTATION_PRIORITY_UPDATED.xlsx (fast go-live priority, MVP vertical flow).
A15: Earlier test plans | B15: docs/gokesari-audit/QA_TEST_PLAN_COMPLETE_IN_PROGRESS.md (Phases A-J), GOKESARI_TEST_PLAN.md, the 'Testing handoff' blocks in PHASE1_DEV_LOG.md (Slices 1, 3-4, 6, Phases 2, 3, 4.3, 4.5, duplicate-shop fix, closed-shop ordering), docs/login-profile/DEPLOY_AND_TEST.md, GOKESARI_REGRESSION_MATRIX.xlsx, tests/e2e/acceptance.spec.ts, API.md, RBAC_PLAN.md.
A17: Rules for the run
A18: 1. Environment | B18: Run everything on https://test.gokesari.com. Production (gokesari.com) gets only the read-only smoke case TC-PRE-010. Check the host before every write.
A19: 2. Start with Preflight | B19: Run TC-PRE-001 to TC-PRE-008 first. They show which build and migrations are on test and which modules will be Blocked.
A20: 3. Order of work | B20: Preflight -> Login -> Access control -> Location -> Discovery -> Cart -> Wallet -> Fulfilment -> Dispatch -> Delivery -> Order state/cancellation -> the rest. P0 first inside each module, then the E2E scenarios.
A21: 4. Sign-in | B21: Claude does not type passwords. The owner signs each test account in (or reads out the email code) in the browser Claude is driving. Keep one browser profile per role where two roles must act at the same time.
A22: 5. Method column | B22: UI = through the pages. API = a fetch from the signed-in browser session to the listed endpoint, reading status and JSON. DB = needs database access to the TEST database; mark Blocked if not available. Never point any test tooling at the production database.
A23: 6. Money | B23: Use mock / sandbox payments only, for wallet top-ups and for online order payments. Never complete a real payment. Amounts are integer paise in the API (Rs 70.00 = 7000) and quantities are milli-units (2 L = 2000).
A24: 7. Time-based cases | B24: Cases that wait for expiry or cron (OTP expiry, offer expiry, rider search limits, notification retries) can be shortened by lowering the rule in /admin/settings on test, then restoring the default.
A25: 8. Recording results | B25: Set Status to Pass, Fail, Blocked or Not run. For a Fail write the actual result, the URL, the request/response or a screenshot name. For Blocked say why. Log defects with the TC ID.
A26: 9. Clean up | B26: Restore every rule changed in /admin/settings, reinstate suspended shops/users, and note any test data left behind.
A27: 10. New requirements | B27: NEW-008 to NEW-010 were stated on 3 Oct. Run TC-PRE-011 first; where the build does not have a requirement yet, mark its cases Blocked, not Fail. Open questions in the Change log decide a few Expected results.
A28: 11. Open features | B28: The 24 open features are written as if built. Run TC-PRE-012 first; where a feature is not on the test build yet, mark its cases Blocked, not Fail.
A30: Status values | B30: Pass = behaves as Expected. Fail = differs. Blocked = cannot be tested (say why). Not run = not attempted.
A31: Priority | B31: P0 = go-live blocker path (login, order, pay, fulfil, deliver, money, access control). P1 = important. P2 = secondary / edge.

Sheet Run summary
A1: Module | B1: Cases | C1: Pass | D1: Fail | E1: Blocked | F1: Not run | G1: P0 cases | H1: P0 not passed
A2: Preflight & smoke | B2: =COUNTIF('Test cases'!$B$2:$B$840,A2) | C2: =COUNTIFS('Test cases'!$B$2:$B$840,$A2,'Test cases'!$M$2:$M$840,"Pass") | D2: =COUNTIFS('Test cases'!$B$2:$B$840,$A2,'Test cases'!$M$2:$M$840,"Fail") | E2: =COUNTIFS('Test cases'!$B$2:$B$840,$A2,'Test cases'!$M$2:$M$840,"Blocked") | F2: =COUNTIFS('Test cases'!$B$2:$B$840,$A2,'Test cases'!$M$2:$M$840,"Not run") | G2: =COUNTIFS('Test cases'!$B$2:$B$840,$A2,'Test cases'!$F$2:$F$840,"P0") | H2: =G2-COUNTIFS('Test cases'!$B$2:$B$840,$A2,'Test cases'!$F$2:$F$840,"P0",'Test cases'!$M$2:$M$840,"Pass")
A3: Login, onboarding & profile | B3: =COUNTIF('Test cases'!$B$2:$B$840,A3) | C3: =COUNTIFS('Test cases'!$B$2:$B$840,$A3,'Test cases'!$M$2:$M$840,"Pass") | D3: =COUNTIFS('Test cases'!$B$2:$B$840,$A3,'Test cases'!$M$2:$M$840,"Fail") | E3: =COUNTIFS('Test cases'!$B$2:$B$840,$A3,'Test cases'!$M$2:$M$840,"Blocked") | F3: =COUNTIFS('Test cases'!$B$2:$B$840,$A3,'Test cases'!$M$2:$M$840,"Not run") | G3: =COUNTIFS('Test cases'!$B$2:$B$840,$A3,'Test cases'!$F$2:$F$840,"P0") | H3: =G3-COUNTIFS('Test cases'!$B$2:$B$840,$A3,'Test cases'!$F$2:$F$840,"P0",'Test cases'!$M$2:$M$840,"Pass")
A4: Roles & access control | B4: =COUNTIF('Test cases'!$B$2:$B$840,A4) | C4: =COUNTIFS('Test cases'!$B$2:$B$840,$A4,'Test cases'!$M$2:$M$840,"Pass") | D4: =COUNTIFS('Test cases'!$B$2:$B$840,$A4,'Test cases'!$M$2:$M$840,"Fail") | E4: =COUNTIFS('Test cases'!$B$2:$B$840,$A4,'Test cases'!$M$2:$M$840,"Blocked") | F4: =COUNTIFS('Test cases'!$B$2:$B$840,$A4,'Test cases'!$M$2:$M$840,"Not run") | G4: =COUNTIFS('Test cases'!$B$2:$B$840,$A4,'Test cases'!$F$2:$F$840,"P0") | H4: =G4-COUNTIFS('Test cases'!$B$2:$B$840,$A4,'Test cases'!$F$2:$F$840,"P0",'Test cases'!$M$2:$M$840,"Pass")
A5: Location, addresses & serviceability | B5: =COUNTIF('Test cases'!$B$2:$B$840,A5) | C5: =COUNTIFS('Test cases'!$B$2:$B$840,$A5,'Test cases'!$M$2:$M$840,"Pass") | D5: =COUNTIFS('Test cases'!$B$2:$B$840,$A5,'Test cases'!$M$2:$M$840,"Fail") | E5: =COUNTIFS('Test cases'!$B$2:$B$840,$A5,'Test cases'!$M$2:$M$840,"Blocked") | F5: =COUNTIFS('Test cases'!$B$2:$B$840,$A5,'Test cases'!$M$2:$M$840,"Not run") | G5: =COUNTIFS('Test cases'!$B$2:$B$840,$A5,'Test cases'!$F$2:$F$840,"P0") | H5: =G5-COUNTIFS('Test cases'!$B$2:$B$840,$A5,'Test cases'!$F$2:$F$840,"P0",'Test cases'!$M$2:$M$840,"Pass")
A6: Discovery, search & price comparison | B6: =COUNTIF('Test cases'!$B$2:$B$840,A6) | C6: =COUNTIFS('Test cases'!$B$2:$B$840,$A6,'Test cases'!$M$2:$M$840,"Pass") | D6: =COUNTIFS('Test cases'!$B$2:$B$840,$A6,'Test cases'!$M$2:$M$840,"Fail") | E6: =COUNTIFS('Test cases'!$B$2:$B$840,$A6,'Test cases'!$M$2:$M$840,"Blocked") | F6: =COUNTIFS('Test cases'!$B$2:$B$840,$A6,'Test cases'!$M$2:$M$840,"Not run") | G6: =COUNTIFS('Test cases'!$B$2:$B$840,$A6,'Test cases'!$F$2:$F$840,"P0") | H6: =G6-COUNTIFS('Test cases'!$B$2:$B$840,$A6,'Test cases'!$F$2:$F$840,"P0",'Test cases'!$M$2:$M$840,"Pass")
A7: Cart & checkout | B7: =COUNTIF('Test cases'!$B$2:$B$840,A7) | C7: =COUNTIFS('Test cases'!$B$2:$B$840,$A7,'Test cases'!$M$2:$M$840,"Pass") | D7: =COUNTIFS('Test cases'!$B$2:$B$840,$A7,'Test cases'!$M$2:$M$840,"Fail") | E7: =COUNTIFS('Test cases'!$B$2:$B$840,$A7,'Test cases'!$M$2:$M$840,"Blocked") | F7: =COUNTIFS('Test cases'!$B$2:$B$840,$A7,'Test cases'!$M$2:$M$840,"Not run") | G7: =COUNTIFS('Test cases'!$B$2:$B$840,$A7,'Test cases'!$F$2:$F$840,"P0") | H7: =G7-COUNTIFS('Test cases'!$B$2:$B$840,$A7,'Test cases'!$F$2:$F$840,"P0",'Test cases'!$M$2:$M$840,"Pass")
A8: Wallet, vouchers & gateway | B8: =COUNTIF('Test cases'!$B$2:$B$840,A8) | C8: =COUNTIFS('Test cases'!$B$2:$B$840,$A8,'Test cases'!$M$2:$M$840,"Pass") | D8: =COUNTIFS('Test cases'!$B$2:$B$840,$A8,'Test cases'!$M$2:$M$840,"Fail") | E8: =COUNTIFS('Test cases'!$B$2:$B$840,$A8,'Test cases'!$M$2:$M$840,"Blocked") | F8: =COUNTIFS('Test cases'!$B$2:$B$840,$A8,'Test cases'!$M$2:$M$840,"Not run") | G8: =COUNTIFS('Test cases'!$B$2:$B$840,$A8,'Test cases'!$F$2:$F$840,"P0") | H8: =G8-COUNTIFS('Test cases'!$B$2:$B$840,$A8,'Test cases'!$F$2:$F$840,"P0",'Test cases'!$M$2:$M$840,"Pass")
A9: Cash on delivery | B9: =COUNTIF('Test cases'!$B$2:$B$840,A9) | C9: =COUNTIFS('Test cases'!$B$2:$B$840,$A9,'Test cases'!$M$2:$M$840,"Pass") | D9: =COUNTIFS('Test cases'!$B$2:$B$840,$A9,'Test cases'!$M$2:$M$840,"Fail") | E9: =COUNTIFS('Test cases'!$B$2:$B$840,$A9,'Test cases'!$M$2:$M$840,"Blocked") | F9: =COUNTIFS('Test cases'!$B$2:$B$840,$A9,'Test cases'!$M$2:$M$840,"Not run") | G9: =COUNTIFS('Test cases'!$B$2:$B$840,$A9,'Test cases'!$F$2:$F$840,"P0") | H9: =G9-COUNTIFS('Test cases'!$B$2:$B$840,$A9,'Test cases'!$F$2:$F$840,"P0",'Test cases'!$M$2:$M$840,"Pass")
A10: Order state machine & cancellation | B10: =COUNTIF('Test cases'!$B$2:$B$840,A10) | C10: =COUNTIFS('Test cases'!$B$2:$B$840,$A10,'Test cases'!$M$2:$M$840,"Pass") | D10: =COUNTIFS('Test cases'!$B$2:$B$840,$A10,'Test cases'!$M$2:$M$840,"Fail") | E10: =COUNTIFS('Test cases'!$B$2:$B$840,$A10,'Test cases'!$M$2:$M$840,"Blocked") | F10: =COUNTIFS('Test cases'!$B$2:$B$840,$A10,'Test cases'!$M$2:$M$840,"Not run") | G10: =COUNTIFS('Test cases'!$B$2:$B$840,$A10,'Test cases'!$F$2:$F$840,"P0") | H10: =G10-COUNTIFS('Test cases'!$B$2:$B$840,$A10,'Test cases'!$F$2:$F$840,"P0",'Test cases'!$M$2:$M$840,"Pass")
A11: Shop fulfilment & substitution | B11: =COUNTIF('Test cases'!$B$2:$B$840,A11) | C11: =COUNTIFS('Test cases'!$B$2:$B$840,$A11,'Test cases'!$M$2:$M$840,"Pass") | D11: =COUNTIFS('Test cases'!$B$2:$B$840,$A11,'Test cases'!$M$2:$M$840,"Fail") | E11: =COUNTIFS('Test cases'!$B$2:$B$840,$A11,'Test cases'!$M$2:$M$840,"Blocked") | F11: =COUNTIFS('Test cases'!$B$2:$B$840,$A11,'Test cases'!$M$2:$M$840,"Not run") | G11: =COUNTIFS('Test cases'!$B$2:$B$840,$A11,'Test cases'!$F$2:$F$840,"P0") | H11: =G11-COUNTIFS('Test cases'!$B$2:$B$840,$A11,'Test cases'!$F$2:$F$840,"P0",'Test cases'!$M$2:$M$840,"Pass")
A12: Rider dispatch & assignment rules | B12: =COUNTIF('Test cases'!$B$2:$B$840,A12) | C12: =COUNTIFS('Test cases'!$B$2:$B$840,$A12,'Test cases'!$M$2:$M$840,"Pass") | D12: =COUNTIFS('Test cases'!$B$2:$B$840,$A12,'Test cases'!$M$2:$M$840,"Fail") | E12: =COUNTIFS('Test cases'!$B$2:$B$840,$A12,'Test cases'!$M$2:$M$840,"Blocked") | F12: =COUNTIFS('Test cases'!$B$2:$B$840,$A12,'Test cases'!$M$2:$M$840,"Not run") | G12: =COUNTIFS('Test cases'!$B$2:$B$840,$A12,'Test cases'!$F$2:$F$840,"P0") | H12: =G12-COUNTIFS('Test cases'!$B$2:$B$840,$A12,'Test cases'!$F$2:$F$840,"P0",'Test cases'!$M$2:$M$840,"Pass")
A13: Rider delivery & handover | B13: =COUNTIF('Test cases'!$B$2:$B$840,A13) | C13: =COUNTIFS('Test cases'!$B$2:$B$840,$A13,'Test cases'!$M$2:$M$840,"Pass") | D13: =COUNTIFS('Test cases'!$B$2:$B$840,$A13,'Test cases'!$M$2:$M$840,"Fail") | E13: =COUNTIFS('Test cases'!$B$2:$B$840,$A13,'Test cases'!$M$2:$M$840,"Blocked") | F13: =COUNTIFS('Test cases'!$B$2:$B$840,$A13,'Test cases'!$M$2:$M$840,"Not run") | G13: =COUNTIFS('Test cases'!$B$2:$B$840,$A13,'Test cases'!$F$2:$F$840,"P0") | H13: =G13-COUNTIFS('Test cases'!$B$2:$B$840,$A13,'Test cases'!$F$2:$F$840,"P0",'Test cases'!$M$2:$M$840,"Pass")
... A32: App install & updates | B32: =COUNTIF('Test cases'!$B$2:$B$840,A32) | C32: =COUNTIFS('Test cases'!$B$2:$B$840,$A32,'Test cases'!$M$2:$M$840,"Pass") | D32: =COUNTIFS('Test cases'!$B$2:$B$840,$A32,'Test cases'!$M$2:$M$840,"Fail") | E32: =COUNTIFS('Test cases'!$B$2:$B$840,$A32,'Test cases'!$M$2:$M$840,"Blocked") | F32: =COUNTIFS('Test cases'!$B$2:$B$840,$A32,'Test cases'!$M$2:$M$840,"Not run") | G32: =COUNTIFS('Test cases'!$B$2:$B$840,$A32,'Test cases'!$F$2:$F$840,"P0") | H32: =G32-COUNTIFS('Test cases'!$B$2:$B$840,$A32,'Test cases'!$F$2:$F$840,"P0",'Test cases'!$M$2:$M$840,"Pass")
A33: Total | B33: =SUM(B2:B32) | C33: =SUM(C2:C32) | D33: =SUM(D2:D32) | E33: =SUM(E2:E32) | F33: =SUM(F2:F32) | G33: =SUM(G2:G32) | H33: =SUM(H2:H32)

Sheet Change log
A1: Item | B1: Change | C1: Detail
A2: NEW-008 | B2: New requirement | C2: Loose goods: the price is left empty until the shop sets it. TC-CAT-027 to TC-CAT-036, SC-24.
A3: NEW-009 | B3: New requirement | C3: When a shop owner adds a product category, every product in it is added to the shop inventory at stock 100; products with no price are priced by the owner. TC-CAT-037 to TC-CAT-056, SC-23.
A4: NEW-010 | B4: New requirement | C4: An MRP changed by a shop owner applies to that shop only. TC-CAT-057 to TC-CAT-067, SC-25.
A5: TC-PRE-011 | B5: New case | C5: Preflight check that the three new requirements are on the test build; if not, their cases are Blocked.
A6: TC-AUTH-032 to TC-AUTH-045 | B6: New cases | C6: 14 log out / log off cases: every role, protected pages, session replay, tabs and devices, shared phone, automatic log off.
A7: TC-FLD-001 to TC-FLD-129 | B7: New module | C7: 'Field-level validation': 129 cases, one per field or field group on every form, each with blank, wrong format, boundary, script text and valid entries, checked on the page and through the API.
A8: TC-SPI-001 to TC-SPI-028 | B8: New module | C8: 'Sell, purchase & inventory': 28 cases tying each purchase and sale to its stock movement and money.
A9: SC-23 to SC-28 | B9: New scenarios | C9: Six end-to-end journeys: category stock-up to first sale, loose goods, shop MRP, sell / purchase / inventory reconciliation, log out on a shared phone, field validation on the first order.
A10: TC-PRE-008 | B10: Updated | C10: Seed data extended for the loose product, the test category and Shop C.
A11: TC-AUTH-030 | B11: Updated | C11: Pointer to the new log out cases.
A12: TC-DISC-011 | B12: Updated | C12: Unpriced rows added.
... A73: AI 31-Oct | B73: New module | C73: App install & updates (AI-001 to AI-006, docs/app-install-2026-10): TC-APP-001 to TC-APP-013. Automated in tests/qa/guest/app-install.spec.ts (production-safe, Android and iPhone profiles) and tests/qa/signed-in/app-install.spec.ts (account record). TC-APP-010 needs a deploy and TC-APP-012 a phone: declared manual.

Sheet Test cases
A1: TC ID | B1: Module | C1: Feature IDs | D1: Test case | E1: Type | F1: Priority | G1: Role | H1: Method | I1: Preconditions / data | J1: Steps | K1: Expected result | L1: Source (earlier plan / spec) | M1: Status | N1: Actual result | O1: Defect / evidence | P1: Run date
A2: TC-PRE-001 | B2: Preflight & smoke | C2: INF | D2: Test site is reachable and renders | E2: Positive | F2: P0 | G2: Guest | H2: UI | J2: 1. Open https://test.gokesari.com/ 2. Read the page and the browser console | K2: Home page renders with header (logo, Cart, Sign in), a 'Deliver to' location bar and shop shelves. No 500 page. No React hydration error (#418) in the console. | L2: Decisions & Deployment sheet; Dev log 2-Oct | M2: Pass | N2: Local Pass · Staging Pass · Production Pass local: customer: header (logo, cart, account menu), Deliver to, shelves; no hydration errors ‖ http://localhost:3351 renders; console errors: none staging: https://test.gokesari.com renders; console errors: none production: https://gokesari.com renders; console errors: none | O2: E-02 | P2: 2026-10-29 14:00
A3: TC-PRE-002 | B3: Preflight & smoke | C3: INF | D3: Database-backed pages load (no 500s) | E3: Positive | F3: P0 | G3: Guest | H3: UI | J3: 1. Open /shops, /search?q=milk, /categories, one /shops/{slug} page and one /products/{id} page | K3: Every page returns content. None shows a 500 or 'Something went wrong'. Record any that fail with URL and console/network error. | L3: Decisions & Deployment: 'test site returns 500 on all database pages' | M3: Pass | N3: Local Pass · Staging Pass · Production Pass local: loaded: /shops, /search?q=milk, /categories, /shops/anand-dairy-bakery, /products/ff3f256b-67d9-4fd3-ace9-f27d94c02bec ‖ loaded signed in: /shops, /search?q=milk, /categories, /shops/qa-shop-a-mvmkyclr-mvmkycqv-1, /products/c1046049-c1db-4f95-8571-86224a07ff84, /orders, /wallet staging: loaded: /shops, /search?q=milk, /categories, /shops/agtci-yivu6, /products/246c8d08-c44c-44b9-9ddd-458955580ba5 production: loaded: /shops, /search?q=milk, /categories, /shops/agtci-yivu6, /products/246c8d08-c44c-44b9-9ddd-458955580ba5 | P3: 2026-10-29 14:00
A4: TC-PRE-003 | B4: Preflight & smoke | C4: INF | D4: Deployed build matches the code under test | E4: Positive | F4: P0 | G4: Admin | H4: UI | I4: Signed in as ADMIN | J4: 1. Open each of: /admin/dashboard, /admin/orders, /admin/exceptions, /admin/settings, /admin/suspensions, /admin/rider-earnings, /admin/price-references, /admin/mrp, /admin/shop-categories, /admin/returns, /admin/cod, /admin/risk, /admin/analytics, /admin/campaigns, /admin/societies, /admin/product-master, /admin/consents, /admin/ratings 2. Note which load and which 404/500 | K4: All pages load. A 404 means the build on test is older than the features in this suite; a 500 usually means a migration (0025-0037) is not applied. Record the list - it decides which modules below are Blocked. | L4: Status report 2-Oct: 'migrations 0025-0036 unapplied as of last dev log' | M4: Pass | N4: Local Pass · Staging Pass · Production Not run local: 18/18 admin pages load: none blocks a module staging: 18/18 admin pages load: none blocks a module | P4: 2026-10-24 17:10
A5: TC-PRE-004 | B5: Preflight & smoke | C5: INF | D5: Business-rule defaults are in place before testing | E5: Positive | F5: P0 | G5: Admin | H5: UI | I5: Signed in as ADMIN | J5: 1. Open /admin/settings 2. Note every rule group and whether 'current' differs from 'default' | K5: Nine rule groups are listed (otp, dispatch, riderEarnings, returns, images, notifications, suspension, mrp, externalPrices). Record any non-default value so later results can be interpreted. Restore defaults unless a case says otherwise. | L5: QA plan S-01; NEW-001 | M5: Pass | N5: Passed, partly covered. Local Pass (partial) · Staging Pass (partial) · Production Not run local: not covered: the listing of the nine groups is the signed-tier TC-PRE-004 check ‖ not covered: restoring overridden rules to their defaults is admin-settings work kept to the local tier (tests/qa/local/access-admin.spec.ts) staging: not covered: restoring overridden rules to their defaults is admin-settings work kept to the local tier (tests/qa/local/access-admin.spec.ts) | P5: 2026-10-24 17:12
A6: TC-PRE-005 | B6: Preflight & smoke | C6: INF | D6: Email (SMTP) is configured on test | E6: Positive | F6: P0 | G6: Guest | H6: UI | J6: 1. Open /signin | K6: The mobile/email sign-in form is shown. If a warning says codes cannot be sent, SMTP is missing: mark every OTP and email-notification case Blocked. | L6: Login-profile DEPLOY_AND_TEST; QA plan section 0 | M6: Pass | N6: Passed, partly covered. Local Pass (partial) · Staging Pass (partial) · Production Not run local: not covered: a code actually reaching a mailbox is the local-tier check (local mail catcher) staging: not covered: a code actually reaching a mailbox is the local-tier check (local mail catcher) | P6: 2026-10-24 20:55
A7: TC-PRE-006 | B7: Preflight & smoke | C7: INF | D7: Cron jobs are running on test | E7: Positive | F7: P0 | G7: Admin | H7: UI+API | I7: CRON_SECRET supplied by the owner, or cron scheduled on the host | J7: 1. GET /api/cron/daily-orders with the bearer token (health probe) 2. Mark an order READY with no riders online and watch the attempt counter for 2-3 minutes | K7: Health probe returns 200 and generates nothing. The 'Looking for a rider - attempt N' counter rises about once a minute, proving delivery-dispatch cron runs. If it never rises, mark cron-dependent cases Blocked. | L7: Test plan section 5.2; QA plan section 0 | M7: Pass | N7: Passed, partly covered. Local Pass (partial) · Staging Not run (rule) · Production Not run local: not covered: the local server has no scheduler, so the test calls the dispatch cron as the host's scheduler would; whether the host schedules it every minute is checked on the test site (the exceptions page warns 'dispatch looks stalled') staging: not run on staging: needs the server's database (local run only) | P7: 2026-10-24 17:05
A8: TC-PRE-007 | B8: Preflight & smoke | C8: INF | D8: Required test accounts exist and can sign in | E8: Positive | F8: P0 | G8: All | H8: UI | I8: See 'Test data' sheet | J8: 1. Sign in as each account in turn (the owner enters credentials / codes) 2. Check the header role switcher and landing page for each | K8: ADMIN, OPERATOR, 2 SHOP_OWNERs, 2 CUSTOMERs, 1 approved online rider, 1 verified society admin all sign in and land on the right portal. | L8: QA plan section 0 | M8: Pass | N8: Passed, partly covered. Local Pass (partial) · Staging Blocked · Production Not run local: not covered: one seeded account signs in for real (each code request counts against the hourly limit); every account's session and portal is the signed-tier TC-PRE-007 check ‖ not covered: sessions are the target's own (minted locally, saved sign-ins on the test site); a real emailed-code sign-in is TC-PRE-005/TC-PRE-007 in tests/qa/local/access-platform.spec.ts staging: needs a SHOP_OWNER test account "shopB" | P8: 2026-10-24 17:42
A9: TC-PRE-008 | B9: Preflight & smoke | C9: INF | D9: Seed data is sufficient | E9: Positive | F9: P0 | G9: Admin | H9: UI | J9: 1. Confirm: Shop A approved, delivering, pinned location, stock >= 20 on 3+ products, one packaged product with an MRP; Shop B approved in the same PIN selling at least one of the same master products at a different price; Customer 1 has an address with coordinates inside Shop A's radius and wallet >= Rs 2,000 One loose product (sold by weight) in the master. Category X with at least 5 master products: one with no catalogue price, one loose, one already listed by Shop A. Shop C approved with no products. | K9: All present. Create whatever is missing before starting and note it in the run log. | L9: QA plan section 0; Updated 3-Oct | M9: Fail | N9: Local Fail · Staging Blocked · Production Not run local: shop C has no products | expect(received).toBe(expected) // Object.is equality | Expected: 0 | Received: 10 staging: needs shop B in this site's test data | P9: 2026-10-24 17:12
A10: TC-PRE-009 | B10: Preflight & smoke | C10: INF, GS-071 | D10: Production is not touched by this run | E10: Security | F10: P0 | G10: All | H10: UI | J10: 1. Before every write action confirm the address bar host is test.gokesari.com | K10: No order, payment, suspension, settings change or registration is made on gokesari.com. Production checks in this suite are read-only smoke checks only. | L10: Test plan section 6 | M10: Pass | N10: Passed, partly covered. Local Pass (partial) · Staging Pass (partial) · Production Pass (partial) local: not covered: proves the suite cannot order, pay, suspend, change settings or register on gokesari.com; a person's manual discipline on production is outside automation ‖ not covered: proves the suite's guard; a manual run's discipline is outside automation staging: not covered: proves the suite's guard; a manual run's discipline is outside automation production: not covered: proves the suite's guard; a manual run's discipline is outside automation | P10: 2026-10-29 13:58
A11: TC-PRE-010 | B11: Preflight & smoke | C11: INF | D11: Production read-only smoke | E11: Regression | F11: P1 | G11: Guest | H11: UI | I11: Run last | J11: 1. Open https://gokesari.com/ , /shops, /search?q=milk, /signin, /legal/terms | K11: Pages load without errors. Do not sign in, order or submit any form on production. | L11: Deployment plan | M11: Pass | N11: Passed, partly covered. Local Pass (partial) · Staging Pass (partial) · Production Pass (partial) local: not covered: proves the suite cannot order, pay, suspend, change settings or register on gokesari.com; a person's manual discipline on production is outside automation ‖ not covered: 'Add to cart / subscribe prompts sign-in' is checked in TC-RBAC-001 add-to-cart below staging: not covered: 'Add to cart / subscribe prompts sign-in' is checked in TC-RBAC-001 add-to-cart below production: not covered: 'Add to cart / subscribe prompts sign-in' is checked in TC-RBAC-001 add-to-cart below | P11: 2026-10-29 14:00
A12: TC-PRE-011 | B12: Preflight & smoke | C12: INF, NEW-008, NEW-009, NEW-010 | D12: The 3-Oct requirements are deployed on test | E12: Positive | F12: P0 | G12: Shop | H12: UI | I12: Signed in as SHOP_OWNER A | J12: 1. Open a loose product on /shop/prices and check whether a price is pre-filled 2. Open the shop category screen and check whether the owner can add a product category 3. Open a packaged listing and check whether the MRP can be edited by the owner | K12: Record for each of NEW-008, NEW-009 and NEW-010 whether the behaviour is present. Any that is missing makes its cases below Blocked (not Fail) until the build is deployed. | L12: New requirements 3-Oct | M12: Pass | N12: Passed, partly covered. Local Pass (partial) · Staging Pass (partial) · Production Not run local: not covered: record-only (the case decides Blocked vs run for later modules); src/server/authz/permissions.ts documents the owner may dispute an MRP but never write it (§13) staging: not covered: record-only (the case decides Blocked vs run for later modules); src/server/authz/permissions.ts documents the owner may dispute an MRP but never write it (§13) | P12: 2026-10-24 17:12
A13: TC-PRE-012 | B13: Preflight & smoke | C13: INF | D13: The open features treated as completed are deployed on test | E13: Positive | F13: P0 | G13: Admin | H13: UI | I13: Signed in as ADMIN | J13: 1. Check on test for: SMS code at sign-in, SMS / WhatsApp / push channels, online payment at checkout, coupon field, scheduled slots, master order reference, shop KYC document upload, rider profile edit, image moderation queue, customer referral, home comparison widgets, shop-page offers, tax invoice, photo proof of delivery | K13: Record which are present. The 3-Oct open-features list shows these as not yet built; any that is missing makes its cases Blocked (not Fail) until deployed. | L13: Open features 3-Oct, treated as completed 4-Oct | M13: Pass | N13: Passed, partly covered. Local Pass (partial) · Staging Pass (partial) · Production Not run local: not covered: record-only: presence of each screen/API and the switch of its business rule; the features' own cases test their behaviour staging: not covered: record-only: presence of each screen/API and the switch of its business rule; the features' own cases test their behaviour | P13: 2026-10-24 17:13
A14: TC-AUTH-001 | B14: Login, onboarding & profile | C14: GS-001 | D14: New user signs up with an unused mobile number | E14: Positive | F14: P0 | G14: Guest | H14: UI | I14: Unused 10-digit mobile and unused email whose inbox can be read | J14: 1. Open /signin 2. Enter the mobile 3. Enter the email when asked 4. Enter the 6-digit code from the email | K14: Step 2 says the number is not registered yet and asks for an email. Message shows the masked email (ab***@...). Email subject is 'NNNNNN is your Gokesari sign-in code'. After the code, 'Tell us about you' opens with mobile pre-filled and email read-only. | L14: Login-profile checklist: New user via mobile | M14: Pass | N14: Passed, partly covered. Local Pass (partial) · Staging Not run (rule) · Production Not run local: not covered: step 2 no longer says 'not registered yet': the reply is the same for every number (expected result superseded by docs/login-profile/DEPLOY_AND_TEST.md 'New user via mobile' and src/components/otp-login-form.tsx) — the sign-up starts from 'Sign up with your email' staging: not run on staging: needs the server's database (local run only) | O14: D-99 | P14: 2026-10-24 17:05
A15: TC-AUTH-002 | B15: Login, onboarding & profile | C15: GS-001 | D15: First-time profile: details then address with geo-tag | E15: Positive | F15: P0 | G15: Customer | H15: UI | I15: Continue from previous case | J15: 1. Enter name and gender, Save 2. On 'Delivery address' tap 'Use my current location' (drag the pin if Maps is configured) 3. Fill the address fields, Save | K15: Lands on home. /profile shows name, gender, mobile, email and the default address with 'Geo-tagged at ...'. A wallet exists with balance 0. | L15: Login-profile checklist | M15: Pass | N15: Passed, partly covered. Local Pass (partial) · Staging Not run (rule) · Production Not run local: not covered: dragging the map pin needs a Google Maps key (not set locally): 'Use my current location' geo-tags the address staging: not run on staging: needs the server's database (local run only) | P15: 2026-10-24 17:05
A16: TC-AUTH-003 | B16: Login, onboarding & profile | C16: GS-001 | D16: Returning user signs in with registered mobile | E16: Positive | F16: P0 | G16: Guest | H16: UI | I16: Account from the previous cases | J16: 1. Sign out 2. Enter the same mobile 3. Enter the code | K16: Code goes straight to the account's email, shown masked. After the code, home opens with no onboarding form. | L16: Login-profile checklist; QA A-02..A-04 | M16: Pass | N16: Passed, partly covered. Local Pass (partial) · Staging Not run (rule) · Production Not run local: not covered: the account email is no longer shown masked for a mobile sign-in (expected result superseded by docs/login-profile/DEPLOY_AND_TEST.md 'Returning user via mobile': no address shown) staging: not run on staging: needs the server's database (local run only) | P16: 2026-10-24 17:05
A17: TC-AUTH-004 | B17: Login, onboarding & profile | C17: GS-001 | D17: New user signs up with email only | E17: Positive | F17: P0 | G17: Guest | H17: UI | I17: Unused email | J17: 1. Enter the email on /signin 2. Enter the code 3. Save details without a mobile 4. On the address step choose 'Fill in later' | K17: Account and wallet are created. Details form shows an empty mobile field. Home opens after 'Fill in later'. | L17: Login-profile checklist: New user via email | M17: Pass | N17: Local Pass · Staging Not run (rule) · Production Not run local: qa-auth-email-signup-mvmliqqd-89411c@test.local: account + wallet, details form with empty mobile, saved without a mobile, 'Fill in later' → home staging: not run on staging: needs the server's database (local run only) | P17: 2026-10-24 17:05
A18: TC-AUTH-005 | B18: Login, onboarding & profile | C18: GS-001 | D18: 'Add your mobile number' prompt for accounts without a mobile | E18: Positive | F18: P1 | G18: Customer | H18: UI | I18: Email-only account with details saved | J18: 1. Sign out and in again with the email 2. Click 'Not now' 3. Sign out and in again 4. Add a valid number in the popup 5. Sign out and in again | K18: Popup appears after each sign-in until a number is added. 'Not now' closes it. After adding a valid number it never appears again. | L18: Login-profile checklist | M18: Pass | N18: Passed, partly covered. Local Pass (partial) · Staging Not run (rule) · Production Not run local: not covered: the minute between sign-ins is simulated by ageing the codes staging: not run on staging: needs the server's database (local run only) | P18: 2026-10-24 17:05
A19: TC-AUTH-006 | B19: Login, onboarding & profile | C19: GS-001 | D19: Existing pre-release account is prompted once and keeps its data | E19: Regression | F19: P0 | G19: Customer | H19: UI | I19: An account created before migration 0037 with wallet balance and orders | J19: 1. Sign in (code, magic link or Google) | K19: Details form appears. Wallet balance and order history are unchanged. | L19: Login-profile checklist: Existing email-only user | M19: Pass | N19: Passed, partly covered. Local Pass (partial) · Staging Not run (rule) · Production Not run local: not covered: signed in by emailed code; the magic link is TC-AUTH-009, Google needs a Google account (TC-AUTH-008) staging: not run on staging: needs the server's database (local run only) | P19: 2026-10-24 17:05
A20: TC-AUTH-007 | B20: Login, onboarding & profile | C20: GS-001 | D20: Skip onboarding, then be asked at checkout | E20: Positive | F20: P0 | G20: Customer | H20: UI | I20: Brand-new account | J20: 1. Choose 'Fill in later' on step 1 2. Top up the wallet 3. Add an item from a delivering shop and open the cart 4. Add mobile and address 5. Place the order 6. Before saving details, sign out and in again (separate run) | K20: Home and wallet work after skipping. Cart shows 'Add your mobile number...' and 'Add a delivery address...' instead of the pay button. After adding both the pay button appears and the order carries the address. Unsaved profile shows the details form again at next sign-in. | L20: Login-profile checklist: Skip and fill in later | M20: Pass | N20: Passed, partly covered. Local Pass (partial) · Staging Not run (rule) · Production Not run local: not covered: the wallet top-up is settled in the database (a gateway payment is not available on a local production build); top-ups are covered by the wallet specs staging: not run on staging: needs the server's database (local run only) | P20: 2026-10-24 17:05
A21: TC-AUTH-008 | B21: Login, onboarding & profile | C21: GS-001 | D21: Google sign-in still works | E21: Regression | F21: P0 | G21: Guest | H21: UI | I21: A Google account | J21: 1. On /signin choose Google and complete the Google flow | K21: Signed in; session persists across page loads; wallet exists. | L21: QA plan section 12; Regression AUTH-01 | M21: Blocked | N21: Manual (not automatable): Local Manual · Staging Not run (rule) · Production Not run local: not automated: needs a Google account and Google OAuth keys (AUTH_GOOGLE_ID / AUTH_GOOGLE_SECRET are not set on the local server, whose sign-in page says 'Google sign-in is not configured'); run by hand on test.gokesari.com staging: not run on staging: needs the server's database (local run only) | P21: 2026-10-24 17:05
A22: TC-AUTH-009 | B22: Login, onboarding & profile | C22: GS-001 | D22: Email magic-link sign-in still works | E22: Regression | F22: P1 | G22: Guest | H22: UI | I22: SMTP configured | J22: 1. Request a sign-in link by email 2. Open the link | K22: Signed in. Link cannot be reused after sign-out. | L22: Dev log Wave 1; QA plan section 12 | M22: Pass | N22: Local Pass · Staging Not run (rule) · Production Not run local: link mailed and signed in; after signing out the same link → /signin?error=Verification, not signed in staging: not run on staging: needs the server's database (local run only) | P22: 2026-10-24 17:05
A23: TC-AUTH-010 | B23: Login, onboarding & profile | C23: GS-001 | D23: Mobile login channel step offers SMS and email | E23: Positive | F23: P2 | G23: Guest | H23: UI | J23: 1. Enter a registered mobile on /signin and look at the OTP destination step | K23: Email and SMS are both selectable. Choosing SMS sends the code by SMS (see the SMS cases added 4-Oct). | L23: QA A-02; Updated 4-Oct (feature treated as completed) | M23: Pass | N23: Passed, partly covered. Local Pass (partial) · Staging Not run (rule) · Production Not run local: not covered: SMS codes are a Phase 2 stub with no vendor (src/server/otp/providers.ts; docs/decision-log.md D-A02, D-F08), so no SMS option is offered and the SMS half needs a vendor and a handset staging: not run on staging: needs the server's database (local run only) | P23: 2026-10-24 17:05
A24: TC-AUTH-011 | B24: Login, onboarding & profile | C24: GS-001 | D24: No account enumeration on unregistered number | E24: Security | F24: P0 | G24: Guest | H24: UI+API | J24: 1. POST /api/otp/request for a registered number and for an unregistered one 2. Compare status, body and timing | K24: Flow never reveals whether another person's number or email has an account beyond what the designed 'not registered - enter your email' step shows to the person typing it; error and throttle responses are identical for known and unknown values. | L24: QA A-05 | M24: Pass | N24: Passed, partly covered. Local Pass (partial) · Staging Not run (rule) · Production Not run local: not covered: the designed 'Sign up with your email' link shows for every number (no 'not registered' message at all) staging: not run on staging: needs the server's database (local run only) | P24: 2026-10-24 17:05
A25: TC-AUTH-012 | B25: Login, onboarding & profile | C25: GS-001 | D25: Wrong code five times locks the code | E25: Negative | F25: P0 | G25: Guest | H25: UI | I25: Default otp rule (5 attempts) | J25: 1. Request a code 2. Enter a wrong code 5 times 3. Enter the correct code | K25: Each failure: 'That code is wrong or has expired...'. After 5, the right code is refused ('Too many wrong attempts'); a new code must be requested. | L25: QA A-06; Login-profile checklist | M25: Pass | N25: Local Pass · Staging Not run (rule) · Production Not run local: 5 × 'That code is wrong or has expired…'; the right code then → 'Too many wrong attempts. Request a new code.'; not signed in staging: not run on staging: needs the server's database (local run only) | P25: 2026-10-24 17:05
A26: TC-AUTH-013 | B26: Login, onboarding & profile | C26: GS-001 | D26: Expired code is refused | E26: Negative | F26: P1 | G26: Guest | H26: UI | I26: Default expiry 10 min (or set otp expiry to 1 min) | J26: 1. Request a code 2. Wait past expiry 3. Enter it | K26: Refused with the generic wrong/expired message. | L26: QA A-07 | M26: Pass | N26: Passed, partly covered. Local Pass (partial) · Staging Not run (rule) · Production Not run local: not covered: default expiry is now 5 minutes, not 10 (expected result superseded by docs/decision-log.md D-A01); the wait is simulated by moving the code's expiry into the past staging: not run on staging: needs the server's database (local run only) | P26: 2026-10-24 17:05
A27: TC-AUTH-014 | B27: Login, onboarding & profile | C27: GS-001 | D27: Older code is superseded by a newer one | E27: Negative | F27: P1 | G27: Guest | H27: UI | J27: 1. Request a code, wait 60 s, request another 2. Enter the first 3. Enter the second | K27: First refused, second works. | L27: QA A-08 | M27: Pass | N27: Passed, partly covered. Local Pass (partial) · Staging Not run (rule) · Production Not run local: not covered: the 60 s wait between the two codes is simulated by ageing the first code staging: not run on staging: needs the server's database (local run only) | P27: 2026-10-24 17:05
A28: TC-AUTH-015 | B28: Login, onboarding & profile | C28: GS-001 | D28: Used code cannot be replayed | E28: Security | F28: P0 | G28: Guest | H28: UI | J28: 1. Sign in with a code 2. Sign out 3. Try the same code again | K28: Refused. | L28: QA A-11 | M28: Pass | N28: Local Pass · Staging Not run (rule) · Production Not run local: signed in with 315641, signed out; the same code → "That code is wrong or has expired…"; no session staging: not run on staging: needs the server's database (local run only) | P28: 2026-10-24 17:05
A29: TC-AUTH-016 | B29: Login, onboarding & profile | C29: GS-001 | D29: Resend cooldown | E29: Boundary | F29: P1 | G29: Guest | H29: UI | I29: Default 60 s | J29: 1. Request a code 2. Click Resend immediately 3. Wait for the countdown, click Resend | K29: Resend is disabled with a countdown for 60 seconds; an immediate API call is refused with 'wait N seconds'. After the cooldown a new code arrives. | L29: QA A-09 | M29: Pass | N29: Local Pass · Staging Not run (rule) · Production Not run local: Resend disabled with a countdown; API at once → 429 "Please wait 60 seconds before requesting another code."; after 60 s Resend sent a new code (586989 → 652526) that signed in staging: not run on staging: needs the server's database (local run only) | P29: 2026-10-24 17:05
A30: TC-AUTH-017 | B30: Login, onboarding & profile | C30: GS-001 | D30: Hourly code limit per email / number | E30: Boundary | F30: P1 | G30: Guest | H30: UI+API | I30: Default 5 per hour | J30: 1. Request codes repeatedly for the same identifier (respecting cooldown) | K30: The 6th request is refused ('Too many code requests'). Unknown identifiers are throttled the same way. | L30: QA A-10 | M30: Pass | N30: Passed, partly covered. Local Pass (partial) · Staging Not run (rule) · Production Not run local: not covered: the 60 s between requests is simulated by ageing each code staging: not run on staging: needs the server's database (local run only) | P30: 2026-10-24 17:05
A31: TC-AUTH-018 | B31: Login, onboarding & profile | C31: GS-001 | D31: Per-IP request limit | E31: Boundary | F31: P2 | G31: Guest | H31: API | I31: Default 20 per IP per hour | J31: 1. Send more than 20 OTP requests for different identifiers from one browser | K31: Requests after the limit return 429 RATE_LIMITED with retryAfterSeconds. | L31: Login-profile rules; QA section 13 | M31: Pass | N31: Local Pass · Staging Not run (rule) · Production Not run local: 20 × 200 from 10.160.7.170; 21st → 429 RATE_LIMITED, retryAfterSeconds 3599; another IP still 200 staging: not run on staging: needs the server's database (local run only) | P31: 2026-10-24 17:05
A32: TC-AUTH-019 | B32: Login, onboarding & profile | C32: GS-001 | D32: Invalid mobile / email input | E32: Negative | F32: P1 | G32: Guest | H32: UI | J32: 1. Enter each of: 12345, 5876543210, abcdefghij, +91 5xxxxxxxxx, abc@, empty | K32: Clear field-level validation message each time. No email is sent. Only Indian mobiles (10 digits starting 6-9) are accepted. | L32: QA A-12; Login-profile checklist | M32: Pass | N32: Passed, partly covered. Local Pass (partial) · Staging Pass (partial) · Production Pass (partial) local: not covered: blank and over-254-character emails, and how a valid number is stored, run on the local tier ‖ not covered: a number typed with spaces is accepted and normalised, by design (src/lib/contact.ts: accepts "98765 43210") staging: not covered: blank and over-254-character emails, and how a valid number is stored, run on the local tier production: not covered: blank and over-254-character emails, and how a valid number is stored, run on the local tier | P32: 2026-10-29 14:00
A33: TC-AUTH-020 | B33: Login, onboarding & profile | C33: GS-001 | D33: Mobile already linked to another account | E33: Negative | F33: P0 | G33: Customer | H33: UI | I33: Two accounts; number linked to account 1 | J33: 1. On account 2 add the same number from profile, from the popup and during onboarding | K33: Each refuses: 'This mobile number is already linked to another account...'. | L33: QA A-13; Login-profile checklist | M33: Pass | N33: Passed, partly covered. Local Pass (partial) · Staging Blocked · Production Not run local: not covered: the onboarding-form half (first-time details) is in tests/qa/local/auth-profile.spec.ts; TC-AUTH-054: a free number is saved without an SMS code by design (numbers are not SMS-verified — docs/login-profile/DEPLOY_AND_TEST.md), so only a number already linked elsewhere is protected ‖ not covered: the My Profile and popup halves are in tests/qa/signed-in/auth-profile.spec.ts staging: customer 2 must have no mobile for the popup half | P33: 2026-10-24 18:06
A34: TC-AUTH-021 | B34: Login, onboarding & profile | C34: GS-001 | D34: Unregistered mobile + email that belongs to a different mobile | E34: Negative | F34: P1 | G34: Guest | H34: UI | I34: Account X has email E and mobile M1 | J34: 1. On /signin enter new mobile M2 2. Enter email E | K34: 'This email is already registered with a different mobile number...'. No account is changed. | L34: Login-profile checklist | M34: Pass | N34: Passed, partly covered. Local Pass (partial) · Staging Not run (rule) · Production Not run local: not covered: no 'already registered with a different mobile' refusal: the code goes to the email and signs in to its account (expected result superseded by docs/login-profile/DEPLOY_AND_TEST.md 'Duplicate mobile or email' and the comment in src/server/otp/service.ts requestLoginOtp — refusing would reveal which numbers have accounts) staging: not run on staging: needs the server's database (local run only) | P34: 2026-10-24 17:05
A35: TC-AUTH-022 | B35: Login, onboarding & profile | C35: GS-001, RBAC-013 | D35: Admin releases a claimed mobile number | E35: Positive | F35: P1 | G35: Admin | H35: UI | I35: Number M claimed by account 1 | J35: 1. Admin console -> 'Release a mobile number' -> enter M 2. On account 2 add M | K35: Release succeeds and is audited. Account 2 can now add M. Account 1 no longer shows it. | L35: Login-profile DEPLOY_AND_TEST | M35: Pass | N35: Local Pass · Staging Not run (rule) · Production Not run local: released +916210570509 from the console (audited by the admin); holder's profile shows no mobile; the claimant added it staging: not run on staging: needs the server's database (local run only) | P35: 2026-10-24 17:05
A36: TC-AUTH-023 | B36: Login, onboarding & profile | C36: GS-001 | D36: Edit name and gender on My Profile | E36: Positive | F36: P1 | G36: Customer | H36: UI | J36: 1. Open /profile 2. Change name and gender 3. Save details | K36: 'Saved' confirmation. Header initial updates. Values persist after reload. | L36: Login-profile checklist | M36: Pass | N36: Local Pass · Staging Pass · Production Not run local: name → "Zara QA mvmn5pup", gender → Male; 'Saved.'; header initial Z; both kept after reload ‖ [phone] name → "Zara QA mvml9j40", gender → Male; 'Saved.'; header initial Z; both kept after reload staging: name → "Zara QA mvmphu8y", gender → Male; 'Saved.'; header initial Z; both kept after reload ‖ [phone] name → "Zara QA mvmvdlwt", gender → Male; 'Saved.'; header initial Z; both kept after reload | P36: 2026-10-24 20:57
A37: TC-AUTH-024 | B37: Login, onboarding & profile | C37: GS-001 | D37: Change and remove mobile on My Profile | E37: Positive | F37: P1 | G37: Customer | H37: UI | J37: 1. Change mobile to a new valid number 2. Remove it 3. Open the cart with a delivery item | K37: New number shows; after removal it shows 'Not added' and the cart asks for a mobile again. A 'Mobile number changed' security notification is sent. | L37: Login-profile checklist; QA A-01, F-09 | M37: Fail | N37: Local Fail · Staging Pass (partial) · Production Not run local: add a delivery item — HTTP 409: This product is currently unavailable online. | expect(received).toContain(expected) // indexOf | Expected value: 409 | Received array: [200, 201] staging: not covered: the notice is checked in-app; its email copy follows the customer's notification settings (notification specs) | P37: 2026-10-24 18:06
A38: TC-AUTH-025 | B38: Login, onboarding & profile | C38: GS-001 | D38: Change email with verification on the new address | E38: Positive | F38: P0 | G38: Customer | H38: UI | I38: Inbox access for old and new address | J38: 1. Start a change of email 2. Enter a wrong code 3. Enter the right code 4. Sign out and sign in with the new email | K38: Code goes to the NEW address. Wrong code: error, email unchanged. Right code: email updated and the OLD address receives a 'was changed' email. New email signs in. | L38: Login-profile checklist | M38: Pass | N38: Local Pass · Staging Not run (rule) · Production Not run local: code to qa***@ ("NNNNNN is your Gokesari email confirmation code"); wrong code → error, email kept; right code → changed, old address mailed "was changed", audited; the new email signs in staging: not run on staging: needs the server's database (local run only) | P38: 2026-10-24 17:05
A39: TC-AUTH-026 | B39: Login, onboarding & profile | C39: GS-001 | D39: Change email to one used by another account | E39: Negative | F39: P1 | G39: Customer | H39: UI | J39: 1. Enter another account's email as the new email | K39: 'This email address is already used by another account.' | L39: Login-profile checklist | M39: Pass | N39: Local Pass · Staging Pass · Production Not run local: page and API (409) refuse qa***@test.local; email unchanged staging: page and API (409) refuse sa***@gmail.com; email unchanged | P39: 2026-10-24 18:06
A40: TC-AUTH-027 | B40: Login, onboarding & profile | C40: GS-001 | D40: Suspended account cannot sign in | E40: Security | F40: P0 | G40: Guest | H40: UI | I40: Account suspended by admin | J40: 1. Try mobile, email-code and Google sign-in | K40: All refused; /signin?error=AccessDenied explains the account is suspended or closed with a link to the grievance form. No session is created. | L40: QA A-14; Dev log Phase 4.5 | M40: Pass | N40: Passed, partly covered. Local Pass (partial) · Staging Not run (rule) · Production Not run local: not covered: Google sign-in is not configured on the local server (needs a Google account and OAuth keys); the emailed link is the next check staging: not run on staging: needs the server's database (local run only) | O40: D-19 | P40: 2026-10-24 17:05
...

Sheet E2E scenarios
A1: Scenario ID | B1: Scenario | C1: Workflows / features | D1: Priority | E1: Journey | F1: Expected outcome | G1: Status | H1: Notes
A2: SC-01 | B2: Customer buys from a local shop and receives it (wallet) | C2: WF-001, WF-002, WF-003, WF-005, WF-010 | D2: P0 | E2: 1. Customer signs in and sets a delivery location 2. Searches a product, opens Compare prices, picks the lowest-price delivering shop 3. Adds to cart, chooses address and delivery window, pays from wallet 4. Shop accepts, picks, packs, marks READY 5. Rider is offered automatically, accepts, enters the pickup code, starts delivery 6. Rider arrives, enters the customer's OTP - DELIVERED 7. Customer rates shop and rider 8. Admin opens the money trace: snapshot, commission, rider earning | F2: Order moves through every state with notifications at each step; wallet debited once; stock reduced; one finance snapshot; rider earning recorded; ratings saved. | G2: Pass | H2: [Run 2026-10-24 17:07: Local Pass · Staging Not run (rule) · Production Not run. local: DB-20261024-GQT21Y: compare page → QA Shop A mvmkyclr; window STANDARD_60; CONFIRMED → … → DELIVERED; customer notified 9× (order.confirmed, order.accepted, order.ready, order.rider_search, order.assigned, order.picked_up, order.out_for_delivery, rating.requested, order.delivered); rated 5/4; snapshot 0bp commission ₹0, earning ₹28.01 staging: not run on staging: needs the server's database (local run only)]
A3: SC-02 | B3: Multi-shop cart | C3: GS-025, GS-033 | D3: P0 | E3: 1. Add items from two delivering shops 2. Pay from wallet 3. Each shop fulfils independently; one is delivered, the other is rejected by the shop | F3: Two independent orders and debits; the rejected one is fully refunded with stock restored; the other completes. | G3: Pass | H3: [Run 2026-10-24 17:07: Local Pass · Staging Not run (rule) · Production Not run. local: DB-20261024-X42NMQ (A) delivered; DB-20261024-FON5AH (B) rejected → refunded ₹50, stock 10 again staging: not run on staging: needs the server's database (local run only)]
A4: SC-03 | B4: Item unavailable - substitution | C4: GS-035, GS-036 | D4: P0 | E4: 1. Place a 3-line order 2. Shop accepts, proposes a cheaper substitute for line 1 and removes line 2 3. Customer approves the substitute 4. Shop marks READY; delivery completes | F4: Difference and removed line refunded immediately; READY blocked until the customer decides; final snapshot uses the reduced goods value. | G4: Pass | H4: [Run 2026-10-24 17:07: Local Pass · Staging Not run (rule) · Production Not run. local: DB-20261024-B4FYYX: line 2 refunded ₹30 and the ₹8 difference at once; READY refused (409) until approval; delivered with goods ₹62 staging: not run on staging: needs the server's database (local run only)]
A5: SC-04 | B5: Shop rejects the order | C5: GS-034 | D5: P0 | E5: 1. Customer orders 2. Shop rejects with a reason | F5: Full refund, stock restored, customer notified with the reason, order never reaches a settlement. | G5: Pass | H5: [Run 2026-10-24 17:07: Local Pass · Staging Not run (rule) · Production Not run. local: DB-20261024-T9T7FT rejected: refunded ₹80, stock 5, notice "Your order DB-20261024-T9T7FT was cancelled: Rejected by shop: QA: our oven broke down" staging: not run on staging: needs the server's database (local run only)]
A6: SC-05 | B6: No rider available | C6: GA-009, RBAC-007 | D6: P0 | E6: 1. All riders offline; shop marks READY 2. Watch attempts until the search stops 3. A rider comes online; shop presses 'Try finding a rider again' 4. Delivery completes | F6: Bounded search with one notification at start and one at stop; restart offers the rider; order completes. | G6: Pass | H6: [Run 2026-10-24 17:07: Local Pass · Staging Not run (rule) · Production Not run. local: DB-20261024-I2KN5G: search stopped after 2 attempts (STOPPED); shop told delivery.unassigned → delivery.search_stopped; restarted, offered, delivered staging: not run on staging: needs the server's database (local run only)]
A7: SC-06 | B7: Rider declines / offer lapses | C7: GS-039, GA-009 | D7: P0 | E7: 1. Two riders online 2. Rider 1 declines (or lets 2 minutes pass) 3. Rider 2 accepts and delivers | F7: Rider 1 is never re-offered; only one active assignment at any time. | G7: Blocked | H7: [Run 2026-10-24 17:07: Local Blocked · Staging Not run (rule) · Production Not run. local: no delivery offer reached the rider for order 6abbb3b4-a55d-4d9d-993b-998aa2a8a752 within 45 s (rider offline or busy?) staging: not run on staging: needs the server's database (local run only)]
A8: SC-07 | B8: Customer unavailable - failed delivery and return to shop | C8: WF-005 | D8: P0 | E8: 1. Rider picks up and starts delivery 2. Rider reports customer not reachable 3. Shop marks RETURNED | F8: Order FAILED then cancelled and refunded per policy; rider paid per the failed-delivery rule; stock restored. | G8: Pass | H8: [Run 2026-10-24 17:07: Local Pass (partial) · Staging Not run (rule) · Production Not run. local: not covered: marking the goods RETURNED alone neither refunds nor restocks: the shop (or operations) then cancels the order, which does both staging: not run on staging: needs the server's database (local run only)]
A9: SC-08 | B9: Society authorised delivery | C9: WF-004, GA-001, GS-045, GS-046, GS-047 | D9: P0 | E9: 1. Society registered and verified; admin lists a rider and turns on exclusive riders and security notices 2. Resident joins, links an address, places an order 3. Shop marks READY 4. Only the listed rider is offered; accepts 5. Security staff notified; rider sees gate notes; delivers with OTP | F9: Dispatch honours the list; dashboard shows the delivery without PII. | G9: Pass | H9: [Run 2026-10-24 17:07: Local Pass · Staging Not run (rule) · Production Not run. local: DB-20261024-6LNKEX: offered to rider 2 only (rider 1 nearer, not listed); 'Delivery rider on the way' to society staff; rider saw "QA SC-08 Society mvmmqb1z Gate: Security calls the resident before letting you in QA SC-08: use gate 2, park by the club house mvmmqb1z"; delivered with the code; dashboard row createdAt, orderNumber, promisedByAt, riderName, riderVehicle, riderVehicleNumber, shopName, status, unitLabel — no PII staging: not run on staging: needs the server's database (local run only)]
A10: SC-09 | B10: Daily milk subscription | C10: WF-006, GS-048, GS-050, GS-051 | D10: P0 | E10: 1. Top up the wallet 2. Subscribe to 2 L/day of milk 3. Daily-orders cron runs for the start date, then again 4. Change tomorrow to 3 L; skip the day after; pause the following two days 5. Run the cron for each date 6. Let the wallet run short one day, then top up and retry | F10: Rs 140 then Rs 210 charged once each; no order on skipped/paused days; the failed day is recovered by retry with a single debit. | G10: Pass | H10: [Run 2026-10-24 17:07: Local Pass · Staging Not run (rule) · Production Not run. local: 2026-10-25 CONFIRMED ₹140; 2026-10-26 CONFIRMED ₹210; 2026-10-30 CONFIRMED ₹140; second retry → 409 staging: not run on staging: needs the server's database (local run only)]
A11: SC-10 | B11: Return and refund with rider pickup | C11: WF-007, GS-057 | D11: P0 | E11: 1. Customer requests a return on a delivered order with a photo 2. Shop approves 3. Rider accepts the pickup, enters the handover code 4. Shop receives, inspects and accepts a partial amount 5. Refund completes | F11: Each status visible to the customer; wallet credited once; shop share adjusted in the next settlement; rider paid the pickup fee. | G11: Pass | H11: [Run 2026-10-24 17:07: Local Pass (partial) · Staging Not run (rule) · Production Not run. local: not covered: TC-FIN-019's 'return-pickup fee in the payout' is shown as the fee in the rider's unpaid statement, which the weekly payout batches staging: not run on staging: needs the server's database (local run only)]
A12: SC-11 | B12: Cancellation at every stage (D10) | C12: NEW-006 | D12: P0 | E12: 1. Place 7 orders and bring them to CONFIRMED, ACCEPTED, PREPARING, READY, ASSIGNED, PICKED_UP, OUT_FOR_DELIVERY 2. Customer tries to cancel each 3. Shop cancels the ones the customer could not | F12: Customer: allowed at CONFIRMED (full refund), blocked at four middle states, goods-only after pickup. Shop: full refund always. | G12: Pass | H12: [Run 2026-10-24 17:07: Local Pass · Staging Not run (rule) · Production Not run. local: CONFIRMED customer ✓ ₹20; ACCEPTED customer ✗ (409) → shop ✓ ₹20; PREPARING customer ✗ (409) → shop ✓ ₹20; READY customer ✗ (409) → shop ✓ ₹20; ASSIGNED customer ✗ (409) → shop ✓ ₹20; PICKED_UP customer ✓ ₹20; OUT_FOR_DELIVERY customer ✓ ₹20 staging: not run on staging: needs the server's database (local run only)]
... A38: SC-37 | B38: Signed-in test run by the Claude QA agent | C38: QA-011, QA-010 | D38: P1 | E38: 1. The agent signs the staging test accounts in with the emailed codes (owner's mailbox) 2. It runs the signed-in tier on test.gokesari.com 3. It collects the results and rebuilds the register | F38: A staging run with signed-in checks that passed (so the sessions worked), collected into docs/testing/qa-runs. | G38: Pass | H38: Added 24-Oct (QA automation) [Run 2026-10-29 13:59: Local Blocked · Staging Pass · Production Pass. local: needs a collected staging run with signed-in checks staging: 177 signed-in checks passed on test.gokesari.com (133 case IDs) production: 177 signed-in checks passed on test.gokesari.com (133 case IDs)]

Sheet Coverage
A1: Feature ID | B1: Module | C1: Feature | D1: Development status | E1: Test cases | F1: TC IDs | G1: Not-yet-testable part
A2: RBAC-002 | B2: Security | C2: Place order (Customer, Admin only) | D2: COMPLETED | E2: 4 | F2: TC-RBAC-016, TC-RBAC-017, TC-RBAC-018, TC-SPI-007
A3: RBAC-007 | B3: Security | C3: Assign delivery | D3: COMPLETED (2-Oct) | E3: 4 | F3: TC-DSP-009, TC-DSP-010, TC-DSP-014, TC-DSP-015
A4: RBAC-003 | B4: Security | C4: Manage own shop (Operator Limited) | D4: UNCLEAR | E4: 1 | F4: TC-RBAC-008 | G4: Part not built: Operator 'Limited' shop management
A5: GS-002 | B5: Identity & Access | C5: Role-based access control | D5: COMPLETED | E5: 10 | F5: TC-RBAC-001, TC-RBAC-002, TC-RBAC-003, TC-RBAC-004, TC-RBAC-005, TC-RBAC-006, TC-RBAC-024, TC-AUTH-033, TC-CAT-048, TC-SPI-027
