Workbook

Sheet Inventory
A1: ID | B1: Module | C1: Feature | D1: Frontend | E1: Backend | F1: Database | G1: API | H1: Status | I1: Working? | J1: Location | K1: Notes
A2: AUTH-01 | B2: Authentication | C2: Google OAuth sign-in (Auth.js v5, Drizzle adapter) | D2: Yes | E2: Yes | F2: Yes | G2: Yes | H2: EXISTING_WORKING | I2: Yes in use on hosted envs; not automatable here | J2: src/server/auth.ts; /signin; /api/auth/[...nextauth] | K2: JWT sessions (30 d) - older docs still say database sessions. New user => CUSTOMER role + wallet + TERMS_AND_PRIVACY consent. Providers probe 2026-09-22: hosted test and live expose only 'google'.
A3: AUTH-02 | B3: Authentication | C3: Dev/test credentials sign-in (email only) | D3: Yes | E3: Yes | F3: Yes | G3: Yes | H3: EXISTING_WORKING | I3: Yes - code-verified only (no dedicated test) | J3: src/server/auth.ts:47-87 | K3: Disabled when NODE_ENV=production (provider list and authorize()). Verified absent on test.gokesari.com and gokesari.com.
A4: AUTH-03 | B4: Authentication | C4: Role and status re-read from DB on every request; suspended/deleted accounts get no session | D4: n/a | E4: Yes | F4: Yes | G4: n/a | H4: EXISTING_WORKING | I4: Yes - automated tests pass | J4: src/server/auth.ts:109-157; src/server/authz/guards.ts:25-36 | K4: Stale JWT cannot keep old privileges.
A5: AUTH-04 | B5: Authentication | C5: Bootstrap admin (BOOTSTRAP_ADMIN_EMAILS + two permanent emails in source) | D5: n/a | E5: Yes | F5: Yes | G5: n/a | H5: EXISTING_PARTIAL | I5: Yes - code-verified only (no dedicated test) | J5: src/lib/env.ts:137-158; src/server/auth.ts:139-148 | K5: Works, but two personal admin emails are hard-coded and re-promoted to ADMIN on every session (finding SEC-03).
A6: AUTH-05 | B6: Authentication | C6: Phone number capture / OTP verification | D6: No | E6: No | F6: Partial | G6: No | H6: MISSING | I6: n/a - not built | J6: users.phone (nullable, unverified) | K6: No SMS/OTP provider exists anywhere in the codebase.
A7: AUTH-06 | B7: Authentication | C7: Profile page (name, email, role, addresses link, sign-out, notification list) | D7: Yes | E7: Partial | F7: Yes | G7: No | H7: EXISTING_PARTIAL | I7: Yes - code-verified only (no dedicated test) | J7: src/app/profile/page.tsx | K7: Read-only: no API/UI to edit name or phone. Notification list is shown here (no bell, no mark-read control).
A8: RBAC-01 | B8: RBAC | C8: Server-side capability matrix: 5 roles (CUSTOMER, SHOP_OWNER, OPERATOR, ADMIN, DELIVERY_PARTNER), ~76 permissions | D8: n/a | E8: Yes | F8: Yes | G8: Yes | H8: EXISTING_WORKING | I8: Yes - automated tests pass | J8: src/server/authz/permissions.ts | K8: 27 permissions are never referenced by name outside the matrix (ownership or role logic enforces some; some are unused).
A9: RBAC-02 | B9: RBAC | C9: Ownership guards (requireShopAccess, requireSubscriptionAccess) - IDOR protection | D9: n/a | E9: Yes | F9: Yes | G9: Yes | H9: EXISTING_PARTIAL | I9: Partly - see notes | J9: src/server/authz/guards.ts:83-122 | K9: Blocks a genuine cross-user IDOR (a different user's shop/subscription) - that part works and is tested. But 'capability and ownership are both checked' is not true for requireShopAccess's OWNER branch: it returns as soon as shop.ownerId matches, before any can() call, so role demotion and shop suspension do not revoke a shop owner's own write access (finding SEC-06, found on Opus review 2026-09-22).
A10: RBAC-03 | B10: RBAC | C10: Admin sets a user's role | D10: Yes | E10: Yes | F10: Yes | G10: Yes | H10: EXISTING_WORKING | I10: Yes - automated tests pass | J10: /api/users/[id]/role; src/components/user-role-manager.tsx | K10: Role never accepted from a request body except this ADMIN route.
A11: RBAC-04 | B11: RBAC | C11: roles / permissions / role_permissions tables | D11: n/a | E11: Partial | F11: Yes | G11: n/a | H11: EXISTING_PARTIAL | I11: Yes - code-verified only (no dedicated test) | J11: src/server/db/schema.ts:465-487; src/server/db/seed.ts | K11: Seeded mirror for reporting only; runtime checks use the in-code matrix.
A12: RBAC-05 | B12: RBAC | C12: Suspend a user account | D12: No | E12: Partial | F12: Yes | G12: No | H12: EXISTING_PLACEHOLDER | I12: Service layer only - tested, but no API route or UI reaches it | J12: USER_SUSPEND permission (unused); auth.ts honours status=SUSPENDED | K12: No route or screen sets a user to SUSPENDED.
A13: RBAC-06 | B13: RBAC | C13: Shop Staff role (sub-users of a shop) | D13: No | E13: No | F13: No | G13: No | H13: MISSING | I13: n/a - not built | J13: - | K13: Only the shop owner can act for a shop.
A14: RBAC-07 | B14: RBAC | C14: Society Administrator role | D14: No | E14: No | F14: No | G14: No | H14: MISSING | I14: n/a - not built | J14: -
A15: RBAC-08 | B15: RBAC | C15: Super Admin role | D15: No | E15: No | F15: No | G15: No | H15: MISSING | I15: n/a - not built | J15: - | K15: ADMIN is the highest role today; decide whether a distinct role is really required.
A16: RBAC-09 | B16: RBAC | C16: System configuration UI (SYSTEM_CONFIG) | D16: No | E16: No | F16: No | G16: No | H16: EXISTING_PLACEHOLDER | I16: n/a - not built | J16: SYSTEM_CONFIG permission (unused) | K16: Only registration-fee and delivery-earnings configuration screens exist.
A17: CUS-01 | B17: Customer | C17: Address book: create/edit/delete, default, landmark, delivery instructions | D17: Yes | E17: Yes | F17: Yes | G17: Yes | H17: EXISTING_WORKING | I17: Yes - automated tests pass | J17: /profile/addresses; /api/addresses*; src/server/services/addresses.ts
A18: CUS-02 | B18: Customer | C18: Map picker + Google Geocoding (verify once, store coordinates) | D18: Yes | E18: Yes | F18: Yes | G18: Yes | H18: EXISTING_WORKING | I18: Yes - automated tests pass | J18: src/components/map-picker.tsx; /api/geo/verify-location; geocoding.ts | K18: Needs Google keys; falls back to manual entry. Tests stub fetch.
A19: CUS-03 | B19: Customer | C19: Society / block / flat on an address | D19: No | E19: No | F19: No | G19: No | H19: MISSING | I19: n/a - not built | J19: addresses table has line1/line2/area/landmark only
A20: CUS-04 | B20: Customer | C20: Browse categories and department pages | D20: Yes | E20: Yes | F20: Yes | G20: Yes | H20: EXISTING_WORKING | I20: Yes - code-verified only (no dedicated test) | J20: /categories; /category/[type]; /dairy; /bakery | K20: Not covered by an automated UI test; Playwright suite was not runnable here.
A21: CUS-05 | B21: Customer | C21: Shop discovery: list and filter by city, area, PIN, type, classification, delivery | D21: Yes | E21: Yes | F21: Yes | G21: Yes | H21: EXISTING_WORKING | I21: Yes - code-verified only (no dedicated test) | J21: /shops; GET /api/shops; shops.ts:679-718 | K21: Text/PIN filters only.
A22: CUS-06 | B22: Customer | C22: Nearby shops by customer location / sort by distance | D22: No | E22: No | F22: Partial | G22: No | H22: MISSING | I22: n/a - not built | J22: shops.latitude/longitude exist | K22: searchShops has no geospatial filter or ordering (orders by name).
A23: CUS-07 | B23: Customer | C23: Shop storefront page with catalogue | D23: Yes | E23: Yes | F23: Yes | G23: Yes | H23: EXISTING_WORKING | I23: Yes - code-verified only (no dedicated test) | J23: /shops/[slug]; catalogue.ts:listStorefrontProducts
A24: CUS-08 | B24: Customer | C24: Unified search (products, shops, area, PIN) | D24: Yes | E24: Yes | F24: Yes | G24: Yes | H24: EXISTING_WORKING | I24: Yes - code-verified only (no dedicated test) | J24: /search; catalogue.ts:867-947 | K24: ILIKE substring match; no relevance ranking, typo tolerance or synonyms.
A25: CUS-09 | B25: Customer | C25: Product detail page | D25: No | E25: No | F25: Yes | G25: No | H25: MISSING | I25: n/a - not built | J25: - | K25: Product cards only; no /product/[id] page.
A26: CUS-10 | B26: Customer | C26: All shops selling one product + local price comparison | D26: No | E26: Partial | F26: Yes | G26: No | H26: EXISTING_PARTIAL | I26: Partly - see notes | J26: products <-> shop_products (GTIN partial-unique) | K26: Data supports it; search returns one row per shop-product, ungrouped, no sort by price/distance/ETA and no comparison view.
A27: CUS-11 | B27: Customer | C27: External e-commerce price references | D27: No | E27: Partial | F27: Yes | G27: Partial | H27: EXISTING_PARTIAL | I27: Partly - see notes | J27: pmd.offers, price history; /api/product-master/products/[id]/offers | K27: Staff-only. Open data only; every marketplace source is BLOCKED_NEEDS_AGREEMENT by policy (no scraping). Not shown to customers.
A28: CUS-12 | B28: Customer | C28: Cart: multi-shop grouping, live prices, purchasable flag, per-shop delivery fee | D28: Yes | E28: Yes | F28: Yes | G28: Yes | H28: EXISTING_WORKING | I28: Yes - automated tests pass | J28: /cart; /api/cart*; cart.ts
A29: CUS-13 | B29: Customer | C29: Checkout: wallet-paid, one order per shop, idempotent requestId, atomic stock + debit | D29: Yes | E29: Yes | F29: Yes | G29: Yes | H29: EXISTING_WORKING | I29: Yes - automated tests pass | J29: POST /api/checkout; orders.ts:113-307 | K29: Wallet is the only payment instrument (see PAY-06).
A30: CUS-14 | B30: Customer | C30: Delivery window at checkout (Express 30 / Standard 60 / Scheduled) with live feasibility | D30: Yes | E30: Yes | F30: Yes | G30: Yes | H30: EXISTING_WORKING | I30: Yes - automated tests pass | J30: GET /api/checkout/delivery-windows; delivery-feasibility.ts | K30: 'SCHEDULED' carries no date/time slot. Feasibility treats only ACCEPTED as busy (DEF-05).
A31: CUS-15 | B31: Customer | C31: Serviceability check (address inside shop's delivery reach) | D31: No | E31: No | F31: No | G31: No | H31: MISSING | I31: n/a - not built | J31: - | K31: Only rider availability is checked; shops have a delivery on/off flag but no radius or area.
A32: CUS-16 | B32: Customer | C32: Order history list | D32: Yes | E32: Yes | F32: Yes | G32: Yes | H32: EXISTING_WORKING | I32: Yes - code-verified only (no dedicated test) | J32: /orders; GET /api/orders
A33: CUS-17 | B33: Customer | C33: Order detail / live tracking (timeline, rider, ETA, map) | D33: No | E33: Partial | F33: Yes | G33: No | H33: MISSING | I33: n/a - not built | J33: order_status_history table; orders.ts:getOrder (no caller) | K33: No GET /api/orders/[id] and no detail page; rider location is stored but never shown to customers.
A34: CUS-18 | B34: Customer | C34: Cancel order with automatic wallet refund (idempotent) | D34: Yes | E34: Yes | F34: Yes | G34: Yes | H34: EXISTING_PARTIAL | I34: Partly - see notes | J34: PATCH /api/orders/[id]/status; orders.ts:372-441 | K34: Does NOT return stock (finding DEF-01). More significantly: has NO cancellation policy at all - a customer can cancel their own order from any pre-terminal status including OUT_FOR_DELIVERY, no time window, no fee, and ORDER_CANCEL_OWN is defined but never actually enforced anywhere (finding DEF-08, found on Opus review 2026-09-22). The refund includes the delivery fee, and an active rider assignment is orphaned rather than cancelled or reassigned.
A35: CUS-19 | B35: Customer | C35: Refund / return / replacement request | D35: No | E35: No | F35: No | G35: No | H35: MISSING | I35: n/a - not built | J35: - | K35: Refund exists only as the automatic result of a cancellation.
A36: CUS-20 | B36: Customer | C36: Ratings and reviews (shop, gig worker, product) | D36: No | E36: No | F36: No | G36: No | H36: MISSING | I36: n/a - not built | J36: -
A37: CUS-21 | B37: Customer | C37: Vouchers: wallet top-up bonus (code or auto-apply, budgets, redemption ledger) | D37: Yes | E37: Yes | F37: Yes | G37: Yes | H37: EXISTING_WORKING | I37: Yes - automated tests pass | J37: vouchers.ts; /api/vouchers*; voucher-manager.tsx | K37: Applies to wallet top-ups, not to order totals.
A38: CUS-22 | B38: Customer | C38: Coupons / discounts applied at checkout | D38: No | E38: No | F38: No | G38: No | H38: MISSING | I38: n/a - not built | J38: -
A39: CUS-23 | B39: Customer | C39: Customer referral programme | D39: No | E39: No | F39: No | G39: No | H39: MISSING | I39: n/a - not built | J39: - | K39: referral_codes exist but attribute SHOPS to operator-managed codes.
A40: CUS-24 | B40: Customer | C40: Grievance / complaint form and public ticket lookup (IT Rules 2021) | D40: Yes | E40: Yes | F40: Yes | G40: Yes | H40: EXISTING_WORKING | I40: Yes - automated tests pass | J40: /grievance; /api/grievances* | K40: A compliance register, not an order-linked helpdesk or chat.
...

Sheet Summary
A1: Existing feature inventory - summary
A2: Counts are live formulas over the Inventory sheet (recalculated when the file is opened). The blue 'Snapshot' column is the value at generation time, for cross-checking.
A4: Status | B4: Count (formula) | C4: Snapshot | D4: Share (formula)
A5: EXISTING_WORKING | B5: =COUNTIF(Inventory!$H$2:$H$159,A5) | C5: 70 | D5: =B5/$B$10
A6: EXISTING_PARTIAL | B6: =COUNTIF(Inventory!$H$2:$H$159,A6) | C6: 22 | D6: =B6/$B$10
A7: EXISTING_BROKEN | B7: =COUNTIF(Inventory!$H$2:$H$159,A7) | C7: 2 | D7: =B7/$B$10
A8: EXISTING_PLACEHOLDER | B8: =COUNTIF(Inventory!$H$2:$H$159,A8) | C8: 11 | D8: =B8/$B$10
A9: MISSING | B9: =COUNTIF(Inventory!$H$2:$H$159,A9) | C9: 53 | D9: =B9/$B$10
A10: Total | B10: =SUM(B5:B9) | C10: 158
A11: Rows in Inventory (check) | B11: =COUNTA(Inventory!$A$2:$A$159)
A13: By module (formulas)
A14: Module | B14: EXISTING_WORKING | C14: EXISTING_PARTIAL | D14: EXISTING_BROKEN | E14: EXISTING_PLACEHOLDER | F14: MISSING | G14: Total
A15: Authentication | B15: =COUNTIFS(Inventory!$B$2:$B$159,$A15,Inventory!$H$2:$H$159,B$14) | C15: =COUNTIFS(Inventory!$B$2:$B$159,$A15,Inventory!$H$2:$H$159,C$14) | D15: =COUNTIFS(Inventory!$B$2:$B$159,$A15,Inventory!$H$2:$H$159,D$14) | E15: =COUNTIFS(Inventory!$B$2:$B$159,$A15,Inventory!$H$2:$H$159,E$14) | F15: =COUNTIFS(Inventory!$B$2:$B$159,$A15,Inventory!$H$2:$H$159,F$14) | G15: =SUM(B15:F15)
A16: RBAC | B16: =COUNTIFS(Inventory!$B$2:$B$159,$A16,Inventory!$H$2:$H$159,B$14) | C16: =COUNTIFS(Inventory!$B$2:$B$159,$A16,Inventory!$H$2:$H$159,C$14) | D16: =COUNTIFS(Inventory!$B$2:$B$159,$A16,Inventory!$H$2:$H$159,D$14) | E16: =COUNTIFS(Inventory!$B$2:$B$159,$A16,Inventory!$H$2:$H$159,E$14) | F16: =COUNTIFS(Inventory!$B$2:$B$159,$A16,Inventory!$H$2:$H$159,F$14) | G16: =SUM(B16:F16)
A17: Customer | B17: =COUNTIFS(Inventory!$B$2:$B$159,$A17,Inventory!$H$2:$H$159,B$14) | C17: =COUNTIFS(Inventory!$B$2:$B$159,$A17,Inventory!$H$2:$H$159,C$14) | D17: =COUNTIFS(Inventory!$B$2:$B$159,$A17,Inventory!$H$2:$H$159,D$14) | E17: =COUNTIFS(Inventory!$B$2:$B$159,$A17,Inventory!$H$2:$H$159,E$14) | F17: =COUNTIFS(Inventory!$B$2:$B$159,$A17,Inventory!$H$2:$H$159,F$14) | G17: =SUM(B17:F17)
A18: Shop | B18: =COUNTIFS(Inventory!$B$2:$B$159,$A18,Inventory!$H$2:$H$159,B$14) | C18: =COUNTIFS(Inventory!$B$2:$B$159,$A18,Inventory!$H$2:$H$159,C$14) | D18: =COUNTIFS(Inventory!$B$2:$B$159,$A18,Inventory!$H$2:$H$159,D$14) | E18: =COUNTIFS(Inventory!$B$2:$B$159,$A18,Inventory!$H$2:$H$159,E$14) | F18: =COUNTIFS(Inventory!$B$2:$B$159,$A18,Inventory!$H$2:$H$159,F$14) | G18: =SUM(B18:F18)
A19: Catalogue | B19: =COUNTIFS(Inventory!$B$2:$B$159,$A19,Inventory!$H$2:$H$159,B$14) | C19: =COUNTIFS(Inventory!$B$2:$B$159,$A19,Inventory!$H$2:$H$159,C$14) | D19: =COUNTIFS(Inventory!$B$2:$B$159,$A19,Inventory!$H$2:$H$159,D$14) | E19: =COUNTIFS(Inventory!$B$2:$B$159,$A19,Inventory!$H$2:$H$159,E$14) | F19: =COUNTIFS(Inventory!$B$2:$B$159,$A19,Inventory!$H$2:$H$159,F$14) | G19: =SUM(B19:F19)
A20: Inventory | B20: =COUNTIFS(Inventory!$B$2:$B$159,$A20,Inventory!$H$2:$H$159,B$14) | C20: =COUNTIFS(Inventory!$B$2:$B$159,$A20,Inventory!$H$2:$H$159,C$14) | D20: =COUNTIFS(Inventory!$B$2:$B$159,$A20,Inventory!$H$2:$H$159,D$14) | E20: =COUNTIFS(Inventory!$B$2:$B$159,$A20,Inventory!$H$2:$H$159,E$14) | F20: =COUNTIFS(Inventory!$B$2:$B$159,$A20,Inventory!$H$2:$H$159,F$14) | G20: =SUM(B20:F20)
A21: Orders | B21: =COUNTIFS(Inventory!$B$2:$B$159,$A21,Inventory!$H$2:$H$159,B$14) | C21: =COUNTIFS(Inventory!$B$2:$B$159,$A21,Inventory!$H$2:$H$159,C$14) | D21: =COUNTIFS(Inventory!$B$2:$B$159,$A21,Inventory!$H$2:$H$159,D$14) | E21: =COUNTIFS(Inventory!$B$2:$B$159,$A21,Inventory!$H$2:$H$159,E$14) | F21: =COUNTIFS(Inventory!$B$2:$B$159,$A21,Inventory!$H$2:$H$159,F$14) | G21: =SUM(B21:F21)
A22: Payments | B22: =COUNTIFS(Inventory!$B$2:$B$159,$A22,Inventory!$H$2:$H$159,B$14) | C22: =COUNTIFS(Inventory!$B$2:$B$159,$A22,Inventory!$H$2:$H$159,C$14) | D22: =COUNTIFS(Inventory!$B$2:$B$159,$A22,Inventory!$H$2:$H$159,D$14) | E22: =COUNTIFS(Inventory!$B$2:$B$159,$A22,Inventory!$H$2:$H$159,E$14) | F22: =COUNTIFS(Inventory!$B$2:$B$159,$A22,Inventory!$H$2:$H$159,F$14) | G22: =SUM(B22:F22)
A23: Wallet | B23: =COUNTIFS(Inventory!$B$2:$B$159,$A23,Inventory!$H$2:$H$159,B$14) | C23: =COUNTIFS(Inventory!$B$2:$B$159,$A23,Inventory!$H$2:$H$159,C$14) | D23: =COUNTIFS(Inventory!$B$2:$B$159,$A23,Inventory!$H$2:$H$159,D$14) | E23: =COUNTIFS(Inventory!$B$2:$B$159,$A23,Inventory!$H$2:$H$159,E$14) | F23: =COUNTIFS(Inventory!$B$2:$B$159,$A23,Inventory!$H$2:$H$159,F$14) | G23: =SUM(B23:F23)
A24: Subscriptions | B24: =COUNTIFS(Inventory!$B$2:$B$159,$A24,Inventory!$H$2:$H$159,B$14) | C24: =COUNTIFS(Inventory!$B$2:$B$159,$A24,Inventory!$H$2:$H$159,C$14) | D24: =COUNTIFS(Inventory!$B$2:$B$159,$A24,Inventory!$H$2:$H$159,D$14) | E24: =COUNTIFS(Inventory!$B$2:$B$159,$A24,Inventory!$H$2:$H$159,E$14) | F24: =COUNTIFS(Inventory!$B$2:$B$159,$A24,Inventory!$H$2:$H$159,F$14) | G24: =SUM(B24:F24)
A25: Delivery | B25: =COUNTIFS(Inventory!$B$2:$B$159,$A25,Inventory!$H$2:$H$159,B$14) | C25: =COUNTIFS(Inventory!$B$2:$B$159,$A25,Inventory!$H$2:$H$159,C$14) | D25: =COUNTIFS(Inventory!$B$2:$B$159,$A25,Inventory!$H$2:$H$159,D$14) | E25: =COUNTIFS(Inventory!$B$2:$B$159,$A25,Inventory!$H$2:$H$159,E$14) | F25: =COUNTIFS(Inventory!$B$2:$B$159,$A25,Inventory!$H$2:$H$159,F$14) | G25: =SUM(B25:F25)
A26: Society | B26: =COUNTIFS(Inventory!$B$2:$B$159,$A26,Inventory!$H$2:$H$159,B$14) | C26: =COUNTIFS(Inventory!$B$2:$B$159,$A26,Inventory!$H$2:$H$159,C$14) | D26: =COUNTIFS(Inventory!$B$2:$B$159,$A26,Inventory!$H$2:$H$159,D$14) | E26: =COUNTIFS(Inventory!$B$2:$B$159,$A26,Inventory!$H$2:$H$159,E$14) | F26: =COUNTIFS(Inventory!$B$2:$B$159,$A26,Inventory!$H$2:$H$159,F$14) | G26: =SUM(B26:F26)
... A31: Platform | B31: =COUNTIFS(Inventory!$B$2:$B$159,$A31,Inventory!$H$2:$H$159,B$14) | C31: =COUNTIFS(Inventory!$B$2:$B$159,$A31,Inventory!$H$2:$H$159,C$14) | D31: =COUNTIFS(Inventory!$B$2:$B$159,$A31,Inventory!$H$2:$H$159,D$14) | E31: =COUNTIFS(Inventory!$B$2:$B$159,$A31,Inventory!$H$2:$H$159,E$14) | F31: =COUNTIFS(Inventory!$B$2:$B$159,$A31,Inventory!$H$2:$H$159,F$14) | G31: =SUM(B31:F31)
A32: Total | B32: =SUM(B15:B31) | C32: =SUM(C15:C31) | D32: =SUM(D15:D31) | E32: =SUM(E15:E31) | F32: =SUM(F15:F31) | G32: =SUM(G15:G31)

Sheet Legend
A1: Legend and method
A3: Scope | B3: GoKesari Next.js app, repo D:\Claude_development\bkesari, audited 2026-09-22. Base: e76ccf2 (branch feature/pmd-review-decide; content equals origin/staging 40ba7b4). Includes explicit MISSING rows for target features so nothing is silently absent.
A4: EXISTING_WORKING | B4: Built, reachable and verified. Verified means: code read AND (automated tests pass OR marked 'code-verified only').
A5: EXISTING_PARTIAL | B5: Works but is incomplete, or has a defect/hole that must be fixed, or is reachable only in part.
A6: EXISTING_BROKEN | B6: Behaves incorrectly today. Confirmed by code reading; a reproducing test is the first step of the fix.
A7: EXISTING_PLACEHOLDER | B7: A type, permission, setting or service exists but nothing uses it, or it does nothing.
A8: MISSING | B8: Not built.
A9: Frontend / Backend / Database / API | B9: Yes = present and connected; Partial = present but not fully connected; No = absent; n/a = does not apply.
A10: Working? | B10: 'Yes - automated tests pass' = the named suites pass in the baseline. 'Service layer only' = the logic is tested but no route or screen calls it. Browser rendering was not exercised (no Playwright browser installed).
A11: Reachability method | B11: Every exported service function (241) was searched for callers in src/app, src/components and src/lib; functions with none are reported as service-only.
A12: Evidence | B12: docs/gokesari-audit/evidence/ (vitest JSON + log, build log, route scan). Findings referenced here (SEC-*, DEF-*) are in GOKESARI_AUDIT_FINDINGS.md.
