Workbook

Sheet Summary
A1: GoKesari (gokesari.com) - consolidated feature, process flow and PR status
A2: As of 29 Oct 2026, 20:00 IST. Production main 4585627 (#287, Release 29 Oct (6)). Ten production releases since the 25 Oct report (#266 to #287); migrations 0097-0117.
A3: Baseline = the 25 Oct status report. Added: 58 features (28 dealer programme, 30 other), flows F16-F18, PRs #250-#289, 239 new functions, 71 new pages / API routes, flow diagrams. Updated 11 existing rows (9 status changes).
A4: Status is development status read from code, PRs, docs, recorded test runs and live checks - not QA sign-off. COMPLETED includes features released with their feature flag off (see "Where it runs").
A5: To update: change Status in the Feature Register (column I) or a step in the Process Flow Tree (column G) with the dropdown - every count on this sheet is a formula. "Status 25 Oct" (column P) is kept for comparison.
A7: 1. Features by status
A8: Status | B8: Features | C8: % of total | D8: Status 25 Oct | E8: Change
A9: COMPLETED | B9: =COUNTIF('Feature Register'!$I$2:$I$336,A9) -> 319 | C9: =IF($B$15=0,0,B9/$B$15) -> 0.95223881 | D9: =COUNTIF('Feature Register'!$P$2:$P$336,A9) -> 259 | E9: =B9-D9 -> 60
A10: IN PROGRESS | B10: =COUNTIF('Feature Register'!$I$2:$I$336,A10) -> 3 | C10: =IF($B$15=0,0,B10/$B$15) -> 0.0089552239 | D10: =COUNTIF('Feature Register'!$P$2:$P$336,A10) -> 4 | E10: =B10-D10 -> -1
A11: YET TO START | B11: =COUNTIF('Feature Register'!$I$2:$I$336,A11) -> 7 | C11: =IF($B$15=0,0,B11/$B$15) -> 0.020895522 | D11: =COUNTIF('Feature Register'!$P$2:$P$336,A11) -> 9 | E11: =B11-D11 -> -2
A12: BLOCKED | B12: =COUNTIF('Feature Register'!$I$2:$I$336,A12) -> 5 | C12: =IF($B$15=0,0,B12/$B$15) -> 0.014925373 | D12: =COUNTIF('Feature Register'!$P$2:$P$336,A12) -> 4 | E12: =B12-D12 -> 1
A13: DROPPED | B13: =COUNTIF('Feature Register'!$I$2:$I$336,A13) -> 1 | C13: =IF($B$15=0,0,B13/$B$15) -> 0.0029850746 | D13: =COUNTIF('Feature Register'!$P$2:$P$336,A13) -> 1 | E13: =B13-D13 -> 0
A14: New since 25 Oct (not in the 25 Oct report) | D14: =COUNTIF('Feature Register'!$P$2:$P$336,"NEW (not in 25 Oct)") -> 58
A15: Total features tracked | B15: =SUM(B9:B13) -> 335 | C15: =SUM(C9:C13) -> 1 | D15: =SUM(D9:D14) -> 335
A17: 2. Features by section and status
A18: Section | B18: COMPLETED | C18: IN PROGRESS | D18: YET TO START | E18: BLOCKED | F18: Total | G18: % complete
A19: Feature Master | B19: =COUNTIFS('Feature Register'!$B$2:$B$336,$A19,'Feature Register'!$I$2:$I$336,B$18) -> 73 | C19: =COUNTIFS('Feature Register'!$B$2:$B$336,$A19,'Feature Register'!$I$2:$I$336,C$18) -> 0 | D19: =COUNTIFS('Feature Register'!$B$2:$B$336,$A19,'Feature Register'!$I$2:$I$336,D$18) -> 0 | E19: =COUNTIFS('Feature Register'!$B$2:$B$336,$A19,'Feature Register'!$I$2:$I$336,E$18) -> 0 | F19: =COUNTIF('Feature Register'!$B$2:$B$336,$A19) -> 74 | G19: =IF(F19=0,0,B19/F19) -> 0.98648649
A20: Workflow Master | B20: =COUNTIFS('Feature Register'!$B$2:$B$336,$A20,'Feature Register'!$I$2:$I$336,B$18) -> 10 | C20: =COUNTIFS('Feature Register'!$B$2:$B$336,$A20,'Feature Register'!$I$2:$I$336,C$18) -> 0 | D20: =COUNTIFS('Feature Register'!$B$2:$B$336,$A20,'Feature Register'!$I$2:$I$336,D$18) -> 0 | E20: =COUNTIFS('Feature Register'!$B$2:$B$336,$A20,'Feature Register'!$I$2:$I$336,E$18) -> 0 | F20: =COUNTIF('Feature Register'!$B$2:$B$336,$A20) -> 10 | G20: =IF(F20=0,0,B20/F20) -> 1
A21: RBAC Matrix | B21: =COUNTIFS('Feature Register'!$B$2:$B$336,$A21,'Feature Register'!$I$2:$I$336,B$18) -> 15 | C21: =COUNTIFS('Feature Register'!$B$2:$B$336,$A21,'Feature Register'!$I$2:$I$336,C$18) -> 0 | D21: =COUNTIFS('Feature Register'!$B$2:$B$336,$A21,'Feature Register'!$I$2:$I$336,D$18) -> 0 | E21: =COUNTIFS('Feature Register'!$B$2:$B$336,$A21,'Feature Register'!$I$2:$I$336,E$18) -> 0 | F21: =COUNTIF('Feature Register'!$B$2:$B$336,$A21) -> 15 | G21: =IF(F21=0,0,B21/F21) -> 1
A22: State Machines | B22: =COUNTIFS('Feature Register'!$B$2:$B$336,$A22,'Feature Register'!$I$2:$I$336,B$18) -> 6 | C22: =COUNTIFS('Feature Register'!$B$2:$B$336,$A22,'Feature Register'!$I$2:$I$336,C$18) -> 0 | D22: =COUNTIFS('Feature Register'!$B$2:$B$336,$A22,'Feature Register'!$I$2:$I$336,D$18) -> 0 | E22: =COUNTIFS('Feature Register'!$B$2:$B$336,$A22,'Feature Register'!$I$2:$I$336,E$18) -> 0 | F22: =COUNTIF('Feature Register'!$B$2:$B$336,$A22) -> 6 | G22: =IF(F22=0,0,B22/F22) -> 1
A23: Gig Assignment Rules | B23: =COUNTIFS('Feature Register'!$B$2:$B$336,$A23,'Feature Register'!$I$2:$I$336,B$18) -> 9 | C23: =COUNTIFS('Feature Register'!$B$2:$B$336,$A23,'Feature Register'!$I$2:$I$336,C$18) -> 0 | D23: =COUNTIFS('Feature Register'!$B$2:$B$336,$A23,'Feature Register'!$I$2:$I$336,D$18) -> 0 | E23: =COUNTIFS('Feature Register'!$B$2:$B$336,$A23,'Feature Register'!$I$2:$I$336,E$18) -> 0 | F23: =COUNTIF('Feature Register'!$B$2:$B$336,$A23) -> 9 | G23: =IF(F23=0,0,B23/F23) -> 1
A24: Navigation | B24: =COUNTIFS('Feature Register'!$B$2:$B$336,$A24,'Feature Register'!$I$2:$I$336,B$18) -> 19 | C24: =COUNTIFS('Feature Register'!$B$2:$B$336,$A24,'Feature Register'!$I$2:$I$336,C$18) -> 0 | D24: =COUNTIFS('Feature Register'!$B$2:$B$336,$A24,'Feature Register'!$I$2:$I$336,D$18) -> 0 | E24: =COUNTIFS('Feature Register'!$B$2:$B$336,$A24,'Feature Register'!$I$2:$I$336,E$18) -> 0 | F24: =COUNTIF('Feature Register'!$B$2:$B$336,$A24) -> 19 | G24: =IF(F24=0,0,B24/F24) -> 1
A25: KPIs | B25: =COUNTIFS('Feature Register'!$B$2:$B$336,$A25,'Feature Register'!$I$2:$I$336,B$18) -> 15 | C25: =COUNTIFS('Feature Register'!$B$2:$B$336,$A25,'Feature Register'!$I$2:$I$336,C$18) -> 0 | D25: =COUNTIFS('Feature Register'!$B$2:$B$336,$A25,'Feature Register'!$I$2:$I$336,D$18) -> 0 | E25: =COUNTIFS('Feature Register'!$B$2:$B$336,$A25,'Feature Register'!$I$2:$I$336,E$18) -> 0 | F25: =COUNTIF('Feature Register'!$B$2:$B$336,$A25) -> 15 | G25: =IF(F25=0,0,B25/F25) -> 1
A26: Added features (to 6 Oct) | B26: =COUNTIFS('Feature Register'!$B$2:$B$336,$A26,'Feature Register'!$I$2:$I$336,B$18) -> 10 | C26: =COUNTIFS('Feature Register'!$B$2:$B$336,$A26,'Feature Register'!$I$2:$I$336,C$18) -> 0 | D26: =COUNTIFS('Feature Register'!$B$2:$B$336,$A26,'Feature Register'!$I$2:$I$336,D$18) -> 0 | E26: =COUNTIFS('Feature Register'!$B$2:$B$336,$A26,'Feature Register'!$I$2:$I$336,E$18) -> 0 | F26: =COUNTIF('Feature Register'!$B$2:$B$336,$A26) -> 10 | G26: =IF(F26=0,0,B26/F26) -> 1
A27: Delivered or started since 6 Oct | B27: =COUNTIFS('Feature Register'!$B$2:$B$336,$A27,'Feature Register'!$I$2:$I$336,B$18) -> 27 | C27: =COUNTIFS('Feature Register'!$B$2:$B$336,$A27,'Feature Register'!$I$2:$I$336,C$18) -> 0 | D27: =COUNTIFS('Feature Register'!$B$2:$B$336,$A27,'Feature Register'!$I$2:$I$336,D$18) -> 0 | E27: =COUNTIFS('Feature Register'!$B$2:$B$336,$A27,'Feature Register'!$I$2:$I$336,E$18) -> 1 | F27: =COUNTIF('Feature Register'!$B$2:$B$336,$A27) -> 28 | G27: =IF(F27=0,0,B27/F27) -> 0.96428571
A28: Delivered or started since 8 Oct | B28: =COUNTIFS('Feature Register'!$B$2:$B$336,$A28,'Feature Register'!$I$2:$I$336,B$18) -> 11 | C28: =COUNTIFS('Feature Register'!$B$2:$B$336,$A28,'Feature Register'!$I$2:$I$336,C$18) -> 1 | D28: =COUNTIFS('Feature Register'!$B$2:$B$336,$A28,'Feature Register'!$I$2:$I$336,D$18) -> 0 | E28: =COUNTIFS('Feature Register'!$B$2:$B$336,$A28,'Feature Register'!$I$2:$I$336,E$18) -> 0 | F28: =COUNTIF('Feature Register'!$B$2:$B$336,$A28) -> 12 | G28: =IF(F28=0,0,B28/F28) -> 0.91666667
A29: Delivered or started since 9 Oct | B29: =COUNTIFS('Feature Register'!$B$2:$B$336,$A29,'Feature Register'!$I$2:$I$336,B$18) -> 6 | C29: =COUNTIFS('Feature Register'!$B$2:$B$336,$A29,'Feature Register'!$I$2:$I$336,C$18) -> 0 | D29: =COUNTIFS('Feature Register'!$B$2:$B$336,$A29,'Feature Register'!$I$2:$I$336,D$18) -> 0 | E29: =COUNTIFS('Feature Register'!$B$2:$B$336,$A29,'Feature Register'!$I$2:$I$336,E$18) -> 0 | F29: =COUNTIF('Feature Register'!$B$2:$B$336,$A29) -> 6 | G29: =IF(F29=0,0,B29/F29) -> 1
A30: Delivered or started since 10 Oct | B30: =COUNTIFS('Feature Register'!$B$2:$B$336,$A30,'Feature Register'!$I$2:$I$336,B$18) -> 8 | C30: =COUNTIFS('Feature Register'!$B$2:$B$336,$A30,'Feature Register'!$I$2:$I$336,C$18) -> 0 | D30: =COUNTIFS('Feature Register'!$B$2:$B$336,$A30,'Feature Register'!$I$2:$I$336,D$18) -> 0 | E30: =COUNTIFS('Feature Register'!$B$2:$B$336,$A30,'Feature Register'!$I$2:$I$336,E$18) -> 0 | F30: =COUNTIF('Feature Register'!$B$2:$B$336,$A30) -> 8 | G30: =IF(F30=0,0,B30/F30) -> 1
... A39: Delivered or started since 25 Oct | B39: =COUNTIFS('Feature Register'!$B$2:$B$336,$A39,'Feature Register'!$I$2:$I$336,B$18) -> 24 | C39: =COUNTIFS('Feature Register'!$B$2:$B$336,$A39,'Feature Register'!$I$2:$I$336,C$18) -> 0 | D39: =COUNTIFS('Feature Register'!$B$2:$B$336,$A39,'Feature Register'!$I$2:$I$336,D$18) -> 4 | E39: =COUNTIFS('Feature Register'!$B$2:$B$336,$A39,'Feature Register'!$I$2:$I$336,E$18) -> 2 | F39: =COUNTIF('Feature Register'!$B$2:$B$336,$A39) -> 30 | G39: =IF(F39=0,0,B39/F39) -> 0.8
A40: Total | B40: =SUM(B19:B39) -> 319 | C40: =SUM(C19:C39) -> 3 | D40: =SUM(D19:D39) -> 7 | E40: =SUM(E19:E39) -> 5 | F40: =SUM(F19:F39) -> 335 | G40: =IF(F40=0,0,B40/F40) -> 0.95223881
A42: 3. Where features run
A43: Where it runs | B43: Features
A44: Production (gokesari.com) | B44: =COUNTIF('Feature Register'!$J$2:$J$336,A44) -> 246
A45: Production - built, switched off by default | B45: =COUNTIF('Feature Register'!$J$2:$J$336,A45) -> 60
A46: Dropped (code constant) | B46: =COUNTIF('Feature Register'!$J$2:$J$336,A46) -> 1
A47: Mobile app - Android test builds only (not in stores) | B47: =COUNTIF('Feature Register'!$J$2:$J$336,A47) -> 1
A48: GitHub Actions (runs from staging) | B48: =COUNTIF('Feature Register'!$J$2:$J$336,A48) -> 2
A49: GitHub Actions (runs from main) | B49: =COUNTIF('Feature Register'!$J$2:$J$336,A49) -> 7
A50: Test site and production (guest tier) | B50: =COUNTIF('Feature Register'!$J$2:$J$336,A50) -> 2
A51: Test site only (test.gokesari.com) | B51: =COUNTIF('Feature Register'!$J$2:$J$336,A51) -> 5
...

Sheet Flow Diagram
A1: GoKesari flow diagrams - 29 Oct 2026
A2: Colours follow the Process Flow Tree sheet. Diagram 1 = all 18 flows; 2 = dealer programme (F16); 3 = shop onboarding, registration fee and documents (F17). PNG copies are saved next to this workbook.
A4: 1. End-to-end
A29: 2. Dealer programme
A53: 3. Shop onboarding

Sheet Feature Register
A1: # | B1: Section | C1: Feature ID | D1: Module / area | E1: Feature | F1: Functionality (what it does today) | G1: Process flow step(s) | H1: Priority | I1: Status (29 Oct 2026) | J1: Where it runs | K1: Switched on? | L1: Built in PR(s) | M1: Released to production in PR(s) | N1: Remaining scope / gap | O1: Blocked on / next step | P1: Status 25 Oct | Q1: Change since 25 Oct (PRs #250-#289) | R1: Evidence (code / docs)
A2: 1 | B2: Feature Master | C2: GS-001 | D2: Identity & Access | E2: Mobile/email/Gmail login | F2: Google, email magic link and a single mobile-or-email form; first-time /onboarding profile; My Profile with verified email change; checkout requires a mobile; admin can release a wrongly claimed number. Login rebuild now on main (was staging-only on 3 Oct). | G2: F1.1.1, F1.1.2, F1.1.3 | H2: P0 | I2: COMPLETED | J2: Production (gokesari.com) | K2: Live (email OTP); SMS OTP only via the Phase-2 SMS stub | L2: #10 (magic link); #23 (Phase A mobile OTP); #31 (login rebuild, onboarding, My Profile); #80 (same OTP reply); #121 (one consent box); #190 (batch) | M2: #14; #23; #43; #81; #123; #194 | N2: SMS vendor only if SMS OTP is wanted later | O2: - | P2: COMPLETED | Q2: No change | R2: src/server/otp/providers.ts; src/app/onboarding; src/app/profile; drizzle/0038_login_profile.sql
A3: 2 | B3: Feature Master | C3: GS-002 | D3: Identity & Access | E3: Role-based access control | F3: SOCIETY_ADMIN role; society roles scoped per membership (ADMIN/OPERATOR/RESIDENT) | G3: F5.1.2, F12.2.1 | H3: P0 | I3: COMPLETED | J3: Production (gokesari.com) | K3: Live | L3: Baseline; #10 (SOCIETY_ADMIN); #11 (society roles) | M3: Baseline; #14; #19 | N3: - | O3: - | P3: COMPLETED | Q3: No change | R3: src/server/authz/permissions.ts; src/server/db/schema.ts (userRoleEnum)
A4: 3 | B4: Feature Master | C4: GS-003 | D4: Identity & Access | E4: Multi-role user account | F4: user_role_grants; active role switcher in the header; /api/me/roles; admin revoke; shop/rider/society flows grant roles; staff roles exclusive | G4: F12.2.1 | H4: P1 | I4: COMPLETED | J4: Production (gokesari.com) | K4: Live | L4: #18 | M4: #19 | N4: - | O4: - | P4: COMPLETED | Q4: No change | R4: src/server/services/roles.ts; src/app/api/me/roles/route.ts
A5: 4 | B5: Feature Master | C5: GS-004 | D5: Location | E5: PIN / address selection | F5: 'Deliver to' location: saved address, device position or PIN, remembered in a cookie. Phase B added Maps Places address search, a 'save this place' path, and recipient name / recipient mobile / Home-Work-Other on addresses | G5: F1.2.1 | H5: P0 | I5: COMPLETED | J5: Production (gokesari.com) | K5: Live | L5: Baseline (location capture); #10 (customer location); #23 (Phase B); #83 (Deliver-to pill) | M5: Baseline; #14; #23; #84 | N5: - | O5: - | P5: COMPLETED | Q5: No change | R5: src/lib/geo/provider.ts; src/components/location-bar.tsx; drizzle/0026
A6: 5 | B6: Feature Master | C6: GS-005 | D6: Location | E6: Society identification | F6: Society membership; address <-> society link; orders.society_id | G6: F1.2.2, F5.1.2 | H6: P0 | I6: COMPLETED | J6: Production (gokesari.com) | K6: Live | L6: #11 | M6: #19 | N6: - | O6: - | P6: COMPLETED | Q6: No change | R6: src/server/services/societies.ts
A7: 6 | B7: Feature Master | C7: GS-006 | D7: Shop Onboarding | E7: Shop registration | F7: Shop owner registers a shop (/shop/register): name, owner, address with map location, shop type and categories, at least one of PAN / Udyam / GST / Shop Act; duplicate-registration guard; resubmission after rejection; operations approve or reject. | G7: F8.1.1 | H7: P0 | I7: COMPLETED | J7: Production (gokesari.com) | K7: Live | L7: Baseline; #22 (duplicate guard); #45 (validation, GST field); #53 (documents) | M7: Baseline; #19; #47; #54 | N7: 6 Oct: GST field added at registration; at least one of PAN / Udyam / GST / Shop Act required (135f29a). | O7: - | P7: COMPLETED | Q7: No change | R7: -
A8: 7 | B8: Feature Master | C8: GS-007 | D8: Shop Onboarding | E8: Business KYC | F8: Seller verification Parts 1-4: PAN, GSTIN, Udyam, FSSAI and Shop Act per shop with document upload, vendor check (provider-agnostic, Gridlines adapter + mock), name matching, cross-document consistency score, per-document status, admin review queue (approve / reject with reason / re-check), daily re-check and expiry job, auto-suspend on lapse, DPDP retention/erasure. | G8: F8.2.1 | H8: P0 | I8: COMPLETED | J8: Production (gokesari.com) | K8: Live; vendor checks run on the MOCK vendor until Gridlines keys are set (KYC_PROVIDER) | L8: Baseline (GST/PAN self-service); #53 (seller verification) | M8: Baseline; #54 | N8: Real vendor: Gridlines sandbox then live keys and written confirmation of response fields, Shop Act coverage, prices, DPA. Since SM-002 (PR #58) an admin can approve a shop only once every mandatory document is verified (VERIFIED stage). | O8: - | P8: COMPLETED | Q8: No change | R8: src/server/services/seller-verification*.ts; src/server/kyc/; /shop/verification; /admin/seller-verification; drizzle/0040, 0041; docs/seller-verification/
A9: 8 | B9: Feature Master | C9: GS-008 | D9: Shop Onboarding | E9: Payment reference verification | F9: approveShop() now refuses unless fee_payment_status = PAID (derived from the shop_payments ledger), naming the amount outstanding; waived fee (zero snapshot) is written PAID at registration; approval queue shows each pending shop's fee state. Gate is on the transition only - shops already APPROVED untouched | G9: F8.2.3 | H9: P0 | I9: COMPLETED | J9: Production (gokesari.com) | K9: Live | L9: Baseline (registration fees); #29 (fee gate on approval) | M9: Baseline; #29 | N9: - | O9: - | P9: COMPLETED | Q9: No change | R9: src/server/services/shops.ts (approveShop); src/components/shop-approval-panel.tsx; tests/integration/registration-fees.test.ts
A10: 9 | B10: Feature Master | C10: GS-009 | D10: Shop Onboarding | E10: Shop categories | F10: Admin-configurable category master: shop_categories + shop_category_mapping (many per shop), seeded from the 44 shop types and backfilled; registration requires at least one category; owners edit their own on /shop; operators/admins manage the list at /admin/shop-categories and assign per shop; uncategorised shops flagged; categories feed search relevance | G10: F8.3.2 | H10: P0 | I10: COMPLETED | J10: Production (gokesari.com) | K10: Live | L10: #23 (shop categories); #30 (explicit Save) | M10: #23; #32 | N10: - | O10: - | P10: COMPLETED | Q10: No change | R10: src/server/services/shop-categories.ts; src/app/admin/shop-categories/page.tsx; drizzle/0035
A11: 10 | B11: Feature Master | C11: GS-010 | D11: Shop Onboarding | E11: Service radius / delivery zone | F11: shops.service_radius_km (1-50 km) editable by the shop; Phase B added extra delivery zones by PIN code (shops.delivery_pincodes), honoured by serviceability, checkout and discovery | G11: F8.3.3 | H11: P0 | I11: COMPLETED | J11: Production (gokesari.com) | K11: Live | L11: Baseline; #10 (delivery radius); #23 (Phase B PIN zones) | M11: Baseline; #14; #23 | N11: - | O11: - | P11: COMPLETED | Q11: No change | R11: src/server/services/serviceability.ts; src/server/db/schema.ts:691; drizzle/0019, 0026
A12: 11 | B12: Feature Master | C12: GS-011 | D12: Catalog | E12: Product master | F12: Central product catalogue (products) with brand, pack size, GTIN, HSN, GST rate and MRP; fed by the Product Master Data Platform (PMD) and the category master; shop-created products go through an approval queue. | G12: - | H12: P0 | I12: COMPLETED | J12: Production (gokesari.com) | K12: Live | L12: Baseline (product identity/MRP); #4 (Product Master platform); #38 (category master) | M12: Baseline; #8; #43 | N12: - | O12: - | P12: COMPLETED | Q12: No change | R12: -
A13: 12 | B13: Feature Master | C13: GS-012 | D13: Catalog | E13: Shop catalog mapping | F13: Each shop lists master products as its own listings (shop_products) with its own online and in-shop price, stock and availability; listings follow the shop's product categories. | G13: F9.2.2 | H13: P0 | I13: COMPLETED | J13: Production (gokesari.com) | K13: Live | L13: Baseline (shop-created products); #38 (category visibility); #45 (inventory fill) | M13: Baseline; #43; #47 | N13: - | O13: - | P13: COMPLETED | Q13: No change | R13: -
... A336: 335 | B336: Delivered or started since 25 Oct | C336: NEW-105 | D336: QA | E336: QA guest checks follow intended behaviour | F336: Guest checks accept 410 on retired cron routes and the Seller Central sign-in shell | G336: - | H336: - | I336: COMPLETED | J336: Test site and production (guest tier) | K336: - | L336: #283 | M336: #285 | N336: - | O336: - | P336: NEW (not in 25 Oct) | Q336: Added 25-29 Oct 2026 | R336: tests/qa

Sheet Process Flow Tree
A1: GoKesari process flow trees - status of every step (29 Oct 2026; F16-F18 added)
A2: Level 1 = end-to-end flow, level 2 = stage, level 3 = step. Step status is set by hand (dropdown in column G); stage and flow status are formulas: COMPLETED only when every step is; BLOCKED if any step is blocked; YET TO START when no step has started; otherwise IN PROGRESS.
A4: Flow / step ID | B4: Level | C4: Process flow tree | D4: Actor | E4: Feature IDs | F4: Steps done | G4: Status | H4: Built in PR(s) | I4: Gap / note | J4: Batch status (18 Oct) | K4: Batch PR(s) | L4: Batch gap / note
A5: F1 | B5: 1 | C5: F1 Customer purchase journey | D5: Customer | F5: =COUNTIFS($B$6:$B$48,3,$G$6:$G$48,"COMPLETED")&" / "&COUNTIF($B$6:$B$48,3) | G5: =IF(COUNTIFS($B$6:$B$48,3,$G$6:$G$48,"COMPLETED")=COUNTIF($B$6:$B$48,3),"COMPLETED",IF(COUNTIFS($B$6:$B$48,3,$G$6:$G$48,"BLOCKED")>0,"BLOCKED",IF(COUNTIFS($B$6:$B$48,3,$G$6:$G$48,"YET TO START")=COUNTIF($B$6:$B$48,3),"YET TO START","IN PROGRESS"))) | J5: =(COUNTIFS($B$6:$B$48,3,$J$6:$J$48,"DONE")+COUNTIFS($B$6:$B$48,3,$J$6:$J$48,"DONE-SANDBOX"))&" / "&COUNTIFS($B$6:$B$48,3,$J$6:$J$48,"<>")&" batch steps done"
A6: F1.1 | B6: 2 | C6: F1.1 Sign in and profile | F6: =COUNTIFS($B$7:$B$9,3,$G$7:$G$9,"COMPLETED")&" / "&COUNTIF($B$7:$B$9,3) | G6: =IF(COUNTIFS($B$7:$B$9,3,$G$7:$G$9,"COMPLETED")=COUNTIF($B$7:$B$9,3),"COMPLETED",IF(COUNTIFS($B$7:$B$9,3,$G$7:$G$9,"BLOCKED")>0,"BLOCKED",IF(COUNTIFS($B$7:$B$9,3,$G$7:$G$9,"YET TO START")=COUNTIF($B$7:$B$9,3),"YET TO START","IN PROGRESS"))) | J6: =(COUNTIFS($B$7:$B$9,3,$J$7:$J$9,"DONE")+COUNTIFS($B$7:$B$9,3,$J$7:$J$9,"DONE-SANDBOX"))&" / "&COUNTIFS($B$7:$B$9,3,$J$7:$J$9,"<>")&" batch steps done"
A7: F1.1.1 | B7: 3 | C7: Sign in with Google, email magic link or a code sent to email (mobile or email form) | D7: Customer | E7: GS-001, NEW-018 | G7: COMPLETED | H7: #10; #23; #31; #80 | I7: -
A8: F1.1.2 | B8: 3 | C8: Prove the mobile number by SMS OTP | D8: Customer | E8: GS-001, GS-074 | G8: COMPLETED | H8: #190, #192, #194 | I8: DONE (18 Oct batch): Email channel live: OtpProvider routing, 6-digit codes, 5-minute expiry (verified on test.gokesari.com: emails now say 5 minutes), 5 attempts, resend cooldown, DB-backed limits per email/user/IP, hashed + audited, hourly purge. 'OTP sent to your email' wording. SMS = Phase-2 stub (vendor decision D2). | J8: DONE | K8: #190, #192, #194 | L8: Email channel live: OtpProvider routing, 6-digit codes, 5-minute expiry (verified on test.gokesari.com: emails now say 5 minutes), 5 attempts, resend cooldown, DB-backed limits per email/user/IP, hashed + audited, hourly purge. 'OTP sent to your email' wording. SMS = Phase-2 stub (vendor decision D2).
A9: F1.1.3 | B9: 3 | C9: First-time profile (/onboarding) and My Profile | D9: Customer | E9: GS-001 | G9: COMPLETED | H9: #31 | I9: -
A10: F1.2 | B10: 2 | C10: F1.2 Location and society | F10: =COUNTIFS($B$11:$B$12,3,$G$11:$G$12,"COMPLETED")&" / "&COUNTIF($B$11:$B$12,3) | G10: =IF(COUNTIFS($B$11:$B$12,3,$G$11:$G$12,"COMPLETED")=COUNTIF($B$11:$B$12,3),"COMPLETED",IF(COUNTIFS($B$11:$B$12,3,$G$11:$G$12,"BLOCKED")>0,"BLOCKED",IF(COUNTIFS($B$11:$B$12,3,$G$11:$G$12,"YET TO START")=COUNTIF($B$11:$B$12,3),"YET TO START","IN PROGRESS"))) | J10: =(COUNTIFS($B$11:$B$12,3,$J$11:$J$12,"DONE")+COUNTIFS($B$11:$B$12,3,$J$11:$J$12,"DONE-SANDBOX"))&" / "&COUNTIFS($B$11:$B$12,3,$J$11:$J$12,"<>")&" batch steps done"
A11: F1.2.1 | B11: 3 | C11: Choose where to deliver: saved address, device position, PIN or map pin | D11: Customer | E11: GS-004 | G11: COMPLETED | H11: #10; #23; #83 | I11: Map 'Confirm location' 500 was caused by the referrer-restricted server key (GAP-008); fixed 25 Oct, working on test and production
A12: F1.2.2 | B12: 3 | C12: Society recognised from the address | D12: Customer | E12: GS-005 | G12: COMPLETED | H12: #11 | I12: -
A13: F1.3 | B13: 2 | C13: F1.3 Discover shops and products | F13: =COUNTIFS($B$14:$B$17,3,$G$14:$G$17,"COMPLETED")&" / "&COUNTIF($B$14:$B$17,3) | G13: =IF(COUNTIFS($B$14:$B$17,3,$G$14:$G$17,"COMPLETED")=COUNTIF($B$14:$B$17,3),"COMPLETED",IF(COUNTIFS($B$14:$B$17,3,$G$14:$G$17,"BLOCKED")>0,"BLOCKED",IF(COUNTIFS($B$14:$B$17,3,$G$14:$G$17,"YET TO START")=COUNTIF($B$14:$B$17,3),"YET TO START","IN PROGRESS"))) | J13: =(COUNTIFS($B$14:$B$17,3,$J$14:$J$17,"DONE")+COUNTIFS($B$14:$B$17,3,$J$14:$J$17,"DONE-SANDBOX"))&" / "&COUNTIFS($B$14:$B$17,3,$J$14:$J$17,"<>")&" batch steps done"
A14: F1.3.1 | B14: 3 | C14: Shops that deliver here / Shops near you, with filters and sort | D14: Customer | E14: GS-019, NAV-001, NEW-019, NEW-051 | G14: COMPLETED | H14: #10; #83 | I14: -
A15: F1.3.2 | B15: 3 | C15: Product search limited to serviceable shops | D15: Customer | E15: GS-020 | G15: COMPLETED | H15: #10; #48; #83 | I15: -
A16: F1.3.3 | B16: 3 | C16: Every shop selling a product | D16: Customer | E16: GS-021 | G16: COMPLETED | H16: #10 | I16: -
A17: F1.3.4 | B17: 3 | C17: Shops near me from the phone's location: radius 1-10 km, list or map, Directions; PIN box if location is refused | D17: Customer | E17: NEW-057, NEW-059 | G17: COMPLETED | H17: #133; #136; #135 | I17: Live on gokesari.com
A18: F1.4 | B18: 2 | C18: F1.4 Compare prices | F18: =COUNTIFS($B$19:$B$21,3,$G$19:$G$21,"COMPLETED")&" / "&COUNTIF($B$19:$B$21,3) | G18: =IF(COUNTIFS($B$19:$B$21,3,$G$19:$G$21,"COMPLETED")=COUNTIF($B$19:$B$21,3),"COMPLETED",IF(COUNTIFS($B$19:$B$21,3,$G$19:$G$21,"BLOCKED")>0,"BLOCKED",IF(COUNTIFS($B$19:$B$21,3,$G$19:$G$21,"YET TO START")=COUNTIF($B$19:$B$21,3),"YET TO START","IN PROGRESS"))) | J18: =(COUNTIFS($B$19:$B$21,3,$J$19:$J$21,"DONE")+COUNTIFS($B$19:$B$21,3,$J$19:$J$21,"DONE-SANDBOX"))&" / "&COUNTIFS($B$19:$B$21,3,$J$19:$J$21,"<>")&" batch steps done"
A19: F1.4.1 | B19: 3 | C19: Local price comparison across shops | D19: Customer | E19: GS-022 | G19: COMPLETED | H19: #10; #72 | I19: -
A20: F1.4.2 | B20: 3 | C20: Home-page price comparison (F9) | D20: Customer | E20: NAV-001 | G20: COMPLETED | H20: #55 | I20: Off by default
A21: F1.4.3 | B21: 3 | C21: Online (e-commerce) reference prices shown to customers | D21: Customer | E21: GS-023 | G21: BLOCKED | H21: #23; #190, #194 | I21: DROPPED (18 Oct batch): Dropped by a code constant (not a setting): hidden on product pages and for shops, public API 404, admin menu entry removed, no scraping or external calls at runtime; PR #23 code kept and isolated; offline Open Prices CLI refuses to run. | J21: DROPPED | K21: #190, #194 | L21: Dropped by a code constant (not a setting): hidden on product pages and for shops, public API 404, admin menu entry removed, no scraping or external calls at runtime; PR #23 code kept and isolated; offline Open Prices CLI refuses to run.
A22: F1.5 | B22: 2 | C22: F1.5 Cart | F22: =COUNTIFS($B$23:$B$27,3,$G$23:$G$27,"COMPLETED")&" / "&COUNTIF($B$23:$B$27,3) | G22: =IF(COUNTIFS($B$23:$B$27,3,$G$23:$G$27,"COMPLETED")=COUNTIF($B$23:$B$27,3),"COMPLETED",IF(COUNTIFS($B$23:$B$27,3,$G$23:$G$27,"BLOCKED")>0,"BLOCKED",IF(COUNTIFS($B$23:$B$27,3,$G$23:$G$27,"YET TO START")=COUNTIF($B$23:$B$27,3),"YET TO START","IN PROGRESS"))) | J22: =(COUNTIFS($B$23:$B$27,3,$J$23:$J$27,"DONE")+COUNTIFS($B$23:$B$27,3,$J$23:$J$27,"DONE-SANDBOX"))&" / "&COUNTIFS($B$23:$B$27,3,$J$23:$J$27,"<>")&" batch steps done"
A23: F1.5.1 | B23: 3 | C23: Add to cart with quantity controls on the product card | D23: Customer | E23: GS-024, NEW-012 | G23: COMPLETED | H23: #48; #72 | I23: -
A24: F1.5.2 | B24: 3 | C24: Multi-shop cart | D24: Customer | E24: GS-025 | G24: COMPLETED | H24: Baseline; #10 | I24: -
A25: F1.5.3 | B25: 3 | C25: Cart re-validated against the location (serviceability, stock, minimum order, paused shops) | D25: Customer | E25: GS-026, NEW-005 | G25: COMPLETED | H25: #11; #23 | I25: -
A26: F1.5.4 | B26: 3 | C26: Coupons (F7) and shop offers (F8) | D26: Customer | E26: NAV-003, NAV-002 | G26: COMPLETED | H26: #55 | I26: Off by default
A27: F1.5.5 | B27: 3 | C27: Open-order prompt before paying (C3) | D27: Customer | E27: NEW-024 | G27: COMPLETED | H27: #85; #120 | I27: Live on gokesari.com since #120 (9 Oct)
A28: F1.6 | B28: 2 | C28: F1.6 Checkout | F28: =COUNTIFS($B$29:$B$31,3,$G$29:$G$31,"COMPLETED")&" / "&COUNTIF($B$29:$B$31,3) | G28: =IF(COUNTIFS($B$29:$B$31,3,$G$29:$G$31,"COMPLETED")=COUNTIF($B$29:$B$31,3),"COMPLETED",IF(COUNTIFS($B$29:$B$31,3,$G$29:$G$31,"BLOCKED")>0,"BLOCKED",IF(COUNTIFS($B$29:$B$31,3,$G$29:$G$31,"YET TO START")=COUNTIF($B$29:$B$31,3),"YET TO START","IN PROGRESS"))) | J28: =(COUNTIFS($B$29:$B$31,3,$J$29:$J$31,"DONE")+COUNTIFS($B$29:$B$31,3,$J$29:$J$31,"DONE-SANDBOX"))&" / "&COUNTIFS($B$29:$B$31,3,$J$29:$J$31,"<>")&" batch steps done"
A29: F1.6.1 | B29: 3 | C29: Mobile number and delivery address required | D29: Customer | E29: GS-026 | G29: COMPLETED | H29: #31 | I29: -
A30: F1.6.2 | B30: 3 | C30: Delivery window or a scheduled time slot with capacity | D30: Customer | E30: GS-027 | G30: COMPLETED | H30: Baseline; #55; #58 | I30: Slots off by default
A31: F1.6.3 | B31: 3 | C31: Order from a closed shop after confirmation | D31: Customer | E31: NEW-003 | G31: COMPLETED | H31: #24 | I31: -
A32: F1.7 | B32: 2 | C32: F1.7 Payment | F32: =COUNTIFS($B$33:$B$35,3,$G$33:$G$35,"COMPLETED")&" / "&COUNTIF($B$33:$B$35,3) | G32: =IF(COUNTIFS($B$33:$B$35,3,$G$33:$G$35,"COMPLETED")=COUNTIF($B$33:$B$35,3),"COMPLETED",IF(COUNTIFS($B$33:$B$35,3,$G$33:$G$35,"BLOCKED")>0,"BLOCKED",IF(COUNTIFS($B$33:$B$35,3,$G$33:$G$35,"YET TO START")=COUNTIF($B$33:$B$35,3),"YET TO START","IN PROGRESS"))) | J32: =(COUNTIFS($B$33:$B$35,3,$J$33:$J$35,"DONE")+COUNTIFS($B$33:$B$35,3,$J$33:$J$35,"DONE-SANDBOX"))&" / "&COUNTIFS($B$33:$B$35,3,$J$33:$J$35,"<>")&" batch steps done"
A33: F1.7.1 | B33: 3 | C33: Pay from wallet (topped up through Cashfree) | D33: Customer | E33: GS-029, GS-028 | G33: COMPLETED | H33: Baseline | I33: -
A34: F1.7.2 | B34: 3 | C34: Cash on delivery with limits | D34: Customer | E34: GS-030 | G34: COMPLETED | H34: #18 | I34: -
A35: F1.7.3 | B35: 3 | C35: Pay the order directly by UPI / card / netbanking | D35: Customer | E35: GS-028, NEW-007 | G35: COMPLETED | H35: #190, #192, #194 | I35: DONE-SANDBOX (18 Oct batch): PaymentGateway interface: sandbox (working on test.gokesari.com after #192), Cashfree adapter, Razorpay/PhonePe scaffolds; UPI/card/netbanking via hosted checkout only (no card data). Production flag onlinePayments OFF until gateway choice, merchant account, live keys and webhook secret (Owner inputs §1-2). | J35: DONE-SANDBOX | K35: #190, #192, #194 | L35: PaymentGateway interface: sandbox (working on test.gokesari.com after #192), Cashfree adapter, Razorpay/PhonePe scaffolds; UPI/card/netbanking via hosted checkout only (no card data). Production flag onlinePayments OFF until gateway choice, merchant account, live keys and webhook secret (Owner inputs §1-2).
A36: F1.8 | B36: 2 | C36: F1.8 Order engine | F36: =COUNTIFS($B$37:$B$41,3,$G$37:$G$41,"COMPLETED")&" / "&COUNTIF($B$37:$B$41,3) | G36: =IF(COUNTIFS($B$37:$B$41,3,$G$37:$G$41,"COMPLETED")=COUNTIF($B$37:$B$41,3),"COMPLETED",IF(COUNTIFS($B$37:$B$41,3,$G$37:$G$41,"BLOCKED")>0,"BLOCKED",IF(COUNTIFS($B$37:$B$41,3,$G$37:$G$41,"YET TO START")=COUNTIF($B$37:$B$41,3),"YET TO START","IN PROGRESS"))) | J36: =(COUNTIFS($B$37:$B$41,3,$J$37:$J$41,"DONE")+COUNTIFS($B$37:$B$41,3,$J$37:$J$41,"DONE-SANDBOX"))&" / "&COUNTIFS($B$37:$B$41,3,$J$37:$J$41,"<>")&" batch steps done"
A37: F1.8.1 | B37: 3 | C37: Validate stock and service area | D37: Customer | E37: GS-026, GS-016 | G37: COMPLETED | H37: #11; #23 | I37: -
A38: F1.8.2 | B38: 3 | C38: Split by shop; one parent GK- reference (F6) | D38: Customer | E38: GS-033 | G38: COMPLETED | H38: Baseline; #55 | I38: Parent reference off by default
A39: F1.8.3 | B39: 3 | C39: Confirm wallet / COD payment inside the order transaction | D39: Customer | E39: GS-032 | G39: COMPLETED | H39: Baseline; #10 | I39: -
A40: F1.8.4 | B40: 3 | C40: Gateway payment confirmation and payment state machine | D40: Customer | E40: SM-005, GS-073 | G40: COMPLETED | H40: #190, #192, #194 | I40: DONE-SANDBOX (18 Oct batch): Payment state machine CREATED>PENDING>AUTHORIZED>CAPTURED>(PARTIALLY_)REFUNDED + FAILED/EXPIRED; signed webhooks, idempotent by event id, reconciled with the gateway's order status; 5-minute reconciliation job; order idempotency key; order CONFIRMED only on CAPTURED. | J40: DONE-SANDBOX | K40: #190, #192, #194 | L40: Payment state machine CREATED>PENDING>AUTHORIZED>CAPTURED>(PARTIALLY_)REFUNDED + FAILED/EXPIRED; signed webhooks, idempotent by event id, reconciled with the gateway's order status; 5-minute reconciliation job; order idempotency key; order CONFIRMED only on CAPTURED.
A41: F1.8.5 | B41: 3 | C41: Create the shop order and notify the shop | D41: Customer | E41: GS-032, GS-055 | G41: COMPLETED | H41: #10; #23 | I41: -
...

Sheet Dealer Programme
A1: Dealer programme - every module, 29 Oct 2026 (from DEALER_PROGRAMME_TRACKER_2026-10-29.xlsx, plus #271, #275, #280)
A2: All modules built, tested and on gokesari.com with their flags off. Feature IDs match the Feature Register (FLAGS = GKS-FLAGS, FEE-SLABS = GKS-FEE, APP = GKS-APP, DOCS = GKS-DOCS, VER-FIX = GKS-VER).
A3: ID | B3: Module | C3: What it does | D3: Priority | E3: Build step | F3: Migration | G3: Commit(s) | H3: Built | I3: Local + CI tests | J3: Staging (test.gokesari.com) | K3: Production
A4: FLAGS | B4: Feature flags & geo areas | C4: Four flags, per district; Maharashtra districts, Pune talukas / localities, PIN prefixes; DEALER role | D4: P0 | E4: 1 | F4: 0101, 0102, 0103 | G4: bc3f93a | H4: Done | I4: PASS | J4: PASS | K4: Released (flags off): steps 1–10 on 28 Oct; all-India + verification fixes on 29 Oct (release 3, 88d288b)
A5: FEE-SLABS | B5: Registration fee slabs | C5: Admin-defined fee slabs by declared turnover (up to 20) | D5: P0 | E5: 1 | F5: — | G5: 973d520 | H5: Done | I5: PASS | J5: PASS | K5: Released (flags off): steps 1–10 on 28 Oct; all-India + verification fixes on 29 Oct (release 3, 88d288b)
A6: GKS-DR-001 | B6: Dealer registration | C6: Application by type, mobile OTP, e-mail, documents per type, ₹1 bank check, agreement | D6: P0 | E6: 2 | F6: 0104 | G6: 3d92aaf | H6: Done | I6: PASS | J6: PASS | K6: Released (flags off): steps 1–10 on 28 Oct; all-India + verification fixes on 29 Oct (release 3, 88d288b)
A7: GKS-DR-002 | B7: Dealer documents & approval | C7: Configurable document requirements; admin approval queue; suspend / reject / terminate | D7: P0 | E7: 2 | F7: 0104 | G7: 3d92aaf | H7: Done | I7: PASS | J7: PASS | K7: Released (flags off): steps 1–10 on 28 Oct; all-India + verification fixes on 29 Oct (release 3, 88d288b)
A8: GKS-DR-003 | B8: Dealer codes, link & QR | C8: GKS-MH-<district>-code, share link /shop/register?ref=, QR, suspend / replace | D8: P0 | E8: 2 | F8: 0104 | G8: 3d92aaf | H8: Done | I8: PASS | J8: PASS | K8: Released (flags off): steps 1–10 on 28 Oct; all-India + verification fixes on 29 Oct (release 3, 88d288b)
A9: GKS-DR-004 | B9: Employees | C9: Salespeople with optional Employee ID; legacy distributors migrated as dealers | D9: P0 | E9: 2 | F9: 0104 | G9: 3d92aaf | H9: Done | I9: PASS | J9: PASS | K9: Released (flags off): steps 1–10 on 28 Oct; all-India + verification fixes on 29 Oct (release 3, 88d288b)
A10: GKS-SH-001 | B10: Self-registration attribution | C10: Code typed or from ?ref=, optional Employee ID field | D10: P0 | E10: 3 | F10: 0105 | G10: 611f979 | H10: Done | I10: PASS | J10: PASS | K10: Released (flags off): steps 1–10 on 28 Oct; all-India + verification fixes on 29 Oct (release 3, 88d288b)
A11: GKS-SH-002 | B11: Dealer-assisted registration | C11: Dealer registers with the owner; owner confirms with a code | D11: P0 | E11: 3 | F11: 0105 | G11: 611f979 | H11: Done | I11: PASS | J11: PASS | K11: Released (flags off): steps 1–10 on 28 Oct; all-India + verification fixes on 29 Oct (release 3, 88d288b)
A12: GKS-SH-003 | B12: Duplicates | C12: Phone / GSTIN / name within 150 m flagged; no commission | D12: P0 | E12: 3 | F12: 0105 | G12: 611f979 | H12: Done | I12: PASS | J12: PASS | K12: Released (flags off): steps 1–10 on 28 Oct; all-India + verification fixes on 29 Oct (release 3, 88d288b)
A13: GKS-RA-001 | B13: Attribution & claims | C13: 30-day leads (cap 200), attribution priority, dealer claims decided by staff | D13: P0 | E13: 3 | F13: 0105 | G13: 611f979 | H13: Done | I13: PASS | J13: PASS | K13: Released (flags off): steps 1–10 on 28 Oct; all-India + verification fixes on 29 Oct (release 3, 88d288b)
A14: GKS-SH-004 | B14: Instant approval on GST/PAN + payment | C14: Government check + gateway fee → approved; ready-for-upload e-mail; evidence log; retry when source down | D14: P0 | E14: 4 | F14: 0106 | G14: 4500808, 6db91cd | H14: Done | I14: PASS | J14: PASS | K14: Released (flags off): steps 1–10 on 28 Oct; all-India + verification fixes on 29 Oct (release 3, 88d288b)
A15: GKS-CM-001 | B15: Commission rules | C15: Fixed / % / both, per shop type, district, milestone, versioned, admin only | D15: P0 | E15: 5 | F15: 0107 | G15: 22a74db | H15: Done | I15: PASS | J15: PASS | K15: Released (flags off): steps 1–10 on 28 Oct; all-India + verification fixes on 29 Oct (release 3, 88d288b)
... A31: GKS-CM-006 | B31: Waived fee earns no commission | C31: A waived registration fee is a zero base at every milestone | D31: P0 | E31: 12 | F31: - | G31: d8fc985, f2756b6 (#275) | H31: Done | I31: PASS | J31: - | K31: Released 29 Oct in #275
A33: Feature flags
A34: Flag | B34: Switches on | C34: Staging | D34: Production
A35: dealer_programme_enabled | B35: Dealer application and portal, codes, attribution, commission, analytics | C35: On: Karnataka (whole state) + Pune | D35: Off at release (not readable from this session)
A36: gov_verification_auto_approval_enabled | B36: Instant approval on GST/PAN + gateway fee | C36: On: Pune | D36: Off at release (not readable from this session)
A37: dealer_rating_bonus_enabled | B37: Rating bonus on commission | C37: On: Pune | D37: Off at release (not readable from this session)
A38: paid_support_services_enabled | B38: Paid Support services page | C38: On: Pune | D38: Off at release (not readable from this session)
A39: shop_onboarding_wizard_enabled | B39: The new shop onboarding wizard (GSTIN first, Udyam / FSSAI / Shop Act / map, draft -> shop) | C39: See Admin > Feature flags | D39: Off at release (not readable from this session)

Sheet New Functions
A1: New and updated functions since the 25 Oct report (239 exported server functions added, 3dd995c..origin/main)
A2: Every exported function added under src/server and src/app/api between the 25 Oct report and production 4585627. Purpose = the doc comment above the function in the code. Feature = Feature Register ID.
A3: # | B3: Area | C3: File | D3: Function | E3: Purpose (from the code comment) | F3: Feature ID | G3: Added in commit | H3: Where
A4: 1 | B4: aftercare | C4: src/server/aftercare/support-tickets.ts | D4: closeWithdrawnTicket | E4: The request behind a ticket was withdrawn before work started (docs/dealer-programme, paid support services): resolved with the note, then closed, in one go — the requester could not close an open ticket themselves. Already resolved or closed: left as is. | F4: GKS-SP-001 | G4: c70e869 Dealer programme step 7: paid support services (general, product upload, price update) with admin charges, wallet / online payment, tickets and refunds | H4: On production + staging
A5: 2 | B5: api | C5: src/server/api/defer.ts | D5: runOrDefer | E5: Hands `task` to `defer`, or runs it now when there is none — or when `defer` refuses it (`after` throws outside a request, e.g. a route called from a test or a script). The change is already saved by then, so a refusal must not turn into a failed answer. | F5: NEW-087 | G5: ede4260 Approvals answer once the decision is saved; follow-ups run after the response | H5: On production + staging
A6: 3 | B6: cron | C6: src/server/cron/single-run.ts | D6: runSingle | E6: - | F6: NEW-096 | G6: 6a2b174 Cron: one run of each entry point at a time; flock crontab lines | H6: On production + staging
A7: 4 | B7: db | C7: src/server/db/schema.ts | D7: shopTypeColumn | E7: Shop types are plain text keys, not a database enum, so staff can add a type from the admin screen without a migration (migration 0097). The built-in types live in `src/lib/shop-types.ts`; types staff add are rows of `shop_types`. A key is valid when it is... | F7: NEW-078 | G7: 7425434 Add six shop types and an admin-managed shop types screen | H7: On production + staging
A8: 5 | B8: dealers | C8: src/server/dealers/analytics.ts | D8: coverageReport | E8: Coverage of every active area under `rootCode` (default: the whole state), at every level. Status: no approved dealer covers it → NO_DEALER; fewer shops than the target → UNDER_TARGET; half or more of its shops not operational → NOT_OPERATIONAL; otherwise... | F8: GKS-AN-002, GKS-DB-001 | G8: bf53b23 Dealer programme step 8: coverage map with area targets, weighted performance score, activation and 30-day activity | H8: On production + staging
A9: 6 | B9: dealers | C9: src/server/dealers/analytics.ts | D9: setAreaTarget | E9: ADMIN only: the target number of shops for an area (null removes it). Audited. | F9: GKS-AN-002, GKS-DB-001 | G9: bf53b23 Dealer programme step 8: coverage map with area targets, weighted performance score, activation and 30-day activity | H9: On production + staging
A10: 7 | B10: dealers | C10: src/server/dealers/analytics.ts | D10: activationReport | E10: Per dealer, and per employee within each dealer (GKS-AN-002). `dealerId` limits it to one dealer. | F10: GKS-AN-002, GKS-DB-001 | G10: bf53b23 Dealer programme step 8: coverage map with area targets, weighted performance score, activation and 30-day activity | H10: On production + staging
A11: 8 | B11: dealers | C11: src/server/dealers/analytics.ts | D11: dealerScores | E11: Weighted score 0–100 per approved dealer (GKS-AN-001). Each part is 0–1: activated shops and cost are measured against the best dealer in the same district; quality, activity and coverage are the dealer's own ratios. | F11: GKS-AN-002, GKS-DB-001 | G11: bf53b23 Dealer programme step 8: coverage map with area targets, weighted performance score, activation and 30-day activity | H11: On production + staging
A12: 9 | B12: dealers | C12: src/server/dealers/assisted.ts | D12: startAssistedRegistration | E12: Step 1: the owner's details; the code goes to the owner. | F12: GKS-SH-002 | G12: 611f979 Dealer programme step 3: attribution, leads, dealer-assisted registration, duplicates, claims | H12: On production + staging
A13: 10 | B13: dealers | C13: src/server/dealers/assisted.ts | D13: verifyAssistedOwner | E13: Step 2: the code the owner told the dealer. | F13: GKS-SH-002 | G13: 611f979 Dealer programme step 3: attribution, leads, dealer-assisted registration, duplicates, claims | H13: On production + staging
A14: 11 | B14: dealers | C14: src/server/dealers/assisted.ts | D14: submitAssistedShop | E14: Step 3: the shop, registered under the owner with the dealer's code; the owner pays the fee. | F14: GKS-SH-002 | G14: 611f979 Dealer programme step 3: attribution, leads, dealer-assisted registration, duplicates, claims | H14: On production + staging
A15: 12 | B15: dealers | C15: src/server/dealers/assisted.ts | D15: listAssistedSessions | E15: - | F15: GKS-SH-002 | G15: 611f979 Dealer programme step 3: attribution, leads, dealer-assisted registration, duplicates, claims | H15: On production + staging
... A242: 239 | B242: services | C242: src/server/services/support-services.ts | D242: supportServicesReport | E242: Staff: every request, and the report by service (requests, revenue, refunds, SLA kept). | F242: GKS-SP-001 | G242: c70e869 Dealer programme step 7: paid support services (general, product upload, price update) with admin charges, wallet / online payment, tickets and refunds | H242: On production + staging

Sheet New Routes & Pages
A1: New pages and API routes since the 25 Oct report (71)
A2: Added under src/app between the 25 Oct report and production 4585627. Dealer and wizard routes answer only while their feature flag is on for the area (or for an admin).
A3: # | B3: Type | C3: Path | D3: Methods | E3: Used by | F3: Feature ID | G3: File
A4: 1 | B4: Page | C4: /admin/dealers/[id] | D4: page | E4: Admin / staff | F4: Dealer programme | G4: src/app/admin/dealers/[id]/page.tsx
A5: 2 | B5: Page | C5: /admin/dealers/analytics | D5: page | E5: Admin / staff | F5: GKS-AN-001, GKS-AN-002 | G5: src/app/admin/dealers/analytics/page.tsx
A6: 3 | B6: Page | C6: /admin/dealers/claims | D6: page | E6: Admin / staff | F6: GKS-RA-001 | G6: src/app/admin/dealers/claims/page.tsx
A7: 4 | B7: Page | C7: /admin/dealers/commission | D7: page | E7: Admin / staff | F7: Dealer programme | G7: src/app/admin/dealers/commission/page.tsx
A8: 5 | B8: Page | C8: /admin/dealers | D8: page | E8: Admin / staff | F8: Dealer programme | G8: src/app/admin/dealers/page.tsx
A9: 6 | B9: Page | C9: /admin/feature-flags | D9: page | E9: Admin / staff | F9: GKS-FLAGS | G9: src/app/admin/feature-flags/page.tsx
A10: 7 | B10: Page | C10: /admin/shop-types | D10: page | E10: Admin / staff | F10: NEW-078 | G10: src/app/admin/shop-types/page.tsx
A11: 8 | B11: Page | C11: /admin/shops/instant-approvals | D11: page | E11: Admin / staff | F11: GKS-SH-004 | G11: src/app/admin/shops/instant-approvals/page.tsx
A12: 9 | B12: Page | C12: /admin/shops/missing-documents | D12: page | E12: Admin / staff | F12: NEW-089 | G12: src/app/admin/shops/missing-documents/page.tsx
A13: 10 | B13: Page | C13: /admin/support-services | D13: page | E13: Admin / staff | F13: GKS-SP-001 | G13: src/app/admin/support-services/page.tsx
A14: 11 | B14: API | C14: /api/admin/customer-referrals/[id] | D14: POST | E14: Admin / staff | F14: Customer referrals | G14: src/app/api/admin/customer-referrals/[id]/route.ts
A15: 12 | B15: API | C15: /api/admin/dealer-analytics | D15: GET, POST | E15: Admin / staff | F15: GKS-AN-001, GKS-AN-002 | G15: src/app/api/admin/dealer-analytics/route.ts
... A74: 71 | B74: Page | C74: /shop/support-services | D74: page | E74: Shop owner | F74: GKS-SP-001 | G74: src/app/shop/support-services/page.tsx

Sheet Pending for Production
A1: What is not yet on production - 29 Oct 2026 (from GOKESARI_PENDING_FOR_PRODUCTION_2026-10-29.md, updated from git)
A2: Production (main) is at 4585627 (#287, Release 29 Oct (6)), merged 29 Oct 14:00 UTC. Staging is ahead of production by docs only (#288, #289). Its post-deploy check result could not be read from this session.
A4: A. Releases since the 25 Oct report (production, newest first)
A5: Merged (IST) | B5: PR | C5: Commit | D5: What
A6: 29 Oct 19:30 | B6: #287 | C6: 4585627 | D6: Release 29 Oct (6): shop documents D-107 / D-108 fixes, staging QA results
A7: 29 Oct 18:25 | B7: #285 | C7: 84c2279 | D7: Release 29 Oct (5): dealer base commission, verification follow-ups, wizard GST/PAN flag, cron single-run, QA tests
A8: 29 Oct 15:58 | B8: #282 | C8: 01d0d26 | D8: Release: home page database reads run together; logo link no longer prefetches home
A9: 29 Oct 15:35 | B9: #281 | C9: 6f161fa | D9: Release 29 Oct (4): dealer monthly payout; migrations only in GitHub Actions
A10: 29 Oct 13:12 | B10: #277 | C10: 88d288b | D10: Release 29 Oct (3): shop documents before the fee + 1st/15th follow-up, wizard behind its flag, dealers across India
A11: 29 Oct 11:58 | B11: #275 | C11: 381e2a2 | D11: Release: a waived registration fee earns the dealer no commission
A12: 29 Oct 07:55 | B12: #272 | C12: 8219c82 | D12: Release 29 Oct: shop documents scan + more licences, onboarding wizard step 2
A13: 28 Oct 23:27 | B13: direct merge | C13: 8d6ef40 | D13: Release 28 Oct (2): payment follow-up fix, fee record/waive, dealer commission holds, dealer docs.
A14: 28 Oct 22:50 | B14: #268 | C14: 87372c0 | D14: Release 28 Oct: staging to main (registration fee, dealer programme 1–9, approval queue, onboarding wizard step 1)
A15: 27 Oct 23:42 | B15: #266 | C15: f7c0032 | D15: Release 27 Oct: staging to main (product cards, search, shop types, D-95, GAP fixes)
A17: B. On staging, not on production
A18: Item | B18: Commit / PR | C18: State
A19: Docs: D-108 retest passed; pending-for-production list after #285 | B19: 6eef5ac (#288), eb2f628 (#289) | C19: Docs only - goes with the next release
A21: C. Open defects and gaps
A22: # | B22: What | C22: Impact | D22: State / fix
A23: D-106 | B23: Wizard GSTIN / PAN step routes answered a signed-in non-admin while the flag was off | C23: Paid government lookups reachable without the wizard | D23: Fixed and released in #285; on gokesari.com a guest gets 401 from both routes
A24: D-107 | B24: Shop documents follow-up (staging QA SD-03w / SD-07) | C24: - | D24: Fixed (ea20441), released #287
A25: D-108 | B25: Operator approval card did not name the promised date | C25: - | D25: Fixed (63ccd62, #286), retest passed, released #287
A26: E-04 | B26: Staging registration-fee checkout uses the in-process SANDBOX gateway, not the Cashfree sandbox | C26: Cashfree sandbox workflow not usable for fee tests | D26: Resolved by owner decision 29 Oct: pay on the built-in test page
A27: - | B27: 3 staging shops have a verified PAN not yet copied onto the shop row | C27: Shop GST/PAN card shows PAN "Not verified" until the next check | D27: Owner: one-time catch-up script, if wanted (Blockers #77)
A29: D. Built and on production, switched off (feature flags)
A30: Flag | B30: Switches on
A31: dealer_programme_enabled | B31: Dealer application and portal, codes, attribution, commission, analytics, all-India add dealer
A32: gov_verification_auto_approval_enabled | B32: Instant shop approval on GST/PAN verification + online fee
A33: dealer_rating_bonus_enabled | B33: Rating bonus on dealer commission
A34: paid_support_services_enabled | B34: Paid Support services page for shops
A35: shop_onboarding_wizard_enabled | B35: The new shop onboarding wizard
A37: E. Branches deleted (owner, 29 Oct)
A38: Branch | B38: Last commit (restore: git push origin <sha>:refs/heads/<branch>)
A39: release/2026-10-29-waived-fee | B39: 6475bdde5defa8847e1899c8a6ce18d23b65f735 (already on production as f2756b6)
A40: claude/festive-ride-udspyl | B40: d83c91fa7ffc8497111f3a7ada0f3f2ce5adb9e0 ("Driving Simulator" placeholder page, 25 Oct)

Sheet Performance & DB
A1: Speed and database location - 28-29 Oct 2026 (from the performance diagnosis, performance report and region move plan)
A3: 1. Measured response times (gokesari.com)
A4: Page | B4: 28 Oct - database in Ohio | C4: 29 Oct 09:40 - Singapore | D4: 29 Oct 10:35 - after #282 | E4: Target after P1/P2
A5: / home (signed out) | B5: 1.8-2.1 s | C5: 0.42-0.52 s | D5: 0.33-0.46 s (median 0.34 s) | E5: ~0.20 s; ~0.05-0.10 s with P2
A6: /products/<id> product | B6: - | C6: 0.67-0.91 s | D6: unchanged | E6: ~0.25 s
A7: /shops/<slug> shop | B7: - | C7: 0.57 s | D7: unchanged | E7: ~0.25 s
A8: /shops list | B8: - | C8: 0.18-0.26 s | D8: - | E8: -
A9: /about, /contact, /categories | B9: - | C9: 0.05-0.06 s | D9: - | E9: ~40 ms from the CDN (P4)
A10: First request after idle | B10: ~4 s | C10: 2.5 s | D10: 2.5 s | E10: Needs Neon scale-to-zero off (P5)
A11: Approve a seller document | B11: 5-15 s | C11: ~2-4 s expected | D11: Replies once saved (ede4260) | E11: -
A13: 2. Recommendations and status
A14: # | B14: Recommendation | C14: Status | D14: Feature ID | E14: Note
A15: P1 home | B15: Run independent home-page reads together | C15: COMPLETED | D15: NEW-098 | E15: Released #282, 29 Oct
A16: P1 product / shop | B16: Product and shop page reads together; cache() the shop read | C16: YET TO START | D16: NEW-099 | E16: -
A17: P2 | B17: Cache data shared by everyone (30-120 s) | C17: YET TO START | D17: NEW-100 | E17: Keep stock and price live
A18: P3 | B18: Stop the home page prefetching itself | C18: COMPLETED | D18: NEW-098 | E18: Logo link; 7-9 other links still prefetch
A19: P4 | B19: Let the CDN cache static pages | C19: YET TO START | D19: NEW-101 | E19: gk_return_to cookie only where needed
A20: P5 | B20: Remove the cold first request | C20: BLOCKED | D20: NEW-102 | E20: Neon free plan: owner billing decision
A21: P6 | B21: Smaller wins (logo, JS, CDN MISS, session cache) | C21: YET TO START | D21: NEW-103 | E21: -
A22: P7 | B22: App and database in the same place | C22: BLOCKED | D22: NEW-104 | E22: Owner hosting decision
A23: Diag. 2 | B23: Take follow-up work out of the approval request | C23: COMPLETED | D23: NEW-087 | E23: ede4260 (#268)
A24: Diag. 4 | B24: pg_stat_statements on production | C24: COMPLETED | D24: NEW-086 | E24: Installed in the Singapore projects
A26: 3. Database region move (Ohio -> Neon Singapore aws-ap-southeast-1)
A27: Site | B27: Project | C27: Freeze (UTC) | D27: Writes opened (UTC) | E27: Read-only window | F27: Compare result
A28: test.gokesari.com | B28: GoKesari-test-sg (curly-night-16641982) | C28: 28 Oct 10:43:53 | D28: 28 Oct 12:14:09 | E28: 1 h 30 min | F28: All five databases identical
A29: gokesari.com | B29: GoKesari-prod-sg (lively-frost-99365966) | C29: 28 Oct 12:50:33 | D29: 28 Oct 13:23:28 | E29: 32 min 55 s | F29: All three databases identical
A31: 4. Open items after the move
A32: # | B32: Item | C32: Who | D32: Blocker #
A33: 1 | B33: Run "Production database -> verify" once on main | C33: Owner | D33: #73
A34: 2 | B34: Check the every-minute / hourly / daily jobs run on both sites | C34: Owner + session | D34: #4
A35: 3 | B35: Neon plan for production (scale-to-zero) | C35: Owner (billing) | D35: #72
A36: 4 | B36: Delete old Ohio projects: test after 4 Nov, production after 11 Nov | C36: Owner, then a session | D36: #75
A37: 5 | B37: Keep a copy of the backup dumps | C37: Owner | D37: #81

Sheet Blockers & Decisions
A1: # | B1: Type | C1: Item | D1: What is needed | E1: Unblocks (feature IDs) | F1: Who | G1: Status | H1: Source
A2: 1 | B2: Release blocker | C2: Production database is behind (0055) - next release cannot ship | D2: Resolved 9 Oct: the owner set MIGRATE_ON_BUILD=true for gokesari.com and the #120 deploy applied migrations 0056-0073 before the new code went live (Neon snapshot taken first). | E2: NEW-020-026, NEW-028-042, PLT-007 | F2: Owner | G2: Resolved | H2: PR #86, #87; ITEMS_A_E_2026-10-07.md section 3a
A3: 2 | B3: Release blocker | C3: 'Production database' workflow is only on staging | D3: Resolved 9 Oct: #118 put the workflow on main. Running it still needs repository secrets - see #32. | E3: PLT-009 (and the release blocker above) | F3: Owner / dev | G3: Resolved | H3: PR #93; docs/event-driven-2026-10/PROD_DB.md
A4: 3 | B4: Go-live blocker | C4: No recorded browser / QA sign-off | D4: Execute the 791-case plan and record results. 24 Oct: automated (QA-010) and run on local, staging and production (guest); register in docs/testing/GOKESARI_MASTER_TEST_REGISTER.xlsx. Remaining: 8 open defects and the test-side follow-ups. | E4: QA-003; QA-005; go-live | F4: QA / owner | G4: In progress | H4: 6 Oct report; TEST_SUMMARY_AND_STATUS.md
A5: 4 | B5: Go-live blocker | C5: Production cron jobs | D5: Schedule seller-verification, dispute-escalation, shop-acceptance, delivery-dispatch and notifications on gokesari.com. 28 Oct: database counters showed almost no every-minute runs (production 0 in ~15 min, test 2 in ~1 h). New daily jobs since 25 Oct: dealer-monthly-payout, shop-document-follow-up. Check the Hostinger cron list and the [cron:every-minute] log lines. | E5: GS-007, GS-058, NEW-007, NEW-028 | F5: Owner | G5: Open | H5: DEPLOY_RUNBOOK.md; ITEMS_A_E section 3a.7
A6: 5 | B6: Decision | C6: Per-order online payment (GS-028 / NEW-007) | D6: Resolved 18 Oct: per-order online payment built (#190, released #194) on the sandbox; going live needs the gateway keys (Owner inputs §1-2). | E6: GS-028, GS-073, SM-005, WF-001, NAV-003, NEW-007 | F6: Owner | G6: Resolved | H6: 6 Oct report
A7: 6 | B7: Vendor | C7: D2 - SMS / OTP vendor (DLT) and WhatsApp provider | D7: Resolved 18 Oct (D-A02): email is the OTP channel; SMS stays a Phase-2 stub. WhatsApp / push providers: keys in Owner inputs §11. | E7: GS-001, GS-074, NEW-035 (SMS code), NEW-038 | F7: Owner | G7: Resolved | H7: 6 Oct report; three-modules PLAN.md P2
A8: 7 | B8: Decision | C8: D7 - licensed external price source | D8: Resolved 18 Oct (D-A03): online reference prices dropped by owner decision (GS-023 DROPPED). | E8: GS-023 | F8: Owner | G8: Resolved | H8: 6 Oct report
A9: 8 | B9: Decision | C9: D10 - cancellation after packing | D9: Resolved 18 Oct: D10 signed off and built - after-packing per-shop fee within admin limits (F6.1.3). | E9: NEW-006 sign-off, NEW-020 | F9: Owner | G9: Resolved | H9: ITEMS_A_E section 1-A
A10: 9 | B10: Decision | C10: D6 - delivery fee kept on cancellation; platform invoicing of its own fees | D10: Resolved 18 Oct: GoKesari fee invoices built (F10.2.5, sandbox); needs GoKesari GSTIN, legal details and prefix (Owner inputs §4-5). | E10: GAP-006 | F10: Owner / CA | G10: Resolved | H10: 3 Oct open features; ITEMS_A_E section 5
A11: 10 | B11: Decision | C11: RBAC-003 - operator 'Limited' shop management | D11: Resolved 18 Oct: OPERATOR_LIMITED role built (F8.4.2). | E11: RBAC-003 | F11: Owner | G11: Resolved | H11: 6 Oct report
A12: 11 | B12: Decision | C12: SM-006 scope | D12: Resolved 18 Oct: ticket / issue state machine built with the help desk (F6.3.3). | E12: SM-006 | F12: Owner | G12: Resolved | H12: ITEMS_A_E section 5
A13: 12 | B13: Decision | C13: Which off-by-default features to switch on in production | D13: Choose which of the now-released off-by-default features to switch on in production: F3-F11 and #58 rules, plus fulfilmentOptions, legalDocuments, bankAccounts, bankRefunds, bankAccountCheck, shopReferral, customerSignupReferral, shopWallet, selfRegistration, cancellation PREPARING (all off on gokesari.com after #120). 29 Oct: five more flags built and off on gokesari.com: dealer_programme_enabled, gov_verification_auto_approval_enabled, dealer_rating_bonus_enabled, paid_support_services_enabled, shop_onboarding_wizard_enabled (switch on for all India, states or districts in Admin > Feature flags). | E13: GS-014, GS-027, GS-033, GS-054, GS-072, GA-005, NAV-001, NAV-002, NAV-003, NEW-007 | F13: Owner | G13: Pending | H13: 6 Oct report
... A83: 82 | B83: Release step | C83: Post-deploy check for release #287 | D83: Release #287 merged into main 29 Oct 14:00 UTC. Its Post-deploy check result could not be read from this session (GitHub API unreachable). Confirm the run passed. | E83: Release #287 | F83: Owner / dev | G83: Check | H83: CLAUDE.md (Production releases)

Sheet PR Register
A1: PR # | B1: Title | C1: Type | D1: Branch (head -> base) | E1: Target | F1: State | G1: Created | H1: Merged / closed | I1: Features built / extended | J1: Features released to production | K1: Released to production via | L1: Notes
A2: 1 | B2: Add the Product Master Data Platform (pilot) | C2: Feature | D2: feature/product-master-platform -> main | E2: Production (main -> gokesari.com) | F2: Closed - not merged | G2: 2026-09-20 | H2: 2026-09-21 | I2: PMD-001 | J2: - | K2: - | L2: Superseded by #4 (closed unmerged).
A3: 2 | B3: Add GS1 India and manufacturer-catalogue connectors (Excel, mapping templates) | C3: Feature | D3: feature/pmd-gs1-manufacturer-feeds -> feature/product-master-platform | E3: Stacked on feature/product-master-platform | F3: Closed - not merged | G3: 2026-09-20 | H3: 2026-09-21 | I3: PMD-002 | J3: - | K3: - | L3: Stacked on #1; superseded by #4.
A4: 3 | B4: PMD: loader rework for scale (bulk path, workers, dashboard/index fixes) | C4: Feature | D4: feature/pmd-loader-rework -> feature/product-master-platform | E4: Stacked on feature/product-master-platform | F4: Closed - not merged | G4: 2026-09-20 | H4: 2026-09-21 | I4: PMD-003 | J4: - | K4: - | L4: Stacked on #1; superseded by #4.
A5: 4 | B5: Product Master: platform, feeds, loader rework and shop-catalogue promotion (into staging) | C5: Feature | D5: release/pmd-to-staging -> staging | E5: Test site (staging -> test.gokesari.com) | F5: Merged | G5: 2026-09-20 | H5: 2026-09-20 | I5: GS-011, PMD-001, PMD-002, PMD-003, PMD-004 | J5: - | K5: #8 | L5: Released by #8.
A6: 5 | B6: Product Master: one-command copy of the pilot data into a target database | C6: Feature | D6: feature/pmd-copy-script -> staging | E6: Test site (staging -> test.gokesari.com) | F6: Merged | G6: 2026-09-20 | H6: 2026-09-21 | I6: PMD-004 | J6: - | K6: #8 | L6: Released by #8.
A7: 6 | B7: Product Master: fix duplicate brand on concurrent promotion; parallel promotion option | C7: Feature | D7: feature/pmd-promote-concurrency -> staging | E7: Test site (staging -> test.gokesari.com) | F7: Merged | G7: 2026-09-21 | H7: 2026-09-21 | I7: PMD-004 | J7: - | K7: #8 | L7: Released by #8.
