Workbook

Sheet Summary
A1: GoKesari (gokesari.com) - features, process flows and PR status
A2: As of 18 Oct 2026, 13:45 UTC. Production = main @c96cd04 (gokesari.com, migrations to 0078): release #185 (16 Oct 04:24 UTC) added the PMD loader fix (#184) and report docs (#181, #182) to the 15 Oct releases (#175, #177, #179). Test site = staging @3a701c9, same application code as main (#186, #187). Open PRs: #183 (status-report docs), #188 (competitive analysis deck, docs). Sub-feature sheets: 'Bulk Product Upload' and 'Inventory & Accounting'.
A3: Baseline = the 16 Oct status report (267 features, PR #183), plus PRs #185-#188. 'Status 16 Oct' is that report's status for comparison.
A4: Status is development status read from code, PRs, docs, recorded test runs and live checks - not QA sign-off. 'Baseline' in a PR column = code that predates PR #1 in this repository (Aug-Sep 2026 history).
A5: To update: change Status in the Feature Register (column I) or a step in the Process Flow Tree (column G) with the dropdown - every count on this sheet is a formula. 'Status 16 Oct' is unchanged for comparison.
A7: 1. Features by status
A8: Status | B8: Features | C8: % of total | D8: Status 16 Oct | E8: Meaning
A9: COMPLETED | B9: =COUNTIF('Feature Register'!$I$2:$I$268,A9) | C9: =IF($B$13=0,0,B9/$B$13) | D9: =COUNTIF('Feature Register'!$P$2:$P$268,A9) | E9: Built, merged and live on gokesari.com (incl. built but switched off by default), or finished tooling / test runs
A10: IN PROGRESS | B10: =COUNTIF('Feature Register'!$I$2:$I$268,A10) | C10: =IF($B$13=0,0,B10/$B$13) | D10: =COUNTIF('Feature Register'!$P$2:$P$268,A10) | E10: Started: partly working, being run, or built and on the test site but not yet released
A11: YET TO START | B11: =COUNTIF('Feature Register'!$I$2:$I$268,A11) | C11: =IF($B$13=0,0,B11/$B$13) | D11: =COUNTIF('Feature Register'!$P$2:$P$268,A11) | E11: Not built yet (designed, planned or a known gap)
A12: BLOCKED | B12: =COUNTIF('Feature Register'!$I$2:$I$268,A12) | C12: =IF($B$13=0,0,B12/$B$13) | D12: =COUNTIF('Feature Register'!$P$2:$P$268,A12) | E12: Cannot proceed until a decision, vendor, account, agreement or CA/legal check
A13: Total features tracked | B13: =SUM(B9:B12) | C13: =SUM(C9:C12) | D13: =SUM(D9:D12) | E13: Status 16 Oct counts the 16 Oct report's status for every row (267).
A15: 2. Features by section and status
A16: Section | B16: COMPLETED | C16: IN PROGRESS | D16: YET TO START | E16: BLOCKED | F16: Total | G16: % complete
A17: Feature Master | B17: =COUNTIFS('Feature Register'!$B$2:$B$268,$A17,'Feature Register'!$I$2:$I$268,B$16) | C17: =COUNTIFS('Feature Register'!$B$2:$B$268,$A17,'Feature Register'!$I$2:$I$268,C$16) | D17: =COUNTIFS('Feature Register'!$B$2:$B$268,$A17,'Feature Register'!$I$2:$I$268,D$16) | E17: =COUNTIFS('Feature Register'!$B$2:$B$268,$A17,'Feature Register'!$I$2:$I$268,E$16) | F17: =SUM(B17:E17) | G17: =IF(F17=0,0,B17/F17)
A18: Workflow Master | B18: =COUNTIFS('Feature Register'!$B$2:$B$268,$A18,'Feature Register'!$I$2:$I$268,B$16) | C18: =COUNTIFS('Feature Register'!$B$2:$B$268,$A18,'Feature Register'!$I$2:$I$268,C$16) | D18: =COUNTIFS('Feature Register'!$B$2:$B$268,$A18,'Feature Register'!$I$2:$I$268,D$16) | E18: =COUNTIFS('Feature Register'!$B$2:$B$268,$A18,'Feature Register'!$I$2:$I$268,E$16) | F18: =SUM(B18:E18) | G18: =IF(F18=0,0,B18/F18)
A19: RBAC Matrix | B19: =COUNTIFS('Feature Register'!$B$2:$B$268,$A19,'Feature Register'!$I$2:$I$268,B$16) | C19: =COUNTIFS('Feature Register'!$B$2:$B$268,$A19,'Feature Register'!$I$2:$I$268,C$16) | D19: =COUNTIFS('Feature Register'!$B$2:$B$268,$A19,'Feature Register'!$I$2:$I$268,D$16) | E19: =COUNTIFS('Feature Register'!$B$2:$B$268,$A19,'Feature Register'!$I$2:$I$268,E$16) | F19: =SUM(B19:E19) | G19: =IF(F19=0,0,B19/F19)
A20: State Machines | B20: =COUNTIFS('Feature Register'!$B$2:$B$268,$A20,'Feature Register'!$I$2:$I$268,B$16) | C20: =COUNTIFS('Feature Register'!$B$2:$B$268,$A20,'Feature Register'!$I$2:$I$268,C$16) | D20: =COUNTIFS('Feature Register'!$B$2:$B$268,$A20,'Feature Register'!$I$2:$I$268,D$16) | E20: =COUNTIFS('Feature Register'!$B$2:$B$268,$A20,'Feature Register'!$I$2:$I$268,E$16) | F20: =SUM(B20:E20) | G20: =IF(F20=0,0,B20/F20)
A21: Gig Assignment Rules | B21: =COUNTIFS('Feature Register'!$B$2:$B$268,$A21,'Feature Register'!$I$2:$I$268,B$16) | C21: =COUNTIFS('Feature Register'!$B$2:$B$268,$A21,'Feature Register'!$I$2:$I$268,C$16) | D21: =COUNTIFS('Feature Register'!$B$2:$B$268,$A21,'Feature Register'!$I$2:$I$268,D$16) | E21: =COUNTIFS('Feature Register'!$B$2:$B$268,$A21,'Feature Register'!$I$2:$I$268,E$16) | F21: =SUM(B21:E21) | G21: =IF(F21=0,0,B21/F21)
A22: Navigation | B22: =COUNTIFS('Feature Register'!$B$2:$B$268,$A22,'Feature Register'!$I$2:$I$268,B$16) | C22: =COUNTIFS('Feature Register'!$B$2:$B$268,$A22,'Feature Register'!$I$2:$I$268,C$16) | D22: =COUNTIFS('Feature Register'!$B$2:$B$268,$A22,'Feature Register'!$I$2:$I$268,D$16) | E22: =COUNTIFS('Feature Register'!$B$2:$B$268,$A22,'Feature Register'!$I$2:$I$268,E$16) | F22: =SUM(B22:E22) | G22: =IF(F22=0,0,B22/F22)
A23: KPIs | B23: =COUNTIFS('Feature Register'!$B$2:$B$268,$A23,'Feature Register'!$I$2:$I$268,B$16) | C23: =COUNTIFS('Feature Register'!$B$2:$B$268,$A23,'Feature Register'!$I$2:$I$268,C$16) | D23: =COUNTIFS('Feature Register'!$B$2:$B$268,$A23,'Feature Register'!$I$2:$I$268,D$16) | E23: =COUNTIFS('Feature Register'!$B$2:$B$268,$A23,'Feature Register'!$I$2:$I$268,E$16) | F23: =SUM(B23:E23) | G23: =IF(F23=0,0,B23/F23)
A24: Added features (to 6 Oct) | B24: =COUNTIFS('Feature Register'!$B$2:$B$268,$A24,'Feature Register'!$I$2:$I$268,B$16) | C24: =COUNTIFS('Feature Register'!$B$2:$B$268,$A24,'Feature Register'!$I$2:$I$268,C$16) | D24: =COUNTIFS('Feature Register'!$B$2:$B$268,$A24,'Feature Register'!$I$2:$I$268,D$16) | E24: =COUNTIFS('Feature Register'!$B$2:$B$268,$A24,'Feature Register'!$I$2:$I$268,E$16) | F24: =SUM(B24:E24) | G24: =IF(F24=0,0,B24/F24)
A25: Delivered or started since 6 Oct | B25: =COUNTIFS('Feature Register'!$B$2:$B$268,$A25,'Feature Register'!$I$2:$I$268,B$16) | C25: =COUNTIFS('Feature Register'!$B$2:$B$268,$A25,'Feature Register'!$I$2:$I$268,C$16) | D25: =COUNTIFS('Feature Register'!$B$2:$B$268,$A25,'Feature Register'!$I$2:$I$268,D$16) | E25: =COUNTIFS('Feature Register'!$B$2:$B$268,$A25,'Feature Register'!$I$2:$I$268,E$16) | F25: =SUM(B25:E25) | G25: =IF(F25=0,0,B25/F25)
A26: Delivered or started since 8 Oct | B26: =COUNTIFS('Feature Register'!$B$2:$B$268,$A26,'Feature Register'!$I$2:$I$268,B$16) | C26: =COUNTIFS('Feature Register'!$B$2:$B$268,$A26,'Feature Register'!$I$2:$I$268,C$16) | D26: =COUNTIFS('Feature Register'!$B$2:$B$268,$A26,'Feature Register'!$I$2:$I$268,D$16) | E26: =COUNTIFS('Feature Register'!$B$2:$B$268,$A26,'Feature Register'!$I$2:$I$268,E$16) | F26: =SUM(B26:E26) | G26: =IF(F26=0,0,B26/F26)
A27: Delivered or started since 9 Oct | B27: =COUNTIFS('Feature Register'!$B$2:$B$268,$A27,'Feature Register'!$I$2:$I$268,B$16) | C27: =COUNTIFS('Feature Register'!$B$2:$B$268,$A27,'Feature Register'!$I$2:$I$268,C$16) | D27: =COUNTIFS('Feature Register'!$B$2:$B$268,$A27,'Feature Register'!$I$2:$I$268,D$16) | E27: =COUNTIFS('Feature Register'!$B$2:$B$268,$A27,'Feature Register'!$I$2:$I$268,E$16) | F27: =SUM(B27:E27) | G27: =IF(F27=0,0,B27/F27)
A28: Delivered or started since 10 Oct | B28: =COUNTIFS('Feature Register'!$B$2:$B$268,$A28,'Feature Register'!$I$2:$I$268,B$16) | C28: =COUNTIFS('Feature Register'!$B$2:$B$268,$A28,'Feature Register'!$I$2:$I$268,C$16) | D28: =COUNTIFS('Feature Register'!$B$2:$B$268,$A28,'Feature Register'!$I$2:$I$268,D$16) | E28: =COUNTIFS('Feature Register'!$B$2:$B$268,$A28,'Feature Register'!$I$2:$I$268,E$16) | F28: =SUM(B28:E28) | G28: =IF(F28=0,0,B28/F28)
... A33: Known gaps (not started) | B33: =COUNTIFS('Feature Register'!$B$2:$B$268,$A33,'Feature Register'!$I$2:$I$268,B$16) | C33: =COUNTIFS('Feature Register'!$B$2:$B$268,$A33,'Feature Register'!$I$2:$I$268,C$16) | D33: =COUNTIFS('Feature Register'!$B$2:$B$268,$A33,'Feature Register'!$I$2:$I$268,D$16) | E33: =COUNTIFS('Feature Register'!$B$2:$B$268,$A33,'Feature Register'!$I$2:$I$268,E$16) | F33: =SUM(B33:E33) | G33: =IF(F33=0,0,B33/F33)
A34: Total | B34: =SUM(B17:B33) | C34: =SUM(C17:C33) | D34: =SUM(D17:D33) | E34: =SUM(E17:E33) | F34: =SUM(F17:F33) | G34: =IF(F34=0,0,B34/F34)
A36: 3. Where features run
A37: Where it runs | B37: Features
A38: Production (gokesari.com) | B38: =COUNTIF('Feature Register'!$J$2:$J$268,A38)
A39: Production - built, switched off by default | B39: =COUNTIF('Feature Register'!$J$2:$J$268,A39)
A40: Production - partly live | B40: =COUNTIF('Feature Register'!$J$2:$J$268,A40)
A41: Test site only (test.gokesari.com) | B41: =COUNTIF('Feature Register'!$J$2:$J$268,A41)
A42: Test site only - production release reverted (#87) | B42: =COUNTIF('Feature Register'!$J$2:$J$268,A42)
A43: Open PR - not merged | B43: =COUNTIF('Feature Register'!$J$2:$J$268,A43)
A44: Mobile app - Android test builds only (not in stores) | B44: =COUNTIF('Feature Register'!$J$2:$J$268,A44)
A45: GitHub Actions (runs from main) | B45: =COUNTIF('Feature Register'!$J$2:$J$268,A45)
A46: GitHub Actions (runs from staging) | B46: =COUNTIF('Feature Register'!$J$2:$J$268,A46)
A47: On staging only - not yet runnable | B47: =COUNTIF('Feature Register'!$J$2:$J$268,A47)
...

Sheet Batch 2026-10
A1: GoKesari build & integrate batch (18 Oct 2026) — status of every flow step in the brief
A2: DONE = built, merged, tested; DONE-SANDBOX = complete on the sandbox/mock provider, production flag OFF until the owner's keys exist
A4: Flow / step ID | B4: Step | C4: Batch status | D4: PR(s) | E4: Gap / note
A5: F1.1.2 | B5: Prove the mobile number by SMS OTP | C5: DONE | D5: #190, #192, #194 | E5: Email channel live: OtpProvider routing, 6-digit codes, 5-minute expiry (verified on test.gokesari.com: emails now say 5 minutes), 5 attempts, resend cooldown, DB-backed limits per email/user/IP, hashed + audited, hourly purge. 'OTP sent to your email' wording. SMS = Phase-2 stub (vendor decision D2).
A6: F1.4.3 | B6: Online (e-commerce) reference prices shown to customers | C6: DROPPED | D6: #190, #194 | E6: Dropped by a code constant (not a setting): hidden on product pages and for shops, public API 404, admin menu entry removed, no scraping or external calls at runtime; PR #23 code kept and isolated; offline Open Prices CLI refuses to run.
A7: F1.7.3 | B7: Pay the order directly by UPI / card / netbanking | C7: DONE-SANDBOX | D7: #190, #192, #194 | E7: PaymentGateway interface: sandbox (working on test.gokesari.com after #192), Cashfree adapter, Razorpay/PhonePe scaffolds; UPI/card/netbanking via hosted checkout only (no card data). Production flag onlinePayments OFF until gateway choice, merchant account, live keys and webhook secret (Owner inputs §1-2).
A8: F1.8.4 | B8: Gateway payment confirmation and payment state machine | C8: DONE-SANDBOX | D8: #190, #192, #194 | E8: Payment state machine CREATED>PENDING>AUTHORIZED>CAPTURED>(PARTIALLY_)REFUNDED + FAILED/EXPIRED; signed webhooks, idempotent by event id, reconciled with the gateway's order status; 5-minute reconciliation job; order idempotency key; order CONFIRMED only on CAPTURED.
A9: F3.3.2 | B9: Broadcast offers / widen the radius | C9: DONE | D9: #190, #194 | E9: Rider side: broadcast after N s, radius 2>4>6 km, atomic first accept, 'Offer taken' (rule dispatchBroadcast, OFF until the owner switches it on). Owner request: admin/operator broadcasts (audience, city/PIN, schedule, expiry) + Notification Centre (bell + /notifications, read/unread) on web and app; push/email by opt-in.
A10: F4.1.3 | B10: Pickup by QR code | C10: DONE | D10: #190, #192, #194 | E10: Signed single-use QR (HMAC) on the shop screen and printable packing slip; camera scan in the rider app; PICKED_UP with time + GPS, customer told at once; typed-code fallback. Rule pickupQr OFF; on gokesari.com set PICKUP_QR_SECRET first.
A11: F4.2.2 | B11: In-app turn-by-turn navigation | C11: DONE-SANDBOX | D11: #190, #194 | E11: RoutingProvider (mock / Google Routes / OSRM): route line, next manoeuvre, ETA, off-route re-route, voice prompts, Open-in-Google-Maps; keeps feeding live tracking. Mock router on test; real directions need a Google Routes key or own OSRM server. Rule riderNavigation OFF.
A12: F4.2.6 | B12: Signature capture | C12: DEFERRED-PHASE-2 | D12: - | E12: Signature capture deferred to Phase 2 by the owner; not built.
A13: F6.1.3 | B13: After-packing treatments (D10) signed off | C13: DONE | D13: #190, #194 | E13: Before packing: full refund incl. delivery (unchanged). After packing: per-shop fee (amount or %, cap, on/off) within admin limits, shown before confirming, written to the order ledger. Rule afterPackingCancellation OFF until the refund policy text is updated.
A14: F6.2.3 | B14: Refund to card / UPI | C14: DONE-SANDBOX | D14: #190, #194 | E14: Itemised refund breakdown; customer chooses original method (gateway refund API, intent > REFUNDED/PARTIALLY_REFUNDED) or instant wallet (wallet created if missing); wallet/COD orders refund to wallet; email + push; refund timeline in the order. Original-method refunds live with onlinePayments.
A15: F6.3.3 | B15: Issue state machine scope (SM-006) | C15: DONE | D15: #190, #194 | E15: Ticket state machine (OPEN>ACK>IN_PROGRESS>AWAITING_CUSTOMER/SHOP>RESOLVED>CLOSED + REOPENED/ESCALATED), portal + from the order, attachments, queues, assignment, internal notes, canned replies, SLA timers + escalation (Rule 4: 48 h / one month, configurable), CSAT, notify every change, Grievance Officer editable in Admin. Counsel to confirm the rule text.
... A28: F15.2.3 | B28: gokesari.com links open the app (deep links) | C28: BLOCKED-OWNER-INPUT | D28: #190, #194 | E28: Built and live on test: assetlinks.json (host-aware package) and apple-app-site-association (no extension, application/json) always served, intent filters with autoVerify, associated domains, route map product/shop/order/invite/notification/ticket, in-app routing, web fallback. Activates when the owner sets the SHA-256 fingerprint and Apple Team ID (docs/deep-links-activation.md).
A30: Totals
A31: DONE | B31: =COUNTIF($C$5:$C$28,"DONE")
A32: DONE-SANDBOX | B32: =COUNTIF($C$5:$C$28,"DONE-SANDBOX")
A33: DROPPED | B33: =COUNTIF($C$5:$C$28,"DROPPED")
A34: DEFERRED-PHASE-2 | B34: =COUNTIF($C$5:$C$28,"DEFERRED-PHASE-2")
A35: ON-HOLD | B35: =COUNTIF($C$5:$C$28,"ON-HOLD")
A36: BLOCKED-OWNER-INPUT | B36: =COUNTIF($C$5:$C$28,"BLOCKED-OWNER-INPUT")

Sheet Bulk Product Upload
A1: Bulk product upload (Excel/CSV) with shop inventory update - sub-feature status
A2: Statuses: Not started / In progress / Done on Test / Done on Prod / Blocked. Design: docs/product-import-2026-10/README.md. Tests: docs/testing/bulk-product-upload-test-report.md.
A4: ID | B4: Sub-feature | C4: Status | D4: Date | E4: Notes | F4: Branch / PR
A5: BPU-01 | B5: Parser (Amazon template) | C5: Done on Prod | D5: 2026-10-15 | E5: Built and unit-tested locally: Template sheet chosen, headings found by content (labels, attribute keys, section headers), ABC123 example + notice rows skipped, key-first mapping with qualifiers stripped (audience kept), repeated #1-#5 columns to arrays, lossless raw cells. 309-column PUZZLES fixture parses in ~0.2 s. Generic: no product-type logic. Not yet on Test. Live on test.gokesari.com 15 Oct: PI-03 pass (PUZZLES.xlsm: 309 columns, rows 6-7 left out, macros not run). Released to gokesari.com 15 Oct 15:58 UTC (PR #179); signed-out prod checks pass. | F5: PR #173, #174, release #179
A6: BPU-02 | B6: Parser (GoKesari template + CSV) | C6: Done on Prod | D6: 2026-10-15 | E6: Simple template (Products + Instructions sheets, Barcode Type/Unit/Action dropdowns, EXAMPLE row never imported) and CSV (comma/semicolon/tab, BOM). Header aliases case-insensitive. Tested locally. Live on test.gokesari.com 15 Oct: PI-02 template download, PI-09 template import pass. Released to gokesari.com 15 Oct 15:58 UTC (PR #179); signed-out prod checks pass. | F6: PR #173, #174, release #179
A7: BPU-03 | B7: Field mapping | C7: Done on Prod | D7: 2026-10-15 | E7: All §2 fields mapped; Indian numbers, dd/mm/yyyy and Excel-serial dates, Y/N, units to cm/g. Unreadable values = warnings, raw kept. Decision: file MRP = listing MRP (shop_listing_details), never master. Live on test.gokesari.com 15 Oct: PI-03/PI-04/PI-09 pass. Released to gokesari.com 15 Oct 15:58 UTC (PR #179); signed-out prod checks pass. | F7: PR #173, #174, release #179
A8: BPU-04 | B8: Matching & master catalogue | C8: Done on Prod | D8: 2026-10-15 | E8: SKU (or P-code) → barcode → name+brand(+size/color) → new Pending product. Pending products visible to the existing duplicate check. Decision: fallback category = General (system 'uncategorised'). Live on test.gokesari.com 15 Oct: PI-05 re-import matched all 5 by SKU (5 updated); PI-11 Edit with no match skipped. Released to gokesari.com 15 Oct 15:58 UTC (PR #179); signed-out prod checks pass. | F8: PR #173, #174, release #179
A9: BPU-05 | B9: Inventory update + ledger | C9: Done on Prod | D9: 2026-10-15 | E9: Set / Add modes, blank / negative / non-numeric quantity rules, duplicate-SKU merge, inventory_movements with source=bulk_upload + import_job_id + user, row lock + atomic add (tested with concurrent orders). Online stock. Live on test.gokesari.com 15 Oct: PI-10 Set 11 then Add 4 = 15; PI-11 blank/negative unchanged; PI-13 Delete = stock 0. Released to gokesari.com 15 Oct 15:58 UTC (PR #179); signed-out prod checks pass. | F9: PR #173, #174, release #179
A10: BPU-06 | B10: Image import | C10: Done on Prod | D10: 2026-10-15 | E10: Async after commit; http/https only, SSRF guard at connect time, JPEG/PNG/WebP, 5 MB, 15 s, each URL once; existing photo pipeline + moderation; failures are row warnings. Live on test.gokesari.com 15 Oct: Fixture image URLs (example CDN) refused with row warnings, products still created. Real image URLs not tried on the site. Released to gokesari.com 15 Oct 15:58 UTC (PR #179); signed-out prod checks pass. | F10: PR #173, #174, release #179
A11: BPU-07 | B11: Web UI (shop owner) | C11: Done on Prod | D11: 2026-10-15 | E11: Inventory → Bulk upload (Excel/CSV) tile; /shop/product-import: drag-and-drop, template, help, background check with progress, preview (summary, paginated table, warnings filter, stock mode), import progress, result + report, history, duplicate-file prompt. Checked in a browser locally (screenshots in docs/product-import-2026-10/screenshots). Live on test.gokesari.com 15 Oct: PI-01..PI-15 pass (desktop + phone cards with the Android app agent). Released to gokesari.com 15 Oct 15:58 UTC (PR #179); signed-out prod checks pass. | F11: PR #173, #174, release #179
A12: BPU-08 | B12: Web UI (admin/operator) | C12: Done on Prod | D12: 2026-10-15 | E12: /admin/product-import with shop picker; tiles under admin Product master and operator Catalogue. Checked locally as admin and operator. Operators' prices go to the owner for approval (existing rule). Live on test.gokesari.com 15 Oct: Admin and operator PS-01..04 pass; operator prices go to the owner, admin prices apply. Released to gokesari.com 15 Oct 15:58 UTC (PR #179); signed-out prod checks pass. | F12: PR #173, #174, release #179
A13: BPU-09 | B13: API | C13: Done on Prod | D13: 2026-10-15 | E13: 8 endpoints under /api/v1 (+ shop picker). Owner = own shops only; operator/admin any shop; audit-logged. Route tests pass. Live on test.gokesari.com 15 Oct: PI-08/PI-09/PI-15 and the staff runs use /api/v1. Released to gokesari.com 15 Oct 15:58 UTC (PR #179); signed-out prod checks pass. | F13: PR #173, #174, release #179
A14: BPU-10 | B14: Android app | C14: In progress | D14: 2026-10-15 | E14: Version 1.1.0 / versionCode 2. The app shows the website: the upload uses Android's system document picker (Files, Drive, WhatsApp, e-mail attachments). APKs built by the PR's 'Android APK' workflow; Play Store AAB needs EAS (Expo account) - not run. Live on test.gokesari.com 15 Oct: APK run 19 (Android APK workflow) built 1.1.0/versionCode 2; phone-width app agent preview pass (PI-12). System file picker on a real phone not tried; AAB needs EAS. | F14: PR #173, #174, release #179
A15: BPU-11 | B15: iOS app | C15: Blocked | D15: 2026-10-15 | E15: Code is shared with Android (version 1.1.0 / buildNumber 2; iPhone Files picker). iPhone build/TestFlight runs on EAS and needs EXPO_TOKEN + Apple Developer account - not available to this session. | F15: PR #173, #174, release #179
... A21: BPU-17 | B21: Testing report | C21: Done on Prod | D21: 2026-10-15 | E21: Test report md + PDF: Test 23/23 (section 2.7), Prod signed-out 13/13 (section 2.8). | F21: PR #173, #174, release #179

Sheet Inventory & Accounting
A1: Inventory & Accounting for shop owners (NEW-067) - feature and sub-feature status
A2: Statuses: Not started / In progress / Done / Blocked (dropdown in column E). Done = built, tested and live on gokesari.com (released by #179). Design: docs/inventory-accounting-2026-10/README.md. Tests: docs/inventory-accounting-2026-10/TESTING_REPORT.md and INVENTORY_ACCOUNTING_TEST_REPORT_2026-10-15.xlsx.
A4: ID | B4: Part | C4: Feature / sub-feature | D4: What it does | E4: Status | F4: Where it runs | G4: Date | H4: Notes / blocked on | I4: PR(s)
A5: IA-001 | B5: 1 Inventory | C5: Product master per shop | D5: Listings linked to the gokesari.com master product (MRP, HSN, GST rate, unit, barcode/GTIN); shop-level HSN/GST/price stay per shop | E5: Done | F5: Production (gokesari.com) and test | G5: 2026-10-15 | H5: - | I5: #171, released #179
A6: IA-002 | B6: 1 Inventory | C6: Stock ledger | D6: inv_stock_ledger: every movement (opening, purchase, sale, sale return, damage/expiry write-off, adjustment, reversal) with date, source document, qty, cost/rate, user; current stock = sum of the ledger | E6: Done | F6: Production (gokesari.com) and test | G6: 2026-10-15 | H6: - | I6: #171, released #179
A7: IA-003 | B7: 1 Inventory | C7: Online orders reduce stock in real time | D7: DB triggers on shop_products / inventory_movements write the ledger row in the checkout / cancellation / subscription / catalogue transaction (event-driven, no cron, existing code unchanged) | E7: Done | F7: Production (gokesari.com) and test | G7: 2026-10-15 | H7: Verified on test.gokesari.com with a real customer order (stock 199 → 198, SALE row with the order id) and its cancellation; a cancellation is labelled SALE_RETURN since migration 0078 (found in staging testing) | I7: #171, #172 (0078), released #179
A8: IA-004 | B8: 1 Inventory | C8: Opening balance backfill | D8: Migration 0076 writes today's stock of every listing as OPENING so ledger = stock from day one; drift check on the stock page | E8: Done | F8: Production (gokesari.com) and test | G8: 2026-10-15 | H8: - | I8: #171, released #179
A9: IA-005 | B9: 1 Inventory | C9: Batch & expiry tracking | D9: Per listing (auto-on when a bill has batch numbers); FEFO batch balances; expiring-soon list with alert window setting | E9: Done | F9: Production (gokesari.com) and test | G9: 2026-10-15 | H9: - | I9: #171, released #179
A10: IA-006 | B10: 1 Inventory | C10: Low stock / reorder level | D10: Existing per-shop thresholds and stock alerts reused; purchases and write-offs re-evaluate alerts | E10: Done | F10: Production (gokesari.com) and test | G10: 2026-10-15 | H10: - | I10: #171, released #179
A11: IA-007 | B11: 1 Inventory | C11: Stock valuation FIFO / weighted average | D11: Selectable per shop; reversals take back exactly the reversed cost; uncosted opening stock valued at last purchase rate and reported | E11: Done | F11: Production (gokesari.com) and test | G11: 2026-10-15 | H11: - | I11: #171, released #179
A12: IA-008 | B12: 1 Inventory | C12: Loose goods & unit conversions | D12: kg/g/L/ml/piece/dozen, UQC codes, Hindi/Marathi unit words; owner-saved conversions (1 case = 24); fractional quantities exact in the ledger | E12: Done | F12: Production (gokesari.com) and test | G12: 2026-10-15 | H12: - | I12: #171, released #179
A13: IA-009 | B13: 1 Inventory | C13: Write-off and physical count | D13: Damage / expiry write-off at cost (P&L line); physical count posts the difference as an adjustment | E13: Done | F13: Production (gokesari.com) and test | G13: 2026-10-15 | H13: - | I13: #171, released #179
A14: IA-010 | B14: 2 Accounting | C14: Purchase register | D14: Confirmed bills, versions, cancellations; month filter | E14: Done | F14: Production (gokesari.com) and test | G14: 2026-10-15 | H14: - | I14: #171, released #179
A15: IA-011 | B15: 2 Accounting | C15: Sales register | D15: Own GST invoices plus GoKesari order tax invoices | E15: Done | F15: Production (gokesari.com) and test | G15: 2026-10-15 | H15: - | I15: #171, released #179
... A60: IA-056 | B60: 7 Data & security | C60: Encryption key on the servers | D60: INTEGRATION_ENCRYPTION_KEY (base64, 32 bytes) set on test.gokesari.com and gokesari.com — needed for GST portal linking and for encrypting stored bills | E60: Blocked | F60: Server settings (test and production) | G60: 2026-10-15 | H60: Owner added the variable on test and production (15 Oct), but the value is not base64 of 32 bytes: test.gokesari.com reports encryption not configured (/api/shops/{id}/integration → ready.encryption=false) and GST linking answers 500. Fix: set the value from `openssl rand -base64 32` (44 characters ending in '='), a different one per site, and redeploy. Nothing has been encrypted with the old values | I60: #171, released #179
A62: Count | B62: Done | C62: =COUNTIF($E$5:$E$60,B62)
B63: In progress | C63: =COUNTIF($E$5:$E$60,B63)
B64: Not started | C64: =COUNTIF($E$5:$E$60,B64)
B65: Blocked | C65: =COUNTIF($E$5:$E$60,B65)
B66: Total | C66: =SUM(C62:C65)

Sheet Feature Register
A1: # | B1: Section | C1: Feature ID | D1: Module / area | E1: Feature | F1: Functionality (what it does today) | G1: Process flow step(s) | H1: Priority | I1: Status (18 Oct 2026) | J1: Where it runs | K1: Switched on? | L1: Built in PR(s) | M1: Released to production in PR(s) | N1: Remaining scope / gap | O1: Blocked on / next step | P1: Status 16 Oct | Q1: Change since 16 Oct (PRs #185-#188) | R1: Evidence (code / docs)
A2: 1 | B2: Feature Master | C2: GS-001 | D2: Identity & Access | E2: Mobile/email/Gmail login | F2: Google, email magic link and a single mobile-or-email form; first-time /onboarding profile; My Profile with verified email change; checkout requires a mobile; admin can release a wrongly claimed number. Login rebuild now on main (was staging-only on 3 Oct). | G2: F1.1.1, F1.1.2, F1.1.3 | H2: P0 | I2: BLOCKED | J2: Production - partly live | K2: Live (email OTP); SMS OTP not available | L2: #10 (magic link); #23 (Phase A mobile OTP); #31 (login rebuild, onboarding, My Profile); #80 (same OTP reply); #121 (one consent box) | M2: #14; #23; #43; #81; #123 | N2: SMS delivery of the OTP so a mobile number is proven (OTP provider seam ready). | O2: D2 - SMS/OTP vendor with DLT registration | P2: BLOCKED | Q2: No change | R2: src/server/otp/providers.ts; src/app/onboarding; src/app/profile; drizzle/0038_login_profile.sql
A3: 2 | B3: Feature Master | C3: GS-002 | D3: Identity & Access | E3: Role-based access control | F3: SOCIETY_ADMIN role; society roles scoped per membership (ADMIN/OPERATOR/RESIDENT) | G3: F5.1.2, F12.2.1 | H3: P0 | I3: COMPLETED | J3: Production (gokesari.com) | K3: Live | L3: Baseline; #10 (SOCIETY_ADMIN); #11 (society roles) | M3: Baseline; #14; #19 | N3: - | O3: - | P3: COMPLETED | Q3: No change | R3: src/server/authz/permissions.ts; src/server/db/schema.ts (userRoleEnum)
A4: 3 | B4: Feature Master | C4: GS-003 | D4: Identity & Access | E4: Multi-role user account | F4: user_role_grants; active role switcher in the header; /api/me/roles; admin revoke; shop/rider/society flows grant roles; staff roles exclusive | G4: F12.2.1 | H4: P1 | I4: COMPLETED | J4: Production (gokesari.com) | K4: Live | L4: #18 | M4: #19 | N4: - | O4: - | P4: COMPLETED | Q4: No change | R4: src/server/services/roles.ts; src/app/api/me/roles/route.ts
A5: 4 | B5: Feature Master | C5: GS-004 | D5: Location | E5: PIN / address selection | F5: 'Deliver to' location: saved address, device position or PIN, remembered in a cookie. Phase B added Maps Places address search, a 'save this place' path, and recipient name / recipient mobile / Home-Work-Other on addresses | G5: F1.2.1 | H5: P0 | I5: COMPLETED | J5: Production (gokesari.com) | K5: Live | L5: Baseline (location capture); #10 (customer location); #23 (Phase B); #83 (Deliver-to pill) | M5: Baseline; #14; #23; #84 | N5: - | O5: - | P5: COMPLETED | Q5: No change | R5: src/lib/geo/provider.ts; src/components/location-bar.tsx; drizzle/0026
A6: 5 | B6: Feature Master | C6: GS-005 | D6: Location | E6: Society identification | F6: Society membership; address <-> society link; orders.society_id | G6: F1.2.2, F5.1.2 | H6: P0 | I6: COMPLETED | J6: Production (gokesari.com) | K6: Live | L6: #11 | M6: #19 | N6: - | O6: - | P6: COMPLETED | Q6: No change | R6: src/server/services/societies.ts
A7: 6 | B7: Feature Master | C7: GS-006 | D7: Shop Onboarding | E7: Shop registration | F7: Shop owner registers a shop (/shop/register): name, owner, address with map location, shop type and categories, at least one of PAN / Udyam / GST / Shop Act; duplicate-registration guard; resubmission after rejection; operations approve or reject. | G7: F8.1.1 | H7: P0 | I7: COMPLETED | J7: Production (gokesari.com) | K7: Live | L7: Baseline; #22 (duplicate guard); #45 (validation, GST field); #53 (documents) | M7: Baseline; #19; #47; #54 | N7: 6 Oct: GST field added at registration; at least one of PAN / Udyam / GST / Shop Act required (135f29a). | O7: - | P7: COMPLETED | Q7: No change | R7: -
A8: 7 | B8: Feature Master | C8: GS-007 | D8: Shop Onboarding | E8: Business KYC | F8: Seller verification Parts 1-4: PAN, GSTIN, Udyam, FSSAI and Shop Act per shop with document upload, vendor check (provider-agnostic, Gridlines adapter + mock), name matching, cross-document consistency score, per-document status, admin review queue (approve / reject with reason / re-check), daily re-check and expiry job, auto-suspend on lapse, DPDP retention/erasure. | G8: F8.2.1 | H8: P0 | I8: COMPLETED | J8: Production (gokesari.com) | K8: Live; vendor checks run on the MOCK vendor until Gridlines keys are set (KYC_PROVIDER) | L8: Baseline (GST/PAN self-service); #53 (seller verification) | M8: Baseline; #54 | N8: Real vendor: Gridlines sandbox then live keys and written confirmation of response fields, Shop Act coverage, prices, DPA. Since SM-002 (PR #58) an admin can approve a shop only once every mandatory document is verified (VERIFIED stage). | O8: - | P8: COMPLETED | Q8: No change | R8: src/server/services/seller-verification*.ts; src/server/kyc/; /shop/verification; /admin/seller-verification; drizzle/0040, 0041; docs/seller-verification/
A9: 8 | B9: Feature Master | C9: GS-008 | D9: Shop Onboarding | E9: Payment reference verification | F9: approveShop() now refuses unless fee_payment_status = PAID (derived from the shop_payments ledger), naming the amount outstanding; waived fee (zero snapshot) is written PAID at registration; approval queue shows each pending shop's fee state. Gate is on the transition only - shops already APPROVED untouched | G9: F8.2.3 | H9: P0 | I9: COMPLETED | J9: Production (gokesari.com) | K9: Live | L9: Baseline (registration fees); #29 (fee gate on approval) | M9: Baseline; #29 | N9: - | O9: - | P9: COMPLETED | Q9: No change | R9: src/server/services/shops.ts (approveShop); src/components/shop-approval-panel.tsx; tests/integration/registration-fees.test.ts
A10: 9 | B10: Feature Master | C10: GS-009 | D10: Shop Onboarding | E10: Shop categories | F10: Admin-configurable category master: shop_categories + shop_category_mapping (many per shop), seeded from the 44 shop types and backfilled; registration requires at least one category; owners edit their own on /shop; operators/admins manage the list at /admin/shop-categories and assign per shop; uncategorised shops flagged; categories feed search relevance | G10: F8.3.2 | H10: P0 | I10: COMPLETED | J10: Production (gokesari.com) | K10: Live | L10: #23 (shop categories); #30 (explicit Save) | M10: #23; #32 | N10: - | O10: - | P10: COMPLETED | Q10: No change | R10: src/server/services/shop-categories.ts; src/app/admin/shop-categories/page.tsx; drizzle/0035
A11: 10 | B11: Feature Master | C11: GS-010 | D11: Shop Onboarding | E11: Service radius / delivery zone | F11: shops.service_radius_km (1-50 km) editable by the shop; Phase B added extra delivery zones by PIN code (shops.delivery_pincodes), honoured by serviceability, checkout and discovery | G11: F8.3.3 | H11: P0 | I11: COMPLETED | J11: Production (gokesari.com) | K11: Live | L11: Baseline; #10 (delivery radius); #23 (Phase B PIN zones) | M11: Baseline; #14; #23 | N11: - | O11: - | P11: COMPLETED | Q11: No change | R11: src/server/services/serviceability.ts; src/server/db/schema.ts:691; drizzle/0019, 0026
A12: 11 | B12: Feature Master | C12: GS-011 | D12: Catalog | E12: Product master | F12: Central product catalogue (products) with brand, pack size, GTIN, HSN, GST rate and MRP; fed by the Product Master Data Platform (PMD) and the category master; shop-created products go through an approval queue. | G12: - | H12: P0 | I12: COMPLETED | J12: Production (gokesari.com) | K12: Live | L12: Baseline (product identity/MRP); #4 (Product Master platform); #38 (category master) | M12: Baseline; #8; #43 | N12: - | O12: - | P12: COMPLETED | Q12: No change | R12: -
A13: 12 | B13: Feature Master | C13: GS-012 | D13: Catalog | E13: Shop catalog mapping | F13: Each shop lists master products as its own listings (shop_products) with its own online and in-shop price, stock and availability; listings follow the shop's product categories. | G13: F9.2.2 | H13: P0 | I13: COMPLETED | J13: Production (gokesari.com) | K13: Live | L13: Baseline (shop-created products); #38 (category visibility); #45 (inventory fill) | M13: Baseline; #43; #47 | N13: - | O13: - | P13: COMPLETED | Q13: No change | R13: -
... A268: 267 | B268: Known gaps (not started) | C268: GAP-019 | D268: Checkout | E268: Wallet checkout takes 30-38 s on the test site | F268: Placing an order with the wallet took 30+ s (timed out once; the retry with the same request id was safe and charged once) and 37.8 s on the rerun. | G268: - | H268: - | I268: YET TO START | J268: Not started | K268: - | L268: - | M268: - | N268: Profile checkout on test; likely the far database (GAP-010) | O268: - | P268: YET TO START | Q268: No change | R268: docs/order-lifecycle-2026-10/TEST_RESULTS_STAGING_2026-10-14.md

Sheet Process Flow Tree
A1: GoKesari process flow trees - status of every step (16 Oct 2026)
A2: Level 1 = end-to-end flow, level 2 = stage, level 3 = step. Step status is set by hand (dropdown in column G); stage and flow status are formulas: COMPLETED only when every step is; BLOCKED if any step is blocked; YET TO START when no step has started; otherwise IN PROGRESS.
A4: Flow / step ID | B4: Level | C4: Process flow tree | D4: Actor | E4: Feature IDs | F4: Steps done | G4: Status | H4: Built in PR(s) | I4: Gap / note | J4: Batch status (18 Oct) | K4: Batch PR(s) | L4: Batch gap / note
A5: F1 | B5: 1 | C5: F1 Customer purchase journey | D5: Customer | F5: =COUNTIFS($B$6:$B$48,3,$G$6:$G$48,"COMPLETED")&" / "&COUNTIF($B$6:$B$48,3) | G5: =IF(COUNTIFS($B$6:$B$48,3,$G$6:$G$48,"COMPLETED")=COUNTIF($B$6:$B$48,3),"COMPLETED",IF(COUNTIFS($B$6:$B$48,3,$G$6:$G$48,"BLOCKED")>0,"BLOCKED",IF(COUNTIFS($B$6:$B$48,3,$G$6:$G$48,"YET TO START")=COUNTIF($B$6:$B$48,3),"YET TO START","IN PROGRESS"))) | J5: =(COUNTIFS($B$6:$B$48,3,$J$6:$J$48,"DONE")+COUNTIFS($B$6:$B$48,3,$J$6:$J$48,"DONE-SANDBOX"))&" / "&COUNTIFS($B$6:$B$48,3,$J$6:$J$48,"<>")&" batch steps done"
A6: F1.1 | B6: 2 | C6: F1.1 Sign in and profile | F6: =COUNTIFS($B$7:$B$9,3,$G$7:$G$9,"COMPLETED")&" / "&COUNTIF($B$7:$B$9,3) | G6: =IF(COUNTIFS($B$7:$B$9,3,$G$7:$G$9,"COMPLETED")=COUNTIF($B$7:$B$9,3),"COMPLETED",IF(COUNTIFS($B$7:$B$9,3,$G$7:$G$9,"BLOCKED")>0,"BLOCKED",IF(COUNTIFS($B$7:$B$9,3,$G$7:$G$9,"YET TO START")=COUNTIF($B$7:$B$9,3),"YET TO START","IN PROGRESS"))) | J6: =(COUNTIFS($B$7:$B$9,3,$J$7:$J$9,"DONE")+COUNTIFS($B$7:$B$9,3,$J$7:$J$9,"DONE-SANDBOX"))&" / "&COUNTIFS($B$7:$B$9,3,$J$7:$J$9,"<>")&" batch steps done"
A7: F1.1.1 | B7: 3 | C7: Sign in with Google, email magic link or a code sent to email (mobile or email form) | D7: Customer | E7: GS-001, NEW-018 | G7: COMPLETED | H7: #10; #23; #31; #80 | I7: -
A8: F1.1.2 | B8: 3 | C8: Prove the mobile number by SMS OTP | D8: Customer | E8: GS-001, GS-074 | G8: COMPLETED | H8: #190, #192, #194 | I8: DONE (18 Oct batch): Email channel live: OtpProvider routing, 6-digit codes, 5-minute expiry (verified on test.gokesari.com: emails now say 5 minutes), 5 attempts, resend cooldown, DB-backed limits per email/user/IP, hashed + audited, hourly purge. 'OTP sent to your email' wording. SMS = Phase-2 stub (vendor decision D2). | J8: DONE | K8: #190, #192, #194 | L8: Email channel live: OtpProvider routing, 6-digit codes, 5-minute expiry (verified on test.gokesari.com: emails now say 5 minutes), 5 attempts, resend cooldown, DB-backed limits per email/user/IP, hashed + audited, hourly purge. 'OTP sent to your email' wording. SMS = Phase-2 stub (vendor decision D2).
A9: F1.1.3 | B9: 3 | C9: First-time profile (/onboarding) and My Profile | D9: Customer | E9: GS-001 | G9: COMPLETED | H9: #31 | I9: -
A10: F1.2 | B10: 2 | C10: F1.2 Location and society | F10: =COUNTIFS($B$11:$B$12,3,$G$11:$G$12,"COMPLETED")&" / "&COUNTIF($B$11:$B$12,3) | G10: =IF(COUNTIFS($B$11:$B$12,3,$G$11:$G$12,"COMPLETED")=COUNTIF($B$11:$B$12,3),"COMPLETED",IF(COUNTIFS($B$11:$B$12,3,$G$11:$G$12,"BLOCKED")>0,"BLOCKED",IF(COUNTIFS($B$11:$B$12,3,$G$11:$G$12,"YET TO START")=COUNTIF($B$11:$B$12,3),"YET TO START","IN PROGRESS"))) | J10: =(COUNTIFS($B$11:$B$12,3,$J$11:$J$12,"DONE")+COUNTIFS($B$11:$B$12,3,$J$11:$J$12,"DONE-SANDBOX"))&" / "&COUNTIFS($B$11:$B$12,3,$J$11:$J$12,"<>")&" batch steps done"
A11: F1.2.1 | B11: 3 | C11: Choose where to deliver: saved address, device position, PIN or map pin | D11: Customer | E11: GS-004 | G11: COMPLETED | H11: #10; #23; #83 | I11: Map 'Confirm location' 500 on test: the server key is restricted by referrer (GAP-008, owner)
A12: F1.2.2 | B12: 3 | C12: Society recognised from the address | D12: Customer | E12: GS-005 | G12: COMPLETED | H12: #11 | I12: -
A13: F1.3 | B13: 2 | C13: F1.3 Discover shops and products | F13: =COUNTIFS($B$14:$B$17,3,$G$14:$G$17,"COMPLETED")&" / "&COUNTIF($B$14:$B$17,3) | G13: =IF(COUNTIFS($B$14:$B$17,3,$G$14:$G$17,"COMPLETED")=COUNTIF($B$14:$B$17,3),"COMPLETED",IF(COUNTIFS($B$14:$B$17,3,$G$14:$G$17,"BLOCKED")>0,"BLOCKED",IF(COUNTIFS($B$14:$B$17,3,$G$14:$G$17,"YET TO START")=COUNTIF($B$14:$B$17,3),"YET TO START","IN PROGRESS"))) | J13: =(COUNTIFS($B$14:$B$17,3,$J$14:$J$17,"DONE")+COUNTIFS($B$14:$B$17,3,$J$14:$J$17,"DONE-SANDBOX"))&" / "&COUNTIFS($B$14:$B$17,3,$J$14:$J$17,"<>")&" batch steps done"
A14: F1.3.1 | B14: 3 | C14: Shops that deliver here / Shops near you, with filters and sort | D14: Customer | E14: GS-019, NAV-001, NEW-019, NEW-051 | G14: COMPLETED | H14: #10; #83 | I14: -
A15: F1.3.2 | B15: 3 | C15: Product search limited to serviceable shops | D15: Customer | E15: GS-020 | G15: COMPLETED | H15: #10; #48; #83 | I15: -
A16: F1.3.3 | B16: 3 | C16: Every shop selling a product | D16: Customer | E16: GS-021 | G16: COMPLETED | H16: #10 | I16: -
A17: F1.3.4 | B17: 3 | C17: Shops near me from the phone's location: radius 1-10 km, list or map, Directions; PIN box if location is refused | D17: Customer | E17: NEW-057, NEW-059 | G17: COMPLETED | H17: #133; #136; #135 | I17: Live on gokesari.com
A18: F1.4 | B18: 2 | C18: F1.4 Compare prices | F18: =COUNTIFS($B$19:$B$21,3,$G$19:$G$21,"COMPLETED")&" / "&COUNTIF($B$19:$B$21,3) | G18: =IF(COUNTIFS($B$19:$B$21,3,$G$19:$G$21,"COMPLETED")=COUNTIF($B$19:$B$21,3),"COMPLETED",IF(COUNTIFS($B$19:$B$21,3,$G$19:$G$21,"BLOCKED")>0,"BLOCKED",IF(COUNTIFS($B$19:$B$21,3,$G$19:$G$21,"YET TO START")=COUNTIF($B$19:$B$21,3),"YET TO START","IN PROGRESS"))) | J18: =(COUNTIFS($B$19:$B$21,3,$J$19:$J$21,"DONE")+COUNTIFS($B$19:$B$21,3,$J$19:$J$21,"DONE-SANDBOX"))&" / "&COUNTIFS($B$19:$B$21,3,$J$19:$J$21,"<>")&" batch steps done"
A19: F1.4.1 | B19: 3 | C19: Local price comparison across shops | D19: Customer | E19: GS-022 | G19: COMPLETED | H19: #10; #72 | I19: -
A20: F1.4.2 | B20: 3 | C20: Home-page price comparison (F9) | D20: Customer | E20: NAV-001 | G20: COMPLETED | H20: #55 | I20: Off by default
A21: F1.4.3 | B21: 3 | C21: Online (e-commerce) reference prices shown to customers | D21: Customer | E21: GS-023 | G21: BLOCKED | H21: #23; #190, #194 | I21: DROPPED (18 Oct batch): Dropped by a code constant (not a setting): hidden on product pages and for shops, public API 404, admin menu entry removed, no scraping or external calls at runtime; PR #23 code kept and isolated; offline Open Prices CLI refuses to run. | J21: DROPPED | K21: #190, #194 | L21: Dropped by a code constant (not a setting): hidden on product pages and for shops, public API 404, admin menu entry removed, no scraping or external calls at runtime; PR #23 code kept and isolated; offline Open Prices CLI refuses to run.
A22: F1.5 | B22: 2 | C22: F1.5 Cart | F22: =COUNTIFS($B$23:$B$27,3,$G$23:$G$27,"COMPLETED")&" / "&COUNTIF($B$23:$B$27,3) | G22: =IF(COUNTIFS($B$23:$B$27,3,$G$23:$G$27,"COMPLETED")=COUNTIF($B$23:$B$27,3),"COMPLETED",IF(COUNTIFS($B$23:$B$27,3,$G$23:$G$27,"BLOCKED")>0,"BLOCKED",IF(COUNTIFS($B$23:$B$27,3,$G$23:$G$27,"YET TO START")=COUNTIF($B$23:$B$27,3),"YET TO START","IN PROGRESS"))) | J22: =(COUNTIFS($B$23:$B$27,3,$J$23:$J$27,"DONE")+COUNTIFS($B$23:$B$27,3,$J$23:$J$27,"DONE-SANDBOX"))&" / "&COUNTIFS($B$23:$B$27,3,$J$23:$J$27,"<>")&" batch steps done"
A23: F1.5.1 | B23: 3 | C23: Add to cart with quantity controls on the product card | D23: Customer | E23: GS-024, NEW-012 | G23: COMPLETED | H23: #48; #72 | I23: -
A24: F1.5.2 | B24: 3 | C24: Multi-shop cart | D24: Customer | E24: GS-025 | G24: COMPLETED | H24: Baseline; #10 | I24: -
A25: F1.5.3 | B25: 3 | C25: Cart re-validated against the location (serviceability, stock, minimum order, paused shops) | D25: Customer | E25: GS-026, NEW-005 | G25: COMPLETED | H25: #11; #23 | I25: -
A26: F1.5.4 | B26: 3 | C26: Coupons (F7) and shop offers (F8) | D26: Customer | E26: NAV-003, NAV-002 | G26: COMPLETED | H26: #55 | I26: Off by default
A27: F1.5.5 | B27: 3 | C27: Open-order prompt before paying (C3) | D27: Customer | E27: NEW-024 | G27: COMPLETED | H27: #85; #120 | I27: Live on gokesari.com since #120 (9 Oct)
A28: F1.6 | B28: 2 | C28: F1.6 Checkout | F28: =COUNTIFS($B$29:$B$31,3,$G$29:$G$31,"COMPLETED")&" / "&COUNTIF($B$29:$B$31,3) | G28: =IF(COUNTIFS($B$29:$B$31,3,$G$29:$G$31,"COMPLETED")=COUNTIF($B$29:$B$31,3),"COMPLETED",IF(COUNTIFS($B$29:$B$31,3,$G$29:$G$31,"BLOCKED")>0,"BLOCKED",IF(COUNTIFS($B$29:$B$31,3,$G$29:$G$31,"YET TO START")=COUNTIF($B$29:$B$31,3),"YET TO START","IN PROGRESS"))) | J28: =(COUNTIFS($B$29:$B$31,3,$J$29:$J$31,"DONE")+COUNTIFS($B$29:$B$31,3,$J$29:$J$31,"DONE-SANDBOX"))&" / "&COUNTIFS($B$29:$B$31,3,$J$29:$J$31,"<>")&" batch steps done"
A29: F1.6.1 | B29: 3 | C29: Mobile number and delivery address required | D29: Customer | E29: GS-026 | G29: COMPLETED | H29: #31 | I29: -
A30: F1.6.2 | B30: 3 | C30: Delivery window or a scheduled time slot with capacity | D30: Customer | E30: GS-027 | G30: COMPLETED | H30: Baseline; #55; #58 | I30: Slots off by default
A31: F1.6.3 | B31: 3 | C31: Order from a closed shop after confirmation | D31: Customer | E31: NEW-003 | G31: COMPLETED | H31: #24 | I31: -
A32: F1.7 | B32: 2 | C32: F1.7 Payment | F32: =COUNTIFS($B$33:$B$35,3,$G$33:$G$35,"COMPLETED")&" / "&COUNTIF($B$33:$B$35,3) | G32: =IF(COUNTIFS($B$33:$B$35,3,$G$33:$G$35,"COMPLETED")=COUNTIF($B$33:$B$35,3),"COMPLETED",IF(COUNTIFS($B$33:$B$35,3,$G$33:$G$35,"BLOCKED")>0,"BLOCKED",IF(COUNTIFS($B$33:$B$35,3,$G$33:$G$35,"YET TO START")=COUNTIF($B$33:$B$35,3),"YET TO START","IN PROGRESS"))) | J32: =(COUNTIFS($B$33:$B$35,3,$J$33:$J$35,"DONE")+COUNTIFS($B$33:$B$35,3,$J$33:$J$35,"DONE-SANDBOX"))&" / "&COUNTIFS($B$33:$B$35,3,$J$33:$J$35,"<>")&" batch steps done"
A33: F1.7.1 | B33: 3 | C33: Pay from wallet (topped up through Cashfree) | D33: Customer | E33: GS-029, GS-028 | G33: COMPLETED | H33: Baseline | I33: -
A34: F1.7.2 | B34: 3 | C34: Cash on delivery with limits | D34: Customer | E34: GS-030 | G34: COMPLETED | H34: #18 | I34: -
A35: F1.7.3 | B35: 3 | C35: Pay the order directly by UPI / card / netbanking | D35: Customer | E35: GS-028, NEW-007 | G35: COMPLETED | H35: #190, #192, #194 | I35: DONE-SANDBOX (18 Oct batch): PaymentGateway interface: sandbox (working on test.gokesari.com after #192), Cashfree adapter, Razorpay/PhonePe scaffolds; UPI/card/netbanking via hosted checkout only (no card data). Production flag onlinePayments OFF until gateway choice, merchant account, live keys and webhook secret (Owner inputs §1-2). | J35: DONE-SANDBOX | K35: #190, #192, #194 | L35: PaymentGateway interface: sandbox (working on test.gokesari.com after #192), Cashfree adapter, Razorpay/PhonePe scaffolds; UPI/card/netbanking via hosted checkout only (no card data). Production flag onlinePayments OFF until gateway choice, merchant account, live keys and webhook secret (Owner inputs §1-2).
A36: F1.8 | B36: 2 | C36: F1.8 Order engine | F36: =COUNTIFS($B$37:$B$41,3,$G$37:$G$41,"COMPLETED")&" / "&COUNTIF($B$37:$B$41,3) | G36: =IF(COUNTIFS($B$37:$B$41,3,$G$37:$G$41,"COMPLETED")=COUNTIF($B$37:$B$41,3),"COMPLETED",IF(COUNTIFS($B$37:$B$41,3,$G$37:$G$41,"BLOCKED")>0,"BLOCKED",IF(COUNTIFS($B$37:$B$41,3,$G$37:$G$41,"YET TO START")=COUNTIF($B$37:$B$41,3),"YET TO START","IN PROGRESS"))) | J36: =(COUNTIFS($B$37:$B$41,3,$J$37:$J$41,"DONE")+COUNTIFS($B$37:$B$41,3,$J$37:$J$41,"DONE-SANDBOX"))&" / "&COUNTIFS($B$37:$B$41,3,$J$37:$J$41,"<>")&" batch steps done"
A37: F1.8.1 | B37: 3 | C37: Validate stock and service area | D37: Customer | E37: GS-026, GS-016 | G37: COMPLETED | H37: #11; #23 | I37: -
A38: F1.8.2 | B38: 3 | C38: Split by shop; one parent GK- reference (F6) | D38: Customer | E38: GS-033 | G38: COMPLETED | H38: Baseline; #55 | I38: Parent reference off by default
A39: F1.8.3 | B39: 3 | C39: Confirm wallet / COD payment inside the order transaction | D39: Customer | E39: GS-032 | G39: COMPLETED | H39: Baseline; #10 | I39: -
A40: F1.8.4 | B40: 3 | C40: Gateway payment confirmation and payment state machine | D40: Customer | E40: SM-005, GS-073 | G40: COMPLETED | H40: #190, #192, #194 | I40: DONE-SANDBOX (18 Oct batch): Payment state machine CREATED>PENDING>AUTHORIZED>CAPTURED>(PARTIALLY_)REFUNDED + FAILED/EXPIRED; signed webhooks, idempotent by event id, reconciled with the gateway's order status; 5-minute reconciliation job; order idempotency key; order CONFIRMED only on CAPTURED. | J40: DONE-SANDBOX | K40: #190, #192, #194 | L40: Payment state machine CREATED>PENDING>AUTHORIZED>CAPTURED>(PARTIALLY_)REFUNDED + FAILED/EXPIRED; signed webhooks, idempotent by event id, reconciled with the gateway's order status; 5-minute reconciliation job; order idempotency key; order CONFIRMED only on CAPTURED.
A41: F1.8.5 | B41: 3 | C41: Create the shop order and notify the shop | D41: Customer | E41: GS-032, GS-055 | G41: COMPLETED | H41: #10; #23 | I41: -
...

Sheet PR Register
A1: PR # | B1: Title | C1: Type | D1: Branch (head -> base) | E1: Target | F1: State | G1: Created | H1: Merged / closed | I1: Features built / extended | J1: Features released to production | K1: Released to production via | L1: Notes
A2: 1 | B2: Add the Product Master Data Platform (pilot) | C2: Feature | D2: feature/product-master-platform -> main | E2: Production (main -> gokesari.com) | F2: Closed - not merged | G2: 2026-09-20 | H2: 2026-09-21 | I2: PMD-001 | J2: - | K2: - | L2: Superseded by #4 (closed unmerged).
A3: 2 | B3: Add GS1 India and manufacturer-catalogue connectors (Excel, mapping templates) | C3: Feature | D3: feature/pmd-gs1-manufacturer-feeds -> feature/product-master-platform | E3: Stacked on feature/product-master-platform | F3: Closed - not merged | G3: 2026-09-20 | H3: 2026-09-21 | I3: PMD-002 | J3: - | K3: - | L3: Stacked on #1; superseded by #4.
A4: 3 | B4: PMD: loader rework for scale (bulk path, workers, dashboard/index fixes) | C4: Feature | D4: feature/pmd-loader-rework -> feature/product-master-platform | E4: Stacked on feature/product-master-platform | F4: Closed - not merged | G4: 2026-09-20 | H4: 2026-09-21 | I4: PMD-003 | J4: - | K4: - | L4: Stacked on #1; superseded by #4.
A5: 4 | B5: Product Master: platform, feeds, loader rework and shop-catalogue promotion (into staging) | C5: Feature | D5: release/pmd-to-staging -> staging | E5: Test site (staging -> test.gokesari.com) | F5: Merged | G5: 2026-09-20 | H5: 2026-09-20 | I5: GS-011, PMD-001, PMD-002, PMD-003, PMD-004 | J5: - | K5: #8 | L5: Released by #8.
A6: 5 | B6: Product Master: one-command copy of the pilot data into a target database | C6: Feature | D6: feature/pmd-copy-script -> staging | E6: Test site (staging -> test.gokesari.com) | F6: Merged | G6: 2026-09-20 | H6: 2026-09-21 | I6: PMD-004 | J6: - | K6: #8 | L6: Released by #8.
A7: 6 | B7: Product Master: fix duplicate brand on concurrent promotion; parallel promotion option | C7: Feature | D7: feature/pmd-promote-concurrency -> staging | E7: Test site (staging -> test.gokesari.com) | F7: Merged | G7: 2026-09-21 | H7: 2026-09-21 | I7: PMD-004 | J7: - | K7: #8 | L7: Released by #8.
A8: 7 | B8: CI: checkout and setup-node v5 (Node 24) | C8: DevOps / repo | D8: chore/ci-node24-actions -> staging | E8: Test site (staging -> test.gokesari.com) | F8: Merged | G8: 2026-09-21 | H8: 2026-09-21 | I8: PLT-003 | J8: - | K8: #8 | L8: Released by #8.
A9: 8 | B9: Promote staging to main: Product Master platform (deploys live) | C9: Release (staging -> main) | D9: staging -> main | E9: Production (main -> gokesari.com) | F9: Merged | G9: 2026-09-21 | H9: 2026-09-21 | I9: - | J9: GS-011, PMD-001, PMD-002, PMD-003, PMD-004, PLT-003 | K9: Itself (merged to main)
A10: 9 | B10: Product Master: script to apply duplicate-review decisions | C10: Feature | D10: feature/pmd-review-decide -> staging | E10: Test site (staging -> test.gokesari.com) | F10: Merged | G10: 2026-09-21 | H10: 2026-09-21 | I10: PMD-005 | J10: - | K10: #12 | L10: Released by #12.
A11: 10 | B11: Phase 1 go-live development (for QA on staging) | C11: Feature | D11: dev/phase1-go-live -> staging | E11: Test site (staging -> test.gokesari.com) | F11: Merged | G11: 2026-09-24 | H11: 2026-09-28 | I11: GS-001, GS-002, GS-004, GS-010, GS-019, GS-020, GS-021, GS-022, GS-025, GS-031, GS-032, GS-034, GS-035, GS-036, GS-039, GS-041, GS-043, GS-055, GS-057, GS-061, GS-062, GS-064, GS-067, GS-070, GS-071, WF-001, WF-002, WF-003, WF-005, WF-007, WF-010, RBAC-002, RBAC-007, RBAC-011, RBAC-012, RBAC-015, SM-001, GA-006, GA-009, NAV-008, NAV-010, NEW-006 | J11: - | K11: #14 | L11: Squash-merged into staging; released by #14.
A12: 11 | B12: Phase 2: society, ratings, subscription expansion (for QA on staging) | C12: Feature | D12: dev/phase2-society -> staging | E12: Test site (staging -> test.gokesari.com) | F12: Merged | G12: 2026-09-25 | H12: 2026-09-28 | I12: GS-002, GS-005, GS-026, GS-040, GS-044, GS-045, GS-046, GS-047, GS-049, GS-051, GS-056, GS-059, GS-060, WF-001, WF-003, WF-004, WF-006, RBAC-009, SM-004, SM-006, GA-001, GA-002, GA-007, GA-008, NAV-002, NAV-014 | J12: - | K12: #19
A13: 12 | B13: Promote staging to main: Phase 1 + Phase 2 (deploys live) | C13: Release (staging -> main) | D13: staging -> main | E13: Production (main -> gokesari.com) | F13: Merged | G13: 2026-09-25 | H13: 2026-09-28 | I13: - | J13: PMD-005 | K13: Itself (merged to main) | L13: Squash release of #9 to main.
A14: 13 | B14: Hotfix: log the root cause of failed database queries | C14: Fix / hotfix | D14: hotfix/log-db-error-cause -> staging | E14: Test site (staging -> test.gokesari.com) | F14: Merged | G14: 2026-09-25 | H14: 2026-09-28 | I14: PLT-002 | J14: - | K14: #19
A15: 14 | B15: Staging | C15: Release (staging -> main) | D15: staging -> main | E15: Production (main -> gokesari.com) | F15: Merged | G15: 2026-09-28 | H15: 2026-09-28 | I15: - | J15: GS-001, GS-002, GS-004, GS-010, GS-019, GS-020, GS-021, GS-022, GS-025, GS-031, GS-032, GS-034, GS-035, GS-036, GS-039, GS-041, GS-043, GS-055, GS-057, GS-061, GS-062, GS-064, GS-067, GS-070, GS-071, WF-001, WF-002, WF-003, WF-005, WF-007, WF-010, RBAC-002, RBAC-007, RBAC-011, RBAC-012, RBAC-015, SM-001, GA-006, GA-009, NAV-008, NAV-010, NEW-006 | K15: Itself (merged to main) | L15: Squash release of Phase 1 (#10) to main.
A16: 15 | B16: fix: patch Node.js security vulnerabilities | C16: Security / dependencies | D16: fix/patch-vulnerabilities-07273736-1790597348 -> staging | E16: Test site (staging -> test.gokesari.com) | F16: Closed - not merged | G16: 2026-09-28 | H16: 2026-09-28 | I16: PLT-004 | J16: - | K16: - | L16: Superseded by the Next.js 16.3.6 bump released in #19.
A17: 16 | B17: Pin Node 20, bump Next.js to 16.3.6, log DB error causes | C17: Security / dependencies | D17: claude/turbopack-css-crash-2y3or2 -> main | E17: Production (main -> gokesari.com) | F17: Closed - not merged | G17: 2026-09-28 | H17: 2026-09-28 | I17: PLT-002, PLT-004 | J17: - | K17: - | L17: Closed; its DB-error logging landed via #13.
A18: 17 | B18: Hotfix: build with webpack so Hostinger deploys succeed | C18: Fix / hotfix | D18: hotfix/hostinger-webpack-build -> staging | E18: Test site (staging -> test.gokesari.com) | F18: Merged | G18: 2026-09-28 | H18: 2026-09-28 | I18: PLT-001 | J18: - | K18: #19 | L18: Squash-merged into staging; released by #19.
A19: 18 | B19: Phase 3: multi-role grants, COD, shop marketing, risk rules, KPI analytics | C19: Feature | D19: dev/phase3-growth -> staging | E19: Test site (staging -> test.gokesari.com) | F19: Merged | G19: 2026-09-28 | H19: 2026-09-28 | I19: GS-003, GS-030, GS-052, GS-053, GS-068, GS-069, WF-009, RBAC-013, NAV-009, NAV-018, NAV-019, KPI-001, KPI-002, KPI-003, KPI-004, KPI-005, KPI-006, KPI-007, KPI-008, KPI-009, KPI-010, KPI-011, KPI-012, KPI-013, KPI-014, KPI-015 | J19: - | K19: #19
A20: 19 | B20: Staging | C20: Release (staging -> main) | D20: staging -> main | E20: Production (main -> gokesari.com) | F20: Merged | G20: 2026-09-28 | H20: 2026-09-30 | I20: PLT-004 | J20: GS-002, GS-003, GS-005, GS-006, GS-026, GS-030, GS-034, GS-038, GS-040, GS-042, GS-044, GS-045, GS-046, GS-047, GS-049, GS-051, GS-052, GS-053, GS-056, GS-059, GS-060, GS-065, GS-066, GS-068, GS-069, WF-001, WF-003, WF-004, WF-006, WF-008, WF-009, RBAC-009, RBAC-010, RBAC-013, SM-004, SM-006, GA-001, GA-002, GA-007, GA-008, NAV-002, NAV-009, NAV-011, NAV-012, NAV-013, NAV-014, NAV-015, NAV-016, NAV-017, NAV-018, NAV-019, KPI-001, KPI-002, KPI-003, KPI-004, KPI-005, KPI-006, KPI-007, KPI-008, KPI-009, KPI-010, KPI-011, KPI-012, KPI-013, KPI-014, KPI-015, PLT-001, PLT-002, PLT-004 | K20: Itself (merged to main) | L20: Release of Phases 2-4 (#11, #18, #21), #13, #17, #20, #22 to main.
A21: 20 | B21: Hotfix: resolve @/ imports in Hostinger webpack builds | C21: Fix / hotfix | D21: hotfix/webpack-src-alias -> staging | E21: Test site (staging -> test.gokesari.com) | F21: Merged | G21: 2026-09-28 | H21: 2026-09-28 | I21: PLT-001 | J21: - | K21: #19
A22: 21 | B22: Phase 4: operations, exceptions, fraud, and tracking hardening | C22: Feature | D22: dev/phase4-operations -> staging | E22: Test site (staging -> test.gokesari.com) | F22: Merged | G22: 2026-09-29 | H22: 2026-09-30 | I22: GS-034, GS-038, GS-042, GS-065, GS-066, GS-068, RBAC-010, NAV-011, NAV-012, NAV-013, NAV-015, NAV-016, NAV-017 | J22: - | K22: #19 | L22: Rebased onto staging; released by #19.
A23: 22 | B23: Stop the same shop being registered twice | C23: Feature | D23: fix/shop-duplicate-registration -> staging | E23: Test site (staging -> test.gokesari.com) | F23: Merged | G23: 2026-09-29 | H23: 2026-09-30 | I23: GS-006, WF-008 | J23: - | K23: #19 | L23: Merged into staging by hand; released by #19.
A24: 23 | B24: Release: Phases A–J, shop categories, migrations 0025–0035 | C24: Release + direct commits (Phases A-J) | D24: staging -> main | E24: Production (main -> gokesari.com) | F24: Merged | G24: 2026-10-01 | H24: 2026-10-01 | I24: GS-001, GS-004, GS-009, GS-010, GS-014, GS-015, GS-017, GS-018, GS-023, GS-026, GS-039, GS-043, GS-047, GS-055, GS-057, GS-063, GS-065, GS-072, GS-074, WF-001, WF-003, WF-005, WF-007, RBAC-007, RBAC-014, SM-002, SM-003, GA-009, NAV-001, NAV-003, NAV-006, NAV-012, NAV-017, NEW-001, NEW-002, NEW-004, NEW-005, NEW-006, NEW-007 | J24: GS-001, GS-004, GS-009, GS-010, GS-014, GS-015, GS-017, GS-018, GS-023, GS-026, GS-039, GS-043, GS-047, GS-055, GS-057, GS-063, GS-065, GS-072, GS-074, WF-001, WF-003, WF-005, WF-007, RBAC-007, RBAC-014, SM-002, SM-003, GA-009, NAV-001, NAV-003, NAV-006, NAV-012, NAV-017, NEW-001, NEW-002, NEW-004, NEW-005, NEW-006, NEW-007 | K24: Itself (merged to main) | L24: Phases A-J, the settings screen and shop categories were committed straight to staging, so this release PR is their only PR.
A25: 24 | B25: Release: closed-shop ordering with confirmation and alerts; IST opening hours | C25: Feature | D25: staging -> main | E25: Production (main -> gokesari.com) | F25: Merged | G25: 2026-10-01 | H25: 2026-10-01 | I25: WF-001, WF-002, NAV-002, NEW-003 | J25: WF-001, WF-002, NAV-002, NEW-003 | K25: Itself (merged to main) | L25: Closed-shop ordering was committed straight to staging; this release PR is its only PR.
A26: 25 | B26: Point CNAME and domain examples at gokesari.com | C26: DevOps / repo | D26: claude/charming-edison-ofoncf -> staging | E26: Test site (staging -> test.gokesari.com) | F26: Merged | G26: 2026-10-02 | H26: 2026-10-02 | I26: PLT-005 | J26: - | K26: #32
A27: 26 | B27: Port GoKesari from PostgreSQL to MySQL | C27: Platform port | D27: claude/awesome-dijkstra-fmccpl -> main | E27: Production (main -> gokesari.com) | F27: Closed - not merged | G27: 2026-10-02 | H27: 2026-10-07 | I27: - | J27: - | K27: - | L27: Closed without merging - the app stays on PostgreSQL.
A28: 27 | B28: Point this repo's deployment docs at GoKesari, not bkesari | C28: DevOps / repo | D28: claude/amazing-cannon-5n3fro -> main | E28: Production (main -> gokesari.com) | F28: Closed - not merged | G28: 2026-10-02 | H28: 2026-10-03 | I28: PLT-005 | J28: - | K28: - | L28: Closed; superseded by #25 and #33.
A29: 28 | B29: Re-audit the feature status workbook against the code on main | C29: Docs / reports | D29: claude/confident-albattani-dqw1dk -> main | E29: Production (main -> gokesari.com) | F29: Merged | G29: 2026-10-02 | H29: 2026-10-02 | I29: - | J29: - | K29: Itself (merged to main)
A30: 29 | B30: Mount the live tracking screen and enforce the registration-fee gate | C30: Feature | D30: claude/confident-albattani-dqw1dk -> main | E30: Production (main -> gokesari.com) | F30: Merged | G30: 2026-10-02 | H30: 2026-10-03 | I30: GS-008, GS-042, WF-005, WF-008, NAV-004, NAV-016 | J30: GS-008, GS-042, WF-005, WF-008, NAV-004, NAV-016 | K30: Itself (merged to main)
A31: 30 | B31: Explicit Save flow on three admin screens | C31: Feature | D31: claude/eloquent-darwin-n8yblq -> main | E31: Production (main -> gokesari.com) | F31: Merged | G31: 2026-10-02 | H31: 2026-10-03 | I31: GS-009, RBAC-013, NEW-009 | J31: - | K31: #32 | L31: Also merged into staging by hand; released by #32.
A32: 31 | B32: Login by mobile or email, first-time profile and My Profile | C32: Feature | D32: claude/tender-cannon-vmecpj -> staging | E32: Test site (staging -> test.gokesari.com) | F32: Merged | G32: 2026-10-03 | H32: 2026-10-03 | I32: GS-001, GS-026, WF-001, NAV-003 | J32: - | K32: #43
