Workbook

Sheet Summary
A1: Inventory & Accounting for shop owners — feature tracker (2026-10-15)
A2: Status: Done / In progress / Not started / Blocked (dropdown in 'Features' column F). Counts below are formulas.
A4: Status | B4: Features
A5: Done | B5: =COUNTIF(Features!$F$2:$F$500,A5)
A6: In progress | B6: =COUNTIF(Features!$F$2:$F$500,A6)
A7: Not started | B7: =COUNTIF(Features!$F$2:$F$500,A7)
A8: Blocked | B8: =COUNTIF(Features!$F$2:$F$500,A8)
A9: Total | B9: =SUM(B5:B8)
A11: Part | B11: Done | C11: In progress | D11: Not started | E11: Blocked
A12: 1 Inventory | B12: =COUNTIFS(Features!$B$2:$B$500,$A12,Features!$F$2:$F$500,"Done") | C12: =COUNTIFS(Features!$B$2:$B$500,$A12,Features!$F$2:$F$500,"In progress") | D12: =COUNTIFS(Features!$B$2:$B$500,$A12,Features!$F$2:$F$500,"Not started") | E12: =COUNTIFS(Features!$B$2:$B$500,$A12,Features!$F$2:$F$500,"Blocked")
A13: 2 Accounting | B13: =COUNTIFS(Features!$B$2:$B$500,$A13,Features!$F$2:$F$500,"Done") | C13: =COUNTIFS(Features!$B$2:$B$500,$A13,Features!$F$2:$F$500,"In progress") | D13: =COUNTIFS(Features!$B$2:$B$500,$A13,Features!$F$2:$F$500,"Not started") | E13: =COUNTIFS(Features!$B$2:$B$500,$A13,Features!$F$2:$F$500,"Blocked")
A14: 3 GST portal | B14: =COUNTIFS(Features!$B$2:$B$500,$A14,Features!$F$2:$F$500,"Done") | C14: =COUNTIFS(Features!$B$2:$B$500,$A14,Features!$F$2:$F$500,"In progress") | D14: =COUNTIFS(Features!$B$2:$B$500,$A14,Features!$F$2:$F$500,"Not started") | E14: =COUNTIFS(Features!$B$2:$B$500,$A14,Features!$F$2:$F$500,"Blocked")
A15: 4 Soft copy | B15: =COUNTIFS(Features!$B$2:$B$500,$A15,Features!$F$2:$F$500,"Done") | C15: =COUNTIFS(Features!$B$2:$B$500,$A15,Features!$F$2:$F$500,"In progress") | D15: =COUNTIFS(Features!$B$2:$B$500,$A15,Features!$F$2:$F$500,"Not started") | E15: =COUNTIFS(Features!$B$2:$B$500,$A15,Features!$F$2:$F$500,"Blocked")
A16: 5 Hard copy | B16: =COUNTIFS(Features!$B$2:$B$500,$A16,Features!$F$2:$F$500,"Done") | C16: =COUNTIFS(Features!$B$2:$B$500,$A16,Features!$F$2:$F$500,"In progress") | D16: =COUNTIFS(Features!$B$2:$B$500,$A16,Features!$F$2:$F$500,"Not started") | E16: =COUNTIFS(Features!$B$2:$B$500,$A16,Features!$F$2:$F$500,"Blocked")
A17: 6 Review | B17: =COUNTIFS(Features!$B$2:$B$500,$A17,Features!$F$2:$F$500,"Done") | C17: =COUNTIFS(Features!$B$2:$B$500,$A17,Features!$F$2:$F$500,"In progress") | D17: =COUNTIFS(Features!$B$2:$B$500,$A17,Features!$F$2:$F$500,"Not started") | E17: =COUNTIFS(Features!$B$2:$B$500,$A17,Features!$F$2:$F$500,"Blocked")
A18: 7 Data & security | B18: =COUNTIFS(Features!$B$2:$B$500,$A18,Features!$F$2:$F$500,"Done") | C18: =COUNTIFS(Features!$B$2:$B$500,$A18,Features!$F$2:$F$500,"In progress") | D18: =COUNTIFS(Features!$B$2:$B$500,$A18,Features!$F$2:$F$500,"Not started") | E18: =COUNTIFS(Features!$B$2:$B$500,$A18,Features!$F$2:$F$500,"Blocked")
A19: UI | B19: =COUNTIFS(Features!$B$2:$B$500,$A19,Features!$F$2:$F$500,"Done") | C19: =COUNTIFS(Features!$B$2:$B$500,$A19,Features!$F$2:$F$500,"In progress") | D19: =COUNTIFS(Features!$B$2:$B$500,$A19,Features!$F$2:$F$500,"Not started") | E19: =COUNTIFS(Features!$B$2:$B$500,$A19,Features!$F$2:$F$500,"Blocked")
A20: Mobile | B20: =COUNTIFS(Features!$B$2:$B$500,$A20,Features!$F$2:$F$500,"Done") | C20: =COUNTIFS(Features!$B$2:$B$500,$A20,Features!$F$2:$F$500,"In progress") | D20: =COUNTIFS(Features!$B$2:$B$500,$A20,Features!$F$2:$F$500,"Not started") | E20: =COUNTIFS(Features!$B$2:$B$500,$A20,Features!$F$2:$F$500,"Blocked")
A21: QA | B21: =COUNTIFS(Features!$B$2:$B$500,$A21,Features!$F$2:$F$500,"Done") | C21: =COUNTIFS(Features!$B$2:$B$500,$A21,Features!$F$2:$F$500,"In progress") | D21: =COUNTIFS(Features!$B$2:$B$500,$A21,Features!$F$2:$F$500,"Not started") | E21: =COUNTIFS(Features!$B$2:$B$500,$A21,Features!$F$2:$F$500,"Blocked")

Sheet Features
A1: ID | B1: Part | C1: Feature / sub-feature | D1: What it does | E1: Where it runs | F1: Status | G1: Notes / blocked on
A2: IA-001 | B2: 1 Inventory | C2: Product master per shop | D2: Listings linked to the gokesari.com master product (MRP, HSN, GST rate, unit, barcode/GTIN); shop-level HSN/GST/price stay per shop | F2: Done
A3: IA-002 | B3: 1 Inventory | C3: Stock ledger | D3: inv_stock_ledger: every movement (opening, purchase, sale, sale return, damage/expiry write-off, adjustment, reversal) with date, source document, qty, cost/rate, user; current stock = sum of the ledger | F3: Done
A4: IA-003 | B4: 1 Inventory | C4: Online orders reduce stock in real time | D4: DB triggers on shop_products / inventory_movements write the ledger row in the checkout / cancellation / subscription / catalogue transaction (event-driven, no cron, existing code unchanged) | F4: Done | G4: Verified on test.gokesari.com with a real customer order (stock 199 → 198, SALE row with the order id) and its cancellation; a cancellation is labelled SALE_RETURN since migration 0078 (found in staging testing)
A5: IA-004 | B5: 1 Inventory | C5: Opening balance backfill | D5: Migration 0076 writes today's stock of every listing as OPENING so ledger = stock from day one; drift check on the stock page | F5: Done
A6: IA-005 | B6: 1 Inventory | C6: Batch & expiry tracking | D6: Per listing (auto-on when a bill has batch numbers); FEFO batch balances; expiring-soon list with alert window setting | F6: Done
A7: IA-006 | B7: 1 Inventory | C7: Low stock / reorder level | D7: Existing per-shop thresholds and stock alerts reused; purchases and write-offs re-evaluate alerts | F7: Done
A8: IA-007 | B8: 1 Inventory | C8: Stock valuation FIFO / weighted average | D8: Selectable per shop; reversals take back exactly the reversed cost; uncosted opening stock valued at last purchase rate and reported | F8: Done
A9: IA-008 | B9: 1 Inventory | C9: Loose goods & unit conversions | D9: kg/g/L/ml/piece/dozen, UQC codes, Hindi/Marathi unit words; owner-saved conversions (1 case = 24); fractional quantities exact in the ledger | F9: Done
A10: IA-009 | B10: 1 Inventory | C10: Write-off and physical count | D10: Damage / expiry write-off at cost (P&L line); physical count posts the difference as an adjustment | F10: Done
A11: IA-010 | B11: 2 Accounting | C11: Purchase register | D11: Confirmed bills, versions, cancellations; month filter | F11: Done
A12: IA-011 | B12: 2 Accounting | C12: Sales register | D12: Own GST invoices plus GoKesari order tax invoices | F12: Done
A13: IA-012 | B13: 2 Accounting | C13: Supplier & customer ledgers | D13: Parties with GSTIN, credit days, opening balance; running-balance ledger from the books | F13: Done
A14: IA-013 | B14: 2 Accounting | C14: Cash / bank book | D14: Opening, in, out, closing, running balance | F14: Done
A15: IA-014 | B15: 2 Accounting | C15: Expenses | D15: Categories, claimable GST, cash/bank/credit, cancel with reason | F15: Done
A16: IA-015 | B16: 2 Accounting | C16: Payables / receivables with ageing | D16: 0-30 / 31-60 / 61-90 / 90+ by due date; payments applied to the named bill, then oldest first | F16: Done
... A19: IA-018 | B19: 2 Accounting | C19: Reports: P&L, stock summary, day book, GST summary, registers | D19: Perpetual COGS, write-offs, expenses net of GST | F19: Done
A20: IA-019 | B20: 2 Accounting | C20: Export Excel / PDF / Tally XML | D20: Every report as xlsx and PDF; Tally import XML with party masters (GSTIN) and vouchers | F20: Done | G20: Tally import to be confirmed on the shop's own TallyPrime
A21: IA-020 | B21: 3 GST portal | C21: Link GSTIN once (consent + OTP) | D21: Consent text recorded, portal username, OTP, token stored encrypted, unlink | F21: Done | G21: Consent + username + OTP through the GSP adapter; refused on production (no licensed GSP, IA-022). On test.gokesari.com blocked by the encryption key format (IA-056) — tokens are never stored unencrypted. Passes in the integration tests (mock GSP)
A22: IA-021 | B22: 3 GST portal | C22: Pluggable GSP adapter | D22: GST_RETURNS_PROVIDER: none / mock / GSP slots (masters_india, cleartax, iris, tally_gsp, vayana) | F22: Done
A23: IA-022 | B23: 3 GST portal | C23: Licensed GSP live connection | D23: Real GSTR-2B/2A/1 pull from the GST system | E23: Code on undefined; not switched on | F23: Blocked | G23: Needs a GSP contract and API credentials chosen by the owner; until then the manual upload works on gokesari.com
A24: IA-023 | B24: 3 GST portal | C24: Pull GSTR-2B / 2A / GSTR-1 (API) | D24: Through the configured adapter; mock on test.gokesari.com | F24: Done | G24: Live only with a GSP (IA-022); on test blocked by IA-056. Passes in the integration tests (mock GSP, OTP 575757)
A25: IA-024 | B25: 3 GST portal | C25: Manual fallback: upload GSTR-2B JSON / Excel | D25: GSTR-2B JSON (both shapes), GSTR-2A, GSTR-1 JSON, GSTR-2B Excel with merged headers | F25: Done
A26: IA-025 | B26: 3 GST portal | C26: Reconciliation | D26: Supplier GSTIN + invoice no. + date + amount; matched, amount mismatch, missing in books, missing on portal; ITC status updated | F26: Done
A27: IA-026 | B27: 3 GST portal | C27: GST liability dashboard (month / quarter) | D27: Output - reconciled ITC = net payable per CGST/SGST/IGST/cess with the legal set-off order and carry forward; pending ITC shown separately | F27: Done
A28: IA-027 | B28: 3 GST portal | C28: Due dates and reminders | D28: Monthly / QRMP due dates (GSTR-1, GSTR-3B, PMT-06); daily reminder cron, one reminder per return and period | F28: Done | G28: Owner to schedule /api/cron/gst-reminders on the server (see README)
A29: IA-028 | B29: 3 GST portal | C29: Estimates only, no filing | D29: 'Verify with your CA before filing' on every GST figure; nothing is filed | F29: Done
A30: IA-029 | B30: 4 Soft copy | C30: Upload PDF / photo / Excel / e-invoice JSON | D30: Up to 10 files, sniffed types, progress bar for slow networks | F30: Done
A31: IA-030 | B31: 4 Soft copy | C31: Share to app (WhatsApp / email / Files) | D31: PWA share target: installed site on Android receives shared bills | F31: Done
A32: IA-031 | B32: 4 Soft copy | C32: Share straight into the native Android/iOS app | D32: Native share-intent module + new store build | E32: Code on undefined; not switched on | F32: Blocked | G32: Needs a native share-intent module and an EAS store build tested on a device; share to the installed website or forward by email meanwhile
A33: IA-032 | B33: 4 Soft copy | C33: Forward by email | D33: Private per-shop address bills+<id>-<sig>@domain; inbound webhook /api/inbound/bill-email | E33: Code on undefined; not switched on | F33: Blocked | G33: Code done and tested; needs an inbound mail provider + INBOUND_EMAIL_SECRET / INBOUND_EMAIL_DOMAIN on the server
A34: IA-033 | B34: 4 Soft copy | C34: E-invoice JSON / signed QR as trusted source | D34: IRP JSON (plain or signed), signed QR decoded from photos and PDFs; RS256 check when NIC key configured | F34: Done | G34: Signature check needs EINVOICE_QR_PUBLIC_KEY (NIC public key)
A35: IA-034 | B35: 4 Soft copy | C35: AI document parsing | D35: Claude reads supplier, GSTIN, number, date, lines, totals with per-field confidence | E35: Code on undefined; not switched on | F35: Blocked | G35: Code done; needs ANTHROPIC_API_KEY + INVOICE_EXTRACTION_PROVIDER=claude on the servers (owner decision: bills are sent to Anthropic for reading)
A36: IA-035 | B36: 4 Soft copy | C36: Local extraction fallback | D36: Excel item tables, PDF text layer, OCR text with rules | F36: Done | G36: OCR worker does not start on Hostinger (same as the document reader, NEW-062): photos fall back to typing
A37: IA-036 | B37: 4 Soft copy | C37: Match lines to product master | D37: Remembered supplier mapping, barcode/GTIN, HSN + name, name; suggestions; create new product (reuses the master by barcode) | F37: Done
A38: IA-037 | B38: 4 Soft copy | C38: Validation | D38: Line maths, GST maths, totals = invoice total, GSTIN format + check digit, duplicate (supplier + number), e-invoice QR agreement, place of supply | F38: Done
A39: IA-038 | B39: 5 Hard copy | C39: Camera scan (web + app) | D39: Edge detection, crop, de-skew, enhance (colour / grey / B&W), corner adjust, multi-page, blur warning, small JPEGs | F39: Done
A40: IA-039 | B40: 5 Hard copy | C40: OCR + AI for printed and handwritten bills (English, Hindi, Marathi) | D40: AI reader handles handwriting and Hindi/Marathi; local OCR English only | E40: Code on undefined; not switched on | F40: Blocked | G40: Hindi/Marathi and handwriting need the AI reader (IA-034)
A41: IA-040 | B41: 5 Hard copy | C41: Per-field confidence, low confidence highlighted | D41: Amber = not sure, red = must fix; confidence % next to the field | F41: Done
A42: IA-041 | B42: 6 Review | C42: Side-by-side review & correction screen | D42: Original bill + editable table (phone: switch); edit any field, add/remove lines, change mapping, auto-save | F42: Done
...

Sheet Blocked & owner actions
A1: Feature | B1: What is needed | C1: Who
A2: IA-022 | B2: Licensed GSP live connection: Needs a GSP contract and API credentials chosen by the owner; until then the manual upload works on gokesari.com | C2: Owner
A3: IA-031 | B3: Share straight into the native Android/iOS app: Needs a native share-intent module and an EAS store build tested on a device; share to the installed website or forward by email meanwhile | C3: Owner
A4: IA-032 | B4: Forward by email: Code done and tested; needs an inbound mail provider + INBOUND_EMAIL_SECRET / INBOUND_EMAIL_DOMAIN on the server | C4: Owner
A5: IA-034 | B5: AI document parsing: Code done; needs ANTHROPIC_API_KEY + INVOICE_EXTRACTION_PROVIDER=claude on the servers (owner decision: bills are sent to Anthropic for reading) | C5: Owner
A6: IA-039 | B6: OCR + AI for printed and handwritten bills (English, Hindi, Marathi): Hindi/Marathi and handwriting need the AI reader (IA-034) | C6: Owner
A7: IA-049 | B7: Object storage with per-shop access control: Code done; bucket credentials not configured yet, so files are in the database / MEDIA_DIR | C7: Owner
A8: IA-056 | B8: Encryption key on the servers: Owner added the variable on test and production (15 Oct), but the value is not base64 of 32 bytes: test.gokesari.com reports encryption not configured (/api/shops/{id}/integration → ready.encryption=false) and GST linking answers 500. Fix: set the value from `openssl rand -base64 32` (44 characters ending in '='), a different one per site, and redeploy. Nothing has been encrypted with the old values | C8: Owner
